Workbook
Name \a: #REF!
Name \a: #REF!
Name \p: #REF!
Name \p: #REF!
Name _______xlnm.Print_Titles: #REF!
Name _______xlnm_Print_Titles: NA()
Name ______xlnm._FilterDatabase: "#ref!"
Name ______xlnm.Print_Titles: #REF!
Name ______xlnm__FilterDatabase: "#ref!"
Name ______xlnm_Print_Titles: NA()
Name _____xlfn_BAHTTEXT: NA()
Name _____xlfn_SUMIFS: NA()
Name _____xlnm._FilterDatabase: "#ref!"
Name _____xlnm.Print_Titles: #REF!
Name _____xlnm__FilterDatabase: "#ref!"
Name _____xlnm_Print_Titles: NA()
Name ____xlfn_BAHTTEXT: NA()
Name ____xlfn_SUMIFS: NA()
Name ____xlnm._FilterDatabase: "#ref!"
Name ____xlnm.Print_Titles: #REF!
Name ____xlnm__FilterDatabase: "#ref!"
Name ____xlnm_Print_Titles: NA()
Name ___xlfn_BAHTTEXT: NA()
Name ___xlfn_SUMIFS: NA()
Name ___xlnm._FilterDatabase: "#ref!"
Name ___xlnm.Print_Titles: #REF!
Name ___xlnm__FilterDatabase: "#ref!"
Name ___xlnm_Print_Titles: NA()
Name __TAB3688: #REF!
Name __xlfn_BAHTTEXT: NA()
Name __xlfn_SUMIFS: NA()
Name __xlnm._FilterDatabase: "#ref!"
Name __xlnm.Print_Titles: #REF!
Name __xlnm__FilterDatabase: "#ref!"
Name __xlnm_Print_Titles: NA()
Name _TAB3688: #REF!
Name _TAB3688: #REF!
Name a: #REF!
Name abr: #REF!
Name abr: #REF!
Name abril: #REF!
Name ACRESCENTAR: #REF!
Name ADAPTADO: '[1]APONTAMENTO CREDENCIAMENTO'!#REF!
Name ADAPTADO: 'APONTAMENTO CREDENCIAMENTO'!$FF$7:$GJ$7
Name AGOSTO: #REF!
Name AI: #REF!
Name AI: #REF!
Name AII: #REF!
Name AII: #REF!
Name AK: #REF!
Name AK: #REF!
Name AL: #REF!
Name AL: #REF!
Name AMPLIAR: #REF!
Name AMPLIAR: #REF!
Name ApagaAtesteFis: 'ATESTE-LIQ-FIS'!$A$4:$K$3878
Name ApagaBaseC: 'BASE C'!$A$11:$N$4950
Name ApagaDadosA: 'APONTAMENTO CREDENCIAMENTO'!$Q$6:$EL$3029
Name ApagaDadosC: CONTINUA!$L$6:$BU$3047
Name ApagarDadosDigitados: #REF!

Sheet Planilha2
A1: Freguesia / Brasilândia | G1: ABRIL | I1: APONTAMENTO CREDENCIAMENTO | EL1: ATENÇÃO | FE1: =(552.16*30) -> 16564.8
G2: 01/06 a 30/06/2025
A3: 1 | B3: 2 | C3: 3 | D3: 1 | E3: 2 | F3: 3 | G3: 4 | H3: 5 | I3: 6 | J3: 7 | K3: 8 | L3: 9 | M3: 10 | N3: 10 | O3: 11 | P3: 13 | Q3: 14 | R3: 15 | S3: 16 | T3: 17 | U3: 18 | V3: 19 | W3: 20 | X3: 21 | Y3: 22 | Z3: 23 | AA3: 24 | AB3: 25 | AC3: 26 | AD3: 27 | AE3: 28 | AF3: 29 | AG3: 30 | AH3: 31 | AI3: 32 | AJ3: 33 | AK3: 34 | AL3: 35 | AM3: 36 | AN3: 37 | AO3: 38 | AP3: 39 | AQ3: 40 | AR3: 41 | AS3: 42 | AT3: 43 | AU3: 44 | AV3: 45 | AW3: 46 | AX3: 47 | AY3: 48 | AZ3: 49 | BA3: 50 | BB3: 51 | BC3: 52 | BD3: 53 | BE3: 54 | BF3: 55 | BG3: 56 | BH3: 57 | BI3: 58 | BJ3: 59 | BK3: 60 | BL3: 61 | BM3: 62 | BN3: 63 | BO3: 64 | BP3: 65 | BQ3: 66 | BR3: 67 | BS3: 68 | BT3: 69 | BU3: 70 | BV3: 71 | BW3: 72 | BX3: 73 | BY3: 74 | BZ3: 75 | CA3: 76 | CB3: 77 | CC3: 78 | CD3: 79 | CE3: 80 | CF3: 81 | CG3: 82 | CH3: 83 | CI3: 84 | CJ3: 85 | CK3: 86 | CL3: 87 | CM3: 88 | CN3: 89 | CO3: 90 | CP3: 91 | CQ3: 92 | CR3: 93 | CS3: 94 | CT3: 95 | CU3: 96 | CV3: 97 | CW3: 98 | CX3: 99 | CY3: 100 | CZ3: 101 | DA3: 102 | DB3: 103 | DC3: 104 | DD3: 105 | DE3: 106 | DF3: 107 | DG3: 108 | DH3: 109 | DI3: 110 | DJ3: 111 | DK3: 112 | DL3: 113 | DM3: 114 | DN3: 115 | DO3: 116 | DP3: 117 | DQ3: 118 | DR3: 119 | DS3: 120 | DT3: 121 | DU3: 122 | DV3: 123 | DW3: 124 | DX3: 125 | DY3: 126 | DZ3: 127 | EA3: 128 | EB3: 129 | EC3: 130 | ED3: 131 | EE3: 132 | EF3: 133 | EG3: 134 | EH3: 135 | EI3: 136 | EJ3: 137 | EK3: 138 | EL3: 139 | EM3: 140 | EN3: 141 | EO3: 142 | EP3: 143 | EQ3: 144 | ER3: 145 | ES3: 146 | ET3: 147 | EU3: 148 | EV3: 149 | EW3: 150 | EX3: 151 | EY3: 152 | EZ3: 153 | FA3: 154 | FB3: 155 | FC3: 156 | FD3: 157 | FE3: 158 | FF3: 159 | FG3: 160 | FH3: 161 | FI3: 162 | FJ3: 163 | FK3: 164 | FL3: 165 | FM3: 166 | FN3: 167 | FO3: 168 | FP3: 169 | FQ3: 170 | FR3: 171 | FS3: 172 | FT3: 173 | FU3: 174 | FV3: 175 | FW3: 176 | FX3: 177 | FY3: 178 | FZ3: 179 | GA3: 180 | GB3: 181 | GC3: 182 | GD3: 183 | GE3: 184 | GF3: 185 | GG3: 186 | GH3: 187 | GI3: 188 | GJ3: 189 | GK3: 190 | GL3: 191 | GM3: 192 | GN3: 193 | GO3: 194 | GP3: 195 | GQ3: 196 | GR3: 197 | GS3: 198 | GT3: 199 | GU3: 200 | GV3: 201 | GW3: 202 | GX3: 203 | GY3: 204 | GZ3: 205 | HA3: 206 | HB3: 207 | HC3: 208 | HD3: 209 | HE3: 210 | HF3: 211 | HG3: 212 | HH3: 213 | HI3: 214 | HJ3: 215 | HK3: 216 | HL3: 217 | HM3: 218 | HN3: 219 | HO3: 220 | HP3: 221 | HQ3: 222 | HR3: 223 | HS3: 224 | HT3: 225 | HU3: 226 | HV3: 227 | HW3: 228 | HX3: 229 | HY3: 230 | HZ3: 231 | IA3: 232
A4: CRMC | B4: OS | C4: DRE | D4: CONTRATO | E4: PLACA | F4: PERÍODO | H4: EMPRESA | I4: NOME CONDUTOR | J4: TIPO DE VEÍCULO (NORMAL, ADAPTADO) | K4: TIPO DE ATENDIMENTO | L4: TOTAL CONT REG | M4: TOTAL CONT CAD | N4: KM ADICIONAL | O4: SEI | P4: Tipo Optante | Q4: 01/04/2026 | U4: 46114 | Y4: 46115 | AC4: 46116 | AG4: 46117 | AK4: 46118 | AO4: 46119 | AS4: 46120 | AW4: 46121 | BA4: 46122 | BE4: 46123 | BI4: 46124 | BM4: 46125 | BQ4: 46126 | BU4: 46127 | BY4: 46128 | CC4: 46129 | CG4: 46130 | CK4: 46131 | CO4: 46132 | CS4: 46133 | CW4: 46134 | DA4: 46135 | DE4: 46136 | DI4: 46137 | DM4: 46138 | DQ4: 46139 | DU4: 46140 | DY4: 46141 | EC4: 46142 | EK4: FALTAS - APONTAR AS DATAS | EL4: OBSERVAÇÕES ALUNO PRESENCIAL COLUNAS FINAIS | EM4: Ajuste positivo | EN4: Ajuste negativo | EO4: Desconto faltas | EP4: TOTAL ALUNOS N CAD(30 DIAS) | EQ4: TOTAL ALUNOS N CAD(MENOS DE 30 DIAS) | ER4: TOTAL ALUNOS ATIV.COMPL. N CAD | ES4: TOTAL ALUNOS CAD (30 DIAS) | ET4: TOTAL ALUNOS CAD (MENOS DE 30 DIAS) | EU4: TOTAL ALUNOS ATIV.COMPL. CAD | EV4: TOTAL GERAL | EW4: Contratos Especiais (Valor fixo) | EX4: Valor total alunos presenciais (30 dias) | EY4: Ativ.Complementar Continuada | EZ4: Valor alunos presenciais (menos de 30 dias) | FA4: Saida de alunos ao longo do mês | FB4: CCA | FC4: Valor km adicional | FD4: Outros apontamentos | FE4: VALOR ATESTE | FF4: 30 | FG4: 29 | FH4: 28 | FI4: 27 | FJ4: 26 | FK4: 25 | FL4: 24 | FM4: 23 | FN4: 22 | FO4: 21 | FP4: 20 | FQ4: 19 | FR4: 18 | FS4: 17 | FT4: 16 | FU4: 15 | FV4: 14 | FW4: 13 | FX4: 12 | FY4: 11 | FZ4: 10 | GA4: 9 | GB4: 8 | GC4: 7 | GD4: 6 | GE4: 5 | GF4: 4 | GG4: 3 | GH4: 2 | GI4: 1 | GJ4: 1 | GK4: Multa Contratual | GL4: CÁLCULO | GM4: DIAS | GN4: 29 | GO4: 28 | GP4: 27 | GQ4: 26 | GR4: 25 | GS4: 24 | GT4: 23 | GU4: 22 | GV4: 21 | GW4: 20 | GX4: 19 | GY4: 18 | GZ4: 17 | HA4: 16 | HB4: 15 | HC4: 14 | HD4: 13 | HE4: 12 | HF4: 11 | HG4: 10 | HH4: 9 | HI4: 8 | HJ4: 7 | HK4: 6 | HL4: 5 | HM4: 4 | HN4: 3 | HO4: 2 | HP4: 1 | HW4: VALOR ATESTE | HY4: Ajuste positivo | HZ4: Ajuste negativo | IA4: Desconto faltas
F5: 01/04/2026 | G5: 30/04/2026 | Q5: N CAD presencial | R5: CAD | S5: AT. COMPL. N CAD | T5: AT. COMPL. CAD | U5: N CAD presencial | V5: CAD | W5: AT. COMPL. N CAD | X5: AT. COMPL. CAD | Y5: N CAD presencial | Z5: CAD | AA5: AT. COMPL. N CAD | AB5: AT. COMPL. CAD | AC5: N CAD presencial | AD5: CAD | AE5: AT. COMPL. N CAD | AF5: AT. COMPL. CAD | AG5: N CAD presencial | AH5: CAD | AI5: AT. COMPL. N CAD | AJ5: AT. COMPL. CAD | AK5: N CAD presencial | AL5: CAD | AM5: AT. COMPL. N CAD | AN5: AT. COMPL. CAD | AO5: N CAD presencial | AP5: CAD | AQ5: AT. COMPL. N CAD | AR5: AT. COMPL. CAD | AS5: N CAD presencial | AT5: CAD | AU5: AT. COMPL. N CAD | AV5: AT. COMPL. CAD | AW5: N CAD presencial | AX5: CAD | AY5: AT. COMPL. N CAD | AZ5: AT. COMPL. CAD | BA5: N CAD presencial | BB5: CAD | BC5: AT. COMPL. N CAD | BD5: AT. COMPL. CAD | BE5: N CAD presencial | BF5: CAD | BG5: AT. COMPL. N CAD | BH5: AT. COMPL. CAD | BI5: N CAD presencial | BJ5: CAD | BK5: AT. COMPL. N CAD | BL5: AT. COMPL. CAD | BM5: N CAD presencial | BN5: CAD | BO5: AT. COMPL. N CAD | BP5: AT. COMPL. CAD | BQ5: N CAD presencial | BR5: CAD | BS5: AT. COMPL. N CAD | BT5: AT. COMPL. CAD | BU5: N CAD presencial | BV5: CAD | BW5: AT. COMPL. N CAD | BX5: AT. COMPL. CAD | BY5: N CAD presencial | BZ5: CAD | CA5: AT. COMPL. N CAD | CB5: AT. COMPL. CAD | CC5: N CAD presencial | CD5: CAD | CE5: AT. COMPL. N CAD | CF5: AT. COMPL. CAD | CG5: N CAD presencial | CH5: CAD | CI5: AT. COMPL. N CAD | CJ5: AT. COMPL. CAD | CK5: N CAD presencial | CL5: CAD | CM5: AT. COMPL. N CAD | CN5: AT. COMPL. CAD | CO5: N CAD presencial | CP5: CAD | CQ5: AT. COMPL. N CAD | CR5: AT. COMPL. CAD | CS5: N CAD presencial | CT5: CAD | CU5: AT. COMPL. N CAD | CV5: AT. COMPL. CAD | CW5: N CAD presencial | CX5: CAD | CY5: AT. COMPL. N CAD | CZ5: AT. COMPL. CAD | DA5: N CAD presencial | DB5: CAD | DC5: AT. COMPL. N CAD | DD5: AT. COMPL. CAD | DE5: N CAD presencial | DF5: CAD | DG5: AT. COMPL. N CAD | DH5: AT. COMPL. CAD | DI5: N CAD presencial | DJ5: CAD | DK5: AT. COMPL. N CAD | DL5: AT. COMPL. CAD | DM5: N CAD presencial | DN5: CAD | DO5: AT. COMPL. N CAD | DP5: AT. COMPL. CAD | DQ5: N CAD presencial | DR5: CAD | DS5: AT. COMPL. N CAD | DT5: AT. COMPL. CAD | DU5: N CAD presencial | DV5: CAD | DW5: AT. COMPL. N CAD | DX5: AT. COMPL. CAD | DY5: N CAD presencial | DZ5: CAD | EA5: AT. COMPL. N CAD | EB5: AT. COMPL. CAD | EC5: N CAD presencial | ED5: CAD | EE5: AT. COMPL. N CAD | EF5: AT. COMPL. CAD | EG5: N CAD presencial | EH5: CAD | EI5: AT. COMPL. N CAD | EJ5: AT. COMPL. CAD
A6: 020.708-00 | B6: 2022/0026670-001 | C6: 1 | D6: 2022/0026670 | E6: DJE9491 | F6: 01/04/2026 | G6: 30/04/2026 | H6: ADILSON TOLEDO | I6: ADILSON TOLEDO | J6: NORMAL | K6: EMEI | L6: 0 | M6: 0 | O6: 6020.2022/0026670-0 | P6: 0 | U6: =Q6+'APONTAMENTO CREDENCIAMENTO'!U6 -> 0 | V6: =R6+'APONTAMENTO CREDENCIAMENTO'!V6 -> 0 | W6: =S6+'APONTAMENTO CREDENCIAMENTO'!W6 -> 0 | X6: =T6+'APONTAMENTO CREDENCIAMENTO'!X6 -> 0 | Y6: =U6+'APONTAMENTO CREDENCIAMENTO'!Y6 -> 0 | Z6: =V6+'APONTAMENTO CREDENCIAMENTO'!Z6 -> 0 | AA6: =W6+'APONTAMENTO CREDENCIAMENTO'!AA6 -> 0 | AB6: =X6+'APONTAMENTO CREDENCIAMENTO'!AB6 -> 0 | ... EF6: =EB6+'APONTAMENTO CREDENCIAMENTO'!EF6 -> 0 | EP6: 0 | EQ6: 0 | ER6: 0 | ES6: 0 | ET6: 0 | EU6: 0 | EV6: 0 | EW6: 0 | EX6: 24057.41 | EY6: 0 | EZ6: 0 | FA6: 0 | FB6: 0 | FC6: 0 | FD6: 0 | FE6: 24057.41 | FF6: 24057.41 | FG6: 0 | FH6: 0 | FI6: 0 | FJ6: 0 | FK6: 0 | FL6: 0 | FM6: 0 | FN6: 0 | FO6: 0 | FP6: 0 | FQ6: 0 | FR6: 0 | FS6: 0 | FT6: 0 | FU6: 0 | FV6: 0 | FW6: 0 | FX6: 0 | FY6: 0 | FZ6: 0 | GA6: 0 | GB6: 0 | GC6: 0 | GD6: 0 | GE6: 0 | GF6: 0 | GG6: 0 | GH6: 0 | GI6: 0 | GJ6: 0 | GL6: 0 | GN6: 0 | GO6: 0 | GP6: 0 | GQ6: 0 | GR6: 0 | GS6: 0 | GT6: 0 | GU6: 0 | GV6: 0 | GW6: 0 | GX6: 0 | GY6: 0 | GZ6: 0 | HA6: 0 | HB6: 0 | HC6: 0 | HD6: 0 | HE6: 0 | HF6: 0 | HG6: 0 | HH6: 0 | HI6: 0 | HJ6: 0 | HK6: 0 | HL6: 0 | HM6: 0 | HN6: 0 | HO6: 0 | HP6: 0 | HW6: 17629.31 | HY6: 0 | HZ6: 0 | IA6: 0 | IB6: FALSE
A7: 020.708-00 | B7: 2022/0026670-001 | C7: FB | D7: 2022/0026670 | E7: DJE9491 | F7: 01/04/2026 | G7: 30/04/2026 | H7: ADILSON TOLEDO | I7: ADILSON TOLEDO | J7: NORMAL | K7: EMEF | L7: 0 | M7: 0 | O7: 6020.2022/0026670-0 | P7: 0 | Q7: 59 | U7: =Q7+'APONTAMENTO CREDENCIAMENTO'!U7 -> 59 | V7: =R7+'APONTAMENTO CREDENCIAMENTO'!V7 -> 0 | W7: =S7+'APONTAMENTO CREDENCIAMENTO'!W7 -> 0 | X7: =T7+'APONTAMENTO CREDENCIAMENTO'!X7 -> 0 | Y7: =U7+'APONTAMENTO CREDENCIAMENTO'!Y7 -> 59 | Z7: =V7+'APONTAMENTO CREDENCIAMENTO'!Z7 -> 0 | AA7: =W7+'APONTAMENTO CREDENCIAMENTO'!AA7 -> 0 | AB7: =X7+'APONTAMENTO CREDENCIAMENTO'!AB7 -> 0 | ... EF7: =EB7+'APONTAMENTO CREDENCIAMENTO'!EF7 -> 0 | EP7: 59 | EQ7: 0 | ER7: 0 | ES7: 0 | ET7: 0 | EU7: 0 | EV7: 59 | EX7: 0 | EY7: 0 | EZ7: 0 | FA7: 0 | FB7: 0 | FC7: 0 | FD7: 0 | GL7: 0 | HY7: 0 | HZ7: 0 | IA7: 0
A8: 020.708-00 | B8: 2022/0026670-001 | C8: FB | D8: 2022/0026670 | E8: DJE9491 | F8: 01/04/2026 | G8: 30/04/2026 | H8: ADILSON TOLEDO | I8: ADILSON TOLEDO | J8: NORMAL | K8: EMEE | L8: 0 | M8: 0 | O8: 6020.2022/0026670-0 | P8: 0 | U8: =Q8+'APONTAMENTO CREDENCIAMENTO'!U8 -> 0 | V8: =R8+'APONTAMENTO CREDENCIAMENTO'!V8 -> 0 | W8: =S8+'APONTAMENTO CREDENCIAMENTO'!W8 -> 0 | X8: =T8+'APONTAMENTO CREDENCIAMENTO'!X8 -> 0 | Y8: =U8+'APONTAMENTO CREDENCIAMENTO'!Y8 -> 0 | Z8: =V8+'APONTAMENTO CREDENCIAMENTO'!Z8 -> 0 | AA8: =W8+'APONTAMENTO CREDENCIAMENTO'!AA8 -> 0 | AB8: =X8+'APONTAMENTO CREDENCIAMENTO'!AB8 -> 0 | ... EF8: =EB8+'APONTAMENTO CREDENCIAMENTO'!EF8 -> 0 | EP8: 0 | EQ8: 0 | ER8: 0 | ES8: 0 | ET8: 0 | EU8: 0 | EV8: 0 | EX8: 0 | EY8: 0 | EZ8: 0 | FA8: 0 | FB8: 0 | FC8: 0 | FD8: 0 | GL8: 0 | HY8: 0 | HZ8: 0 | IA8: 0
A9: 020.708-00 | B9: 2022/0026670-001 | C9: FB | D9: 2022/0026670 | E9: DJE9491 | F9: 01/04/2026 | G9: 30/04/2026 | H9: ADILSON TOLEDO | I9: ADILSON TOLEDO | J9: NORMAL | K9: CEI | L9: 0 | M9: 0 | O9: 6020.2022/0026670-0 | P9: 0 | U9: =Q9+'APONTAMENTO CREDENCIAMENTO'!U9 -> 0 | V9: =R9+'APONTAMENTO CREDENCIAMENTO'!V9 -> 0 | W9: =S9+'APONTAMENTO CREDENCIAMENTO'!W9 -> 0 | X9: =T9+'APONTAMENTO CREDENCIAMENTO'!X9 -> 0 | Y9: =U9+'APONTAMENTO CREDENCIAMENTO'!Y9 -> 0 | Z9: =V9+'APONTAMENTO CREDENCIAMENTO'!Z9 -> 0 | AA9: =W9+'APONTAMENTO CREDENCIAMENTO'!AA9 -> 0 | AB9: =X9+'APONTAMENTO CREDENCIAMENTO'!AB9 -> 0 | ... EF9: =EB9+'APONTAMENTO CREDENCIAMENTO'!EF9 -> 0 | EP9: 0 | EQ9: 0 | ER9: 0 | ES9: 0 | ET9: 0 | EU9: 0 | EV9: 0 | EX9: 0 | EY9: 0 | EZ9: 0 | FA9: 0 | FB9: 0 | FC9: 0 | FD9: 0 | GL9: 0 | HY9: 0 | HZ9: 0 | IA9: 0
A10: 020.708-00 | B10: 2022/0026670-001 | C10: FB | D10: 2022/0026670 | E10: DJE9491 | F10: 01/04/2026 | G10: 30/04/2026 | H10: ADILSON TOLEDO | I10: ADILSON TOLEDO | J10: NORMAL | K10: CCA | L10: 0 | M10: 0 | O10: 6020.2022/0026670-0 | P10: 0 | U10: =Q10+'APONTAMENTO CREDENCIAMENTO'!U10 -> 0 | V10: =R10+'APONTAMENTO CREDENCIAMENTO'!V10 -> 0 | W10: =S10+'APONTAMENTO CREDENCIAMENTO'!W10 -> 0 | X10: =T10+'APONTAMENTO CREDENCIAMENTO'!X10 -> 0 | Y10: =U10+'APONTAMENTO CREDENCIAMENTO'!Y10 -> 0 | Z10: =V10+'APONTAMENTO CREDENCIAMENTO'!Z10 -> 0 | AA10: =W10+'APONTAMENTO CREDENCIAMENTO'!AA10 -> 0 | AB10: =X10+'APONTAMENTO CREDENCIAMENTO'!AB10 -> 0 | ... EF10: =EB10+'APONTAMENTO CREDENCIAMENTO'!EF10 -> 0 | EP10: 0 | EQ10: 0 | ER10: 0 | ES10: 0 | ET10: 0 | EU10: 0 | EV10: 0 | EX10: 0 | EY10: 0 | EZ10: 0 | FA10: 0 | FB10: 0 | FC10: 0 | FD10: 0 | FF10: 0 | FG10: 0 | FH10: 0 | FI10: 0 | FJ10: 0 | FK10: 0 | FL10: 0 | FM10: 0 | FN10: 0 | FO10: 0 | FP10: 0 | FQ10: 0 | FR10: 0 | FS10: 0 | FT10: 0 | FU10: 0 | FV10: 0 | FW10: 0 | FX10: 0 | FY10: 0 | FZ10: 0 | GA10: 0 | GB10: 0 | GC10: 0 | GD10: 0 | GE10: 0 | GF10: 0 | GG10: 0 | GH10: 0 | GI10: 0 | GJ10: 0 | GL10: 0 | HY10: 0 | HZ10: 0 | IA10: 0
A11: 015.733-00 | B11: 2022/0027713-001B | C11: 4 | D11: 2022/0027713 | E11: ECM4497 | F11: 01/04/2026 | G11: 30/04/2026 | H11: ALEXANDRO CIRINO VIEIRA | I11: ALEXANDRO CIRINO VIEIRA | J11: NORMAL | K11: EMEI | L11: 0 | M11: 0 | O11: 6020.2022/0027713-2 | P11: 0 | U11: =Q11+'APONTAMENTO CREDENCIAMENTO'!U11 -> 0 | V11: =R11+'APONTAMENTO CREDENCIAMENTO'!V11 -> 0 | W11: =S11+'APONTAMENTO CREDENCIAMENTO'!W11 -> 0 | X11: =T11+'APONTAMENTO CREDENCIAMENTO'!X11 -> 0 | Y11: =U11+'APONTAMENTO CREDENCIAMENTO'!Y11 -> 0 | Z11: =V11+'APONTAMENTO CREDENCIAMENTO'!Z11 -> 0 | AA11: =W11+'APONTAMENTO CREDENCIAMENTO'!AA11 -> 0 | AB11: =X11+'APONTAMENTO CREDENCIAMENTO'!AB11 -> 0 | ... EF11: =EB11+'APONTAMENTO CREDENCIAMENTO'!EF11 -> 0 | EP11: 0 | EQ11: 0 | ER11: 0 | ES11: 0 | ET11: 0 | EU11: 0 | EV11: 0 | EW11: 11465.63 | EX11: 1155.69 | EY11: 0 | EZ11: 0 | FA11: 0 | FB11: 0 | FC11: 0 | FD11: 0 | FE11: 12852.68 | FF11: 1155.69 | FG11: 0 | FH11: 0 | FI11: 0 | FJ11: 0 | FK11: 0 | FL11: 0 | FM11: 0 | FN11: 0 | FO11: 0 | FP11: 0 | FQ11: 0 | FR11: 0 | FS11: 0 | FT11: 0 | FU11: 0 | FV11: 0 | FW11: 0 | FX11: 0 | FY11: 0 | FZ11: 0 | GA11: 0 | GB11: 0 | GC11: 0 | GD11: 0 | GE11: 0 | GF11: 0 | GG11: 0 | GH11: 0 | GI11: 0 | GJ11: 0 | GL11: 0 | GN11: 0 | GO11: 0 | GP11: 0 | GQ11: 0 | GR11: 0 | GS11: 0 | GT11: 0 | GU11: 0 | GV11: 0 | GW11: 0 | GX11: 0 | GY11: 0 | GZ11: 0 | HA11: 0 | HB11: 0 | HC11: 0 | HD11: 0 | HE11: 0 | HF11: 0 | HG11: 0 | HH11: 0 | HI11: 0 | HJ11: 0 | HK11: 0 | HL11: 0 | HM11: 0 | HN11: 0 | HO11: 0 | HP11: 0 | HW11: 17629.31 | HY11: 0 | HZ11: 0 | IA11: 0 | IB11: FALSE
A12: 015.733-00 | B12: 2022/0027713-001B | C12: FBE | D12: 2022/0027713 | E12: ECM4497 | F12: 01/04/2026 | G12: 30/04/2026 | H12: ALEXANDRO CIRINO VIEIRA | I12: ALEXANDRO CIRINO VIEIRA | J12: NORMAL | K12: EMEF | L12: 0 | M12: 0 | O12: 6020.2022/0027713-2 | P12: 0 | U12: =Q12+'APONTAMENTO CREDENCIAMENTO'!U12 -> 0 | V12: =R12+'APONTAMENTO CREDENCIAMENTO'!V12 -> 0 | W12: =S12+'APONTAMENTO CREDENCIAMENTO'!W12 -> 0 | X12: =T12+'APONTAMENTO CREDENCIAMENTO'!X12 -> 0 | Y12: =U12+'APONTAMENTO CREDENCIAMENTO'!Y12 -> 0 | Z12: =V12+'APONTAMENTO CREDENCIAMENTO'!Z12 -> 0 | AA12: =W12+'APONTAMENTO CREDENCIAMENTO'!AA12 -> 0 | AB12: =X12+'APONTAMENTO CREDENCIAMENTO'!AB12 -> 0 | ... EF12: =EB12+'APONTAMENTO CREDENCIAMENTO'!EF12 -> 0 | EP12: 0 | EQ12: 0 | ER12: 0 | ES12: 0 | ET12: 0 | EU12: 0 | EV12: 0 | EX12: 0 | EY12: 0 | EZ12: 0 | FA12: 0 | FB12: 0 | FC12: 0 | FD12: 0 | GL12: 0 | HY12: 0 | HZ12: 0 | IA12: 0
A13: 015.733-00 | B13: 2022/0027713-001B | C13: FBE | D13: 2022/0027713 | E13: ECM4497 | F13: 01/04/2026 | G13: 30/04/2026 | H13: ALEXANDRO CIRINO VIEIRA | I13: ALEXANDRO CIRINO VIEIRA | J13: NORMAL | K13: EMEE | L13: 24 | M13: 0 | O13: 6020.2022/0027713-2 | P13: 0 | Q13: 3 | U13: =Q13+'APONTAMENTO CREDENCIAMENTO'!U13 -> 3 | V13: =R13+'APONTAMENTO CREDENCIAMENTO'!V13 -> 0 | W13: =S13+'APONTAMENTO CREDENCIAMENTO'!W13 -> 0 | X13: =T13+'APONTAMENTO CREDENCIAMENTO'!X13 -> 0 | Y13: =U13+'APONTAMENTO CREDENCIAMENTO'!Y13 -> 3 | Z13: =V13+'APONTAMENTO CREDENCIAMENTO'!Z13 -> 0 | AA13: =W13+'APONTAMENTO CREDENCIAMENTO'!AA13 -> 0 | AB13: =X13+'APONTAMENTO CREDENCIAMENTO'!AB13 -> 0 | ... EF13: =EB13+'APONTAMENTO CREDENCIAMENTO'!EF13 -> 0 | EP13: 3 | EQ13: 0 | ER13: 0 | ES13: 0 | ET13: 0 | EU13: 0 | EV13: 3 | EX13: 0 | EY13: 231.36 | EZ13: 0 | FA13: 0 | FB13: 0 | FC13: 0 | FD13: 0 | GL13: 0 | HY13: 0 | HZ13: 0 | IA13: 0
A14: 015.733-00 | B14: 2022/0027713-001B | C14: FBE | D14: 2022/0027713 | E14: ECM4497 | F14: 01/04/2026 | G14: 30/04/2026 | H14: ALEXANDRO CIRINO VIEIRA | I14: ALEXANDRO CIRINO VIEIRA | J14: NORMAL | K14: CEI | L14: 0 | M14: 0 | O14: 6020.2022/0027713-2 | P14: 0 | U14: =Q14+'APONTAMENTO CREDENCIAMENTO'!U14 -> 0 | V14: =R14+'APONTAMENTO CREDENCIAMENTO'!V14 -> 0 | W14: =S14+'APONTAMENTO CREDENCIAMENTO'!W14 -> 0 | X14: =T14+'APONTAMENTO CREDENCIAMENTO'!X14 -> 0 | Y14: =U14+'APONTAMENTO CREDENCIAMENTO'!Y14 -> 0 | Z14: =V14+'APONTAMENTO CREDENCIAMENTO'!Z14 -> 0 | AA14: =W14+'APONTAMENTO CREDENCIAMENTO'!AA14 -> 0 | AB14: =X14+'APONTAMENTO CREDENCIAMENTO'!AB14 -> 0 | ... EF14: =EB14+'APONTAMENTO CREDENCIAMENTO'!EF14 -> 0 | EP14: 0 | EQ14: 0 | ER14: 0 | ES14: 0 | ET14: 0 | EU14: 0 | EV14: 0 | EX14: 0 | EY14: 0 | EZ14: 0 | FA14: 0 | FB14: 0 | FC14: 0 | FD14: 0 | GL14: 0 | HY14: 0 | HZ14: 0 | IA14: 0
A15: 015.733-00 | B15: 2022/0027713-001B | C15: FBE | D15: 2022/0027713 | E15: ECM4497 | F15: 01/04/2026 | G15: 30/04/2026 | H15: ALEXANDRO CIRINO VIEIRA | I15: ALEXANDRO CIRINO VIEIRA | J15: NORMAL | K15: CCA | L15: 0 | M15: 0 | O15: 6020.2022/0027713-2 | P15: 0 | U15: =Q15+'APONTAMENTO CREDENCIAMENTO'!U15 -> 0 | V15: =R15+'APONTAMENTO CREDENCIAMENTO'!V15 -> 0 | W15: =S15+'APONTAMENTO CREDENCIAMENTO'!W15 -> 0 | X15: =T15+'APONTAMENTO CREDENCIAMENTO'!X15 -> 0 | Y15: =U15+'APONTAMENTO CREDENCIAMENTO'!Y15 -> 0 | Z15: =V15+'APONTAMENTO CREDENCIAMENTO'!Z15 -> 0 | AA15: =W15+'APONTAMENTO CREDENCIAMENTO'!AA15 -> 0 | AB15: =X15+'APONTAMENTO CREDENCIAMENTO'!AB15 -> 0 | ... EF15: =EB15+'APONTAMENTO CREDENCIAMENTO'!EF15 -> 0 | EP15: 0 | EQ15: 0 | ER15: 0 | ES15: 0 | ET15: 0 | EU15: 0 | EV15: 0 | EX15: 0 | EY15: 0 | EZ15: 0 | FA15: 0 | FB15: 0 | FC15: 0 | FD15: 0 | FF15: 0 | FG15: 0 | FH15: 0 | FI15: 0 | FJ15: 0 | FK15: 0 | FL15: 0 | FM15: 0 | FN15: 0 | FO15: 0 | FP15: 0 | FQ15: 0 | FR15: 0 | FS15: 0 | FT15: 0 | FU15: 0 | FV15: 0 | FW15: 0 | FX15: 0 | FY15: 0 | FZ15: 0 | GA15: 0 | GB15: 0 | GC15: 0 | GD15: 0 | GE15: 0 | GF15: 0 | GG15: 0 | GH15: 0 | GI15: 0 | GJ15: 0 | GL15: 0 | HY15: 0 | HZ15: 0 | IA15: 0
A16: 015.812-00 | B16: 2022/0033780-001D | C16: 1 | D16: 2022/0033780 | E16: CLU1093 | F16: 01/04/2026 | G16: 30/04/2026 | H16: ANA CRISTINA FABRI DE LIMA | I16: ANA CRISTINA FABRI DE LIMA | J16: NORMAL | K16: EMEI | L16: 0 | M16: 0 | O16: 6020.2022/0033780-1 | P16: 0 | U16: =Q16+'APONTAMENTO CREDENCIAMENTO'!U16 -> 0 | V16: =R16+'APONTAMENTO CREDENCIAMENTO'!V16 -> 0 | W16: =S16+'APONTAMENTO CREDENCIAMENTO'!W16 -> 0 | X16: =T16+'APONTAMENTO CREDENCIAMENTO'!X16 -> 0 | Y16: =U16+'APONTAMENTO CREDENCIAMENTO'!Y16 -> 0 | Z16: =V16+'APONTAMENTO CREDENCIAMENTO'!Z16 -> 0 | AA16: =W16+'APONTAMENTO CREDENCIAMENTO'!AA16 -> 0 | AB16: =X16+'APONTAMENTO CREDENCIAMENTO'!AB16 -> 0 | ... EF16: =EB16+'APONTAMENTO CREDENCIAMENTO'!EF16 -> 0 | EP16: 0 | EQ16: 0 | ER16: 0 | ES16: 0 | ET16: 0 | EU16: 0 | EV16: 0 | EW16: 0 | EX16: 17123.27 | EY16: 0 | EZ16: 308.184 | FA16: 0 | FB16: 0 | FC16: 0 | FD16: 0 | FE16: 17518.214 | FF16: 17123.27 | FG16: 0 | FH16: 0 | FI16: 0 | FJ16: 0 | FK16: 0 | FL16: 308.184 | FM16: 0 | FN16: 0 | FO16: 0 | FP16: 0 | FQ16: 0 | FR16: 0 | FS16: 0 | FT16: 0 | FU16: 0 | FV16: 0 | FW16: 0 | FX16: 0 | FY16: 0 | FZ16: 0 | GA16: 0 | GB16: 0 | GC16: 0 | GD16: 0 | GE16: 0 | GF16: 0 | GG16: 0 | GH16: 0 | GI16: 0 | GJ16: 0 | GL16: 0 | GN16: 0 | GO16: 0 | GP16: 0 | GQ16: 0 | GR16: 0 | GS16: 0 | GT16: 0 | GU16: 0 | GV16: 0 | GW16: 0 | GX16: 0 | GY16: 0 | GZ16: 0 | HA16: 0 | HB16: 0 | HC16: 0 | HD16: 0 | HE16: 0 | HF16: 0 | HG16: 0 | HH16: 0 | HI16: 0 | HJ16: 0 | HK16: 0 | HL16: 0 | HM16: 0 | HN16: 0 | HO16: 0 | HP16: 0 | HW16: 17629.31 | HY16: 0 | HZ16: 0 | IA16: 0 | IB16: FALSE
A17: 015.812-00 | B17: 2022/0033780-001D | C17: FB | D17: 2022/0033780 | E17: CLU1093 | F17: 01/04/2026 | G17: 30/04/2026 | H17: ANA CRISTINA FABRI DE LIMA | I17: ANA CRISTINA FABRI DE LIMA | J17: NORMAL | K17: EMEF | L17: 9 | M17: 0 | O17: 6020.2022/0033780-1 | P17: 0 | Q17: 36 | S17: 5 | U17: =Q17+'APONTAMENTO CREDENCIAMENTO'!U17 -> 36 | V17: =R17+'APONTAMENTO CREDENCIAMENTO'!V17 -> 0 | W17: =S17+'APONTAMENTO CREDENCIAMENTO'!W17 -> 5 | X17: =T17+'APONTAMENTO CREDENCIAMENTO'!X17 -> 0 | Y17: =U17+'APONTAMENTO CREDENCIAMENTO'!Y17 -> 36 | Z17: =V17+'APONTAMENTO CREDENCIAMENTO'!Z17 -> 0 | AA17: =W17+'APONTAMENTO CREDENCIAMENTO'!AA17 -> 5 | AB17: =X17+'APONTAMENTO CREDENCIAMENTO'!AB17 -> 0 | ... EF17: =EB17+'APONTAMENTO CREDENCIAMENTO'!EF17 -> 0 | EP17: 36 | EQ17: 1 | ER17: 5 | ES17: 0 | ET17: 0 | EU17: 0 | EV17: 42 | EX17: 0 | EY17: 86.76 | EZ17: 0 | FA17: 0 | FB17: 0 | FC17: 0 | FD17: 0 | GL17: 0 | HY17: 0 | HZ17: 0 | IA17: 0
A18: 015.812-00 | B18: 2022/0033780-001D | C18: FB | D18: 2022/0033780 | E18: CLU1093 | F18: 01/04/2026 | G18: 30/04/2026 | H18: ANA CRISTINA FABRI DE LIMA | I18: ANA CRISTINA FABRI DE LIMA | J18: NORMAL | K18: EMEE | L18: 0 | M18: 0 | O18: 6020.2022/0033780-1 | P18: 0 | U18: =Q18+'APONTAMENTO CREDENCIAMENTO'!U18 -> 0 | V18: =R18+'APONTAMENTO CREDENCIAMENTO'!V18 -> 0 | W18: =S18+'APONTAMENTO CREDENCIAMENTO'!W18 -> 0 | X18: =T18+'APONTAMENTO CREDENCIAMENTO'!X18 -> 0 | Y18: =U18+'APONTAMENTO CREDENCIAMENTO'!Y18 -> 0 | Z18: =V18+'APONTAMENTO CREDENCIAMENTO'!Z18 -> 0 | AA18: =W18+'APONTAMENTO CREDENCIAMENTO'!AA18 -> 0 | AB18: =X18+'APONTAMENTO CREDENCIAMENTO'!AB18 -> 0 | ... EF18: =EB18+'APONTAMENTO CREDENCIAMENTO'!EF18 -> 0 | EP18: 0 | EQ18: 0 | ER18: 0 | ES18: 0 | ET18: 0 | EU18: 0 | EV18: 0 | EX18: 0 | EY18: 0 | EZ18: 0 | FA18: 0 | FB18: 0 | FC18: 0 | FD18: 0 | GL18: 0 | HY18: 0 | HZ18: 0 | IA18: 0
A19: 015.812-00 | B19: 2022/0033780-001D | C19: FB | D19: 2022/0033780 | E19: CLU1093 | F19: 01/04/2026 | G19: 30/04/2026 | H19: ANA CRISTINA FABRI DE LIMA | I19: ANA CRISTINA FABRI DE LIMA | J19: NORMAL | K19: CEI | L19: 0 | M19: 0 | O19: 6020.2022/0033780-1 | P19: 0 | U19: =Q19+'APONTAMENTO CREDENCIAMENTO'!U19 -> 0 | V19: =R19+'APONTAMENTO CREDENCIAMENTO'!V19 -> 0 | W19: =S19+'APONTAMENTO CREDENCIAMENTO'!W19 -> 0 | X19: =T19+'APONTAMENTO CREDENCIAMENTO'!X19 -> 0 | Y19: =U19+'APONTAMENTO CREDENCIAMENTO'!Y19 -> 0 | Z19: =V19+'APONTAMENTO CREDENCIAMENTO'!Z19 -> 0 | AA19: =W19+'APONTAMENTO CREDENCIAMENTO'!AA19 -> 0 | AB19: =X19+'APONTAMENTO CREDENCIAMENTO'!AB19 -> 0 | ... EF19: =EB19+'APONTAMENTO CREDENCIAMENTO'!EF19 -> 0 | EP19: 0 | EQ19: 0 | ER19: 0 | ES19: 0 | ET19: 0 | EU19: 0 | EV19: 0 | EX19: 0 | EY19: 0 | EZ19: 0 | FA19: 0 | FB19: 0 | FC19: 0 | FD19: 0 | GL19: 0 | HY19: 0 | HZ19: 0 | IA19: 0
A20: 015.812-00 | B20: 2022/0033780-001D | C20: FB | D20: 2022/0033780 | E20: CLU1093 | F20: 01/04/2026 | G20: 30/04/2026 | H20: ANA CRISTINA FABRI DE LIMA | I20: ANA CRISTINA FABRI DE LIMA | J20: NORMAL | K20: CCA | L20: 0 | M20: 0 | O20: 6020.2022/0033780-1 | P20: 0 | U20: =Q20+'APONTAMENTO CREDENCIAMENTO'!U20 -> 0 | V20: =R20+'APONTAMENTO CREDENCIAMENTO'!V20 -> 0 | W20: =S20+'APONTAMENTO CREDENCIAMENTO'!W20 -> 0 | X20: =T20+'APONTAMENTO CREDENCIAMENTO'!X20 -> 0 | Y20: =U20+'APONTAMENTO CREDENCIAMENTO'!Y20 -> 0 | Z20: =V20+'APONTAMENTO CREDENCIAMENTO'!Z20 -> 0 | AA20: =W20+'APONTAMENTO CREDENCIAMENTO'!AA20 -> 0 | AB20: =X20+'APONTAMENTO CREDENCIAMENTO'!AB20 -> 0 | ... EF20: =EB20+'APONTAMENTO CREDENCIAMENTO'!EF20 -> 0 | EP20: 0 | EQ20: 0 | ER20: 0 | ES20: 0 | ET20: 0 | EU20: 0 | EV20: 0 | EX20: 0 | EY20: 0 | EZ20: 0 | FA20: 0 | FB20: 0 | FC20: 0 | FD20: 0 | FF20: 0 | FG20: 0 | FH20: 0 | FI20: 0 | FJ20: 0 | FK20: 0 | FL20: 0 | FM20: 0 | FN20: 0 | FO20: 0 | FP20: 0 | FQ20: 0 | FR20: 0 | FS20: 0 | FT20: 0 | FU20: 0 | FV20: 0 | FW20: 0 | FX20: 0 | FY20: 0 | FZ20: 0 | GA20: 0 | GB20: 0 | GC20: 0 | GD20: 0 | GE20: 0 | GF20: 0 | GG20: 0 | GH20: 0 | GI20: 0 | GJ20: 0 | GL20: 0 | HY20: 0 | HZ20: 0 | IA20: 0
A21: 025.892-00 | B21: 2022/0027355-001 | C21: 4 | D21: 2022/0027355 | E21: EFU6103 | F21: 01/04/2026 | G21: 30/04/2026 | H21: ANDREIA NOEMIA PEREIRA | I21: ANDREIA NOEMIA PEREIRA | J21: NORMAL | K21: EMEI | L21: 0 | M21: 0 | O21: 6020.2022/0027355-2 | P21: 0 | U21: =Q21+'APONTAMENTO CREDENCIAMENTO'!U21 -> 0 | V21: =R21+'APONTAMENTO CREDENCIAMENTO'!V21 -> 0 | W21: =S21+'APONTAMENTO CREDENCIAMENTO'!W21 -> 0 | X21: =T21+'APONTAMENTO CREDENCIAMENTO'!X21 -> 0 | Y21: =U21+'APONTAMENTO CREDENCIAMENTO'!Y21 -> 0 | Z21: =V21+'APONTAMENTO CREDENCIAMENTO'!Z21 -> 0 | AA21: =W21+'APONTAMENTO CREDENCIAMENTO'!AA21 -> 0 | AB21: =X21+'APONTAMENTO CREDENCIAMENTO'!AB21 -> 0 | ... EF21: =EB21+'APONTAMENTO CREDENCIAMENTO'!EF21 -> 0 | EP21: 0 | EQ21: 0 | ER21: 0 | ES21: 0 | ET21: 0 | EU21: 0 | EV21: 0 | EW21: 11465.63 | EX21: 385.23 | EY21: 0 | EZ21: 0 | FA21: 0 | FB21: 0 | FC21: 0 | FD21: 0 | FE21: 11850.86 | FF21: 385.23 | FG21: 0 | FH21: 0 | FI21: 0 | FJ21: 0 | FK21: 0 | FL21: 0 | FM21: 0 | FN21: 0 | FO21: 0 | FP21: 0 | FQ21: 0 | FR21: 0 | FS21: 0 | FT21: 0 | FU21: 0 | FV21: 0 | FW21: 0 | FX21: 0 | FY21: 0 | FZ21: 0 | GA21: 0 | GB21: 0 | GC21: 0 | GD21: 0 | GE21: 0 | GF21: 0 | GG21: 0 | GH21: 0 | GI21: 0 | GJ21: 0 | GL21: 0 | GN21: 0 | GO21: 0 | GP21: 0 | GQ21: 0 | GR21: 0 | GS21: 0 | GT21: 0 | GU21: 0 | GV21: 0 | GW21: 0 | GX21: 0 | GY21: 0 | GZ21: 0 | HA21: 0 | HB21: 0 | HC21: 0 | HD21: 0 | HE21: 0 | HF21: 0 | HG21: 0 | HH21: 0 | HI21: 0 | HJ21: 0 | HK21: 0 | HL21: 0 | HM21: 0 | HN21: 0 | HO21: 0 | HP21: 0 | HW21: 17629.31 | HY21: 0 | HZ21: 0 | IA21: 0 | IB21: FALSE
A22: 025.892-00 | B22: 2022/0027355-001 | C22: FBE | D22: 2022/0027355 | E22: EFU6103 | F22: 01/04/2026 | G22: 30/04/2026 | H22: ANDREIA NOEMIA PEREIRA | I22: ANDREIA NOEMIA PEREIRA | J22: NORMAL | K22: EMEF | L22: 0 | M22: 0 | O22: 6020.2022/0027355-2 | P22: 0 | U22: =Q22+'APONTAMENTO CREDENCIAMENTO'!U22 -> 0 | V22: =R22+'APONTAMENTO CREDENCIAMENTO'!V22 -> 0 | W22: =S22+'APONTAMENTO CREDENCIAMENTO'!W22 -> 0 | X22: =T22+'APONTAMENTO CREDENCIAMENTO'!X22 -> 0 | Y22: =U22+'APONTAMENTO CREDENCIAMENTO'!Y22 -> 0 | Z22: =V22+'APONTAMENTO CREDENCIAMENTO'!Z22 -> 0 | AA22: =W22+'APONTAMENTO CREDENCIAMENTO'!AA22 -> 0 | AB22: =X22+'APONTAMENTO CREDENCIAMENTO'!AB22 -> 0 | ... EF22: =EB22+'APONTAMENTO CREDENCIAMENTO'!EF22 -> 0 | EP22: 0 | EQ22: 0 | ER22: 0 | ES22: 0 | ET22: 0 | EU22: 0 | EV22: 0 | EX22: 0 | EY22: 0 | EZ22: 0 | FA22: 0 | FB22: 0 | FC22: 0 | FD22: 0 | GL22: 0 | HY22: 0 | HZ22: 0 | IA22: 0
A23: 025.892-00 | B23: 2022/0027355-001 | C23: FBE | D23: 2022/0027355 | E23: EFU6103 | F23: 01/04/2026 | G23: 30/04/2026 | H23: ANDREIA NOEMIA PEREIRA | I23: ANDREIA NOEMIA PEREIRA | J23: NORMAL | K23: EMEE | L23: 0 | M23: 0 | O23: 6020.2022/0027355-2 | P23: 0 | Q23: 1 | U23: =Q23+'APONTAMENTO CREDENCIAMENTO'!U23 -> 1 | V23: =R23+'APONTAMENTO CREDENCIAMENTO'!V23 -> 0 | W23: =S23+'APONTAMENTO CREDENCIAMENTO'!W23 -> 0 | X23: =T23+'APONTAMENTO CREDENCIAMENTO'!X23 -> 0 | Y23: =U23+'APONTAMENTO CREDENCIAMENTO'!Y23 -> 1 | Z23: =V23+'APONTAMENTO CREDENCIAMENTO'!Z23 -> 0 | AA23: =W23+'APONTAMENTO CREDENCIAMENTO'!AA23 -> 0 | AB23: =X23+'APONTAMENTO CREDENCIAMENTO'!AB23 -> 0 | ... EF23: =EB23+'APONTAMENTO CREDENCIAMENTO'!EF23 -> 0 | EP23: 1 | EQ23: 0 | ER23: 0 | ES23: 0 | ET23: 0 | EU23: 0 | EV23: 1 | EX23: 0 | EY23: 0 | EZ23: 0 | FA23: 0 | FB23: 0 | FC23: 0 | FD23: 0 | GL23: 0 | HY23: 0 | HZ23: 0 | IA23: 0
A24: 025.892-00 | B24: 2022/0027355-001 | C24: FBE | D24: 2022/0027355 | E24: EFU6103 | F24: 01/04/2026 | G24: 30/04/2026 | H24: ANDREIA NOEMIA PEREIRA | I24: ANDREIA NOEMIA PEREIRA | J24: NORMAL | K24: CEI | L24: 0 | M24: 0 | O24: 6020.2022/0027355-2 | P24: 0 | U24: =Q24+'APONTAMENTO CREDENCIAMENTO'!U24 -> 0 | V24: =R24+'APONTAMENTO CREDENCIAMENTO'!V24 -> 0 | W24: =S24+'APONTAMENTO CREDENCIAMENTO'!W24 -> 0 | X24: =T24+'APONTAMENTO CREDENCIAMENTO'!X24 -> 0 | Y24: =U24+'APONTAMENTO CREDENCIAMENTO'!Y24 -> 0 | Z24: =V24+'APONTAMENTO CREDENCIAMENTO'!Z24 -> 0 | AA24: =W24+'APONTAMENTO CREDENCIAMENTO'!AA24 -> 0 | AB24: =X24+'APONTAMENTO CREDENCIAMENTO'!AB24 -> 0 | ... EF24: =EB24+'APONTAMENTO CREDENCIAMENTO'!EF24 -> 0 | EP24: 0 | EQ24: 0 | ER24: 0 | ES24: 0 | ET24: 0 | EU24: 0 | EV24: 0 | EX24: 0 | EY24: 0 | EZ24: 0 | FA24: 0 | FB24: 0 | FC24: 0 | FD24: 0 | GL24: 0 | HY24: 0 | HZ24: 0 | IA24: 0
A25: 025.892-00 | B25: 2022/0027355-001 | C25: FBE | D25: 2022/0027355 | E25: EFU6103 | F25: 01/04/2026 | G25: 30/04/2026 | H25: ANDREIA NOEMIA PEREIRA | I25: ANDREIA NOEMIA PEREIRA | J25: NORMAL | K25: CCA | L25: 0 | M25: 0 | O25: 6020.2022/0027355-2 | P25: 0 | U25: =Q25+'APONTAMENTO CREDENCIAMENTO'!U25 -> 0 | V25: =R25+'APONTAMENTO CREDENCIAMENTO'!V25 -> 0 | W25: =S25+'APONTAMENTO CREDENCIAMENTO'!W25 -> 0 | X25: =T25+'APONTAMENTO CREDENCIAMENTO'!X25 -> 0 | Y25: =U25+'APONTAMENTO CREDENCIAMENTO'!Y25 -> 0 | Z25: =V25+'APONTAMENTO CREDENCIAMENTO'!Z25 -> 0 | AA25: =W25+'APONTAMENTO CREDENCIAMENTO'!AA25 -> 0 | AB25: =X25+'APONTAMENTO CREDENCIAMENTO'!AB25 -> 0 | ... EF25: =EB25+'APONTAMENTO CREDENCIAMENTO'!EF25 -> 0 | EP25: 0 | EQ25: 0 | ER25: 0 | ES25: 0 | ET25: 0 | EU25: 0 | EV25: 0 | EX25: 0 | EY25: 0 | EZ25: 0 | FA25: 0 | FB25: 0 | FC25: 0 | FD25: 0 | FF25: 0 | FG25: 0 | FH25: 0 | FI25: 0 | FJ25: 0 | FK25: 0 | FL25: 0 | FM25: 0 | FN25: 0 | FO25: 0 | FP25: 0 | FQ25: 0 | FR25: 0 | FS25: 0 | FT25: 0 | FU25: 0 | FV25: 0 | FW25: 0 | FX25: 0 | FY25: 0 | FZ25: 0 | GA25: 0 | GB25: 0 | GC25: 0 | GD25: 0 | GE25: 0 | GF25: 0 | GG25: 0 | GH25: 0 | GI25: 0 | GJ25: 0 | GL25: 0 | HY25: 0 | HZ25: 0 | IA25: 0
A26: 022.524-00 | B26: 2022/0026000-001 | C26: 1 | D26: 2022/0026000 | E26: DTD7389 | F26: 01/04/2026 | G26: 30/04/2026 | H26: ANTONIO CARLOS GOMES | I26: ANTONIO CARLOS GOMES | J26: NORMAL | K26: EMEI | L26: 0 | M26: 0 | O26: 6020.2022/0026000-0 | P26: 0 | U26: =Q26+'APONTAMENTO CREDENCIAMENTO'!U26 -> 0 | V26: =R26+'APONTAMENTO CREDENCIAMENTO'!V26 -> 0 | W26: =S26+'APONTAMENTO CREDENCIAMENTO'!W26 -> 0 | X26: =T26+'APONTAMENTO CREDENCIAMENTO'!X26 -> 0 | Y26: =U26+'APONTAMENTO CREDENCIAMENTO'!Y26 -> 0 | Z26: =V26+'APONTAMENTO CREDENCIAMENTO'!Z26 -> 0 | AA26: =W26+'APONTAMENTO CREDENCIAMENTO'!AA26 -> 0 | AB26: =X26+'APONTAMENTO CREDENCIAMENTO'!AB26 -> 0 | ... EF26: =EB26+'APONTAMENTO CREDENCIAMENTO'!EF26 -> 0 | EP26: 0 | EQ26: 0 | ER26: 0 | ES26: 0 | ET26: 0 | EU26: 0 | EV26: 0 | EW26: 0 | EX26: 14811.89 | EY26: 0 | EZ26: 1181.372 | FA26: -295.343 | FB26: 0 | FC26: 0 | FD26: 0 | FE26: 16257.039 | FF26: 14811.89 | FG26: 0 | FH26: 0 | FI26: 0 | FJ26: 0 | FK26: 0 | FL26: 0 | FM26: 1181.372 | FN26: 0 | FO26: 0 | FP26: 0 | FQ26: 0 | FR26: 0 | FS26: 0 | FT26: 0 | FU26: 0 | FV26: -179.774 | FW26: 0 | FX26: 0 | FY26: 0 | FZ26: 0 | GA26: -115.569 | GB26: 0 | GC26: 0 | GD26: 0 | GE26: 0 | GF26: 0 | GG26: 0 | GH26: 0 | GI26: 0 | GJ26: 0 | GL26: 0 | GN26: 0 | GO26: 0 | GP26: 0 | GQ26: 0 | GR26: 0 | GS26: 0 | GT26: 0 | GU26: 0 | GV26: 0 | GW26: 0 | GX26: 0 | GY26: 0 | GZ26: 0 | HA26: 0 | HB26: 0 | HC26: 0 | HD26: 0 | HE26: 0 | HF26: 0 | HG26: 0 | HH26: 0 | HI26: 0 | HJ26: 0 | HK26: 0 | HL26: 0 | HM26: 0 | HN26: 0 | HO26: 0 | HP26: 0 | HW26: 17629.31 | HY26: 0 | HZ26: 0 | IA26: 0 | IB26: FALSE
A27: 022.524-00 | B27: 2022/0026000-001 | C27: FB | D27: 2022/0026000 | E27: DTD7389 | F27: 01/04/2026 | G27: 30/04/2026 | H27: ANTONIO CARLOS GOMES | I27: ANTONIO CARLOS GOMES | J27: NORMAL | K27: EMEF | L27: 58 | M27: 0 | O27: 6020.2022/0026000-0 | P27: 0 | Q27: 35 | U27: =Q27+'APONTAMENTO CREDENCIAMENTO'!U27 -> 35 | V27: =R27+'APONTAMENTO CREDENCIAMENTO'!V27 -> 0 | W27: =S27+'APONTAMENTO CREDENCIAMENTO'!W27 -> 0 | X27: =T27+'APONTAMENTO CREDENCIAMENTO'!X27 -> 0 | Y27: =U27+'APONTAMENTO CREDENCIAMENTO'!Y27 -> 35 | Z27: =V27+'APONTAMENTO CREDENCIAMENTO'!Z27 -> 0 | AA27: =W27+'APONTAMENTO CREDENCIAMENTO'!AA27 -> 0 | AB27: =X27+'APONTAMENTO CREDENCIAMENTO'!AB27 -> 0 | ... EF27: =EB27+'APONTAMENTO CREDENCIAMENTO'!EF27 -> 0 | EP27: 35 | EQ27: -1 | ER27: 3 | ES27: 0 | ET27: 0 | EU27: 0 | EV27: 37 | EX27: 0 | EY27: 559.12 | EZ27: 0 | FA27: 0 | FB27: 0 | FC27: 0 | FD27: 0 | GL27: 0 | HY27: 0 | HZ27: 0 | IA27: 0
A28: 022.524-00 | B28: 2022/0026000-001 | C28: FB | D28: 2022/0026000 | E28: DTD7389 | F28: 01/04/2026 | G28: 30/04/2026 | H28: ANTONIO CARLOS GOMES | I28: ANTONIO CARLOS GOMES | J28: NORMAL | K28: EMEE | L28: 0 | M28: 0 | O28: 6020.2022/0026000-0 | P28: 0 | U28: =Q28+'APONTAMENTO CREDENCIAMENTO'!U28 -> 0 | V28: =R28+'APONTAMENTO CREDENCIAMENTO'!V28 -> 0 | W28: =S28+'APONTAMENTO CREDENCIAMENTO'!W28 -> 0 | X28: =T28+'APONTAMENTO CREDENCIAMENTO'!X28 -> 0 | Y28: =U28+'APONTAMENTO CREDENCIAMENTO'!Y28 -> 0 | Z28: =V28+'APONTAMENTO CREDENCIAMENTO'!Z28 -> 0 | AA28: =W28+'APONTAMENTO CREDENCIAMENTO'!AA28 -> 0 | AB28: =X28+'APONTAMENTO CREDENCIAMENTO'!AB28 -> 0 | ... EF28: =EB28+'APONTAMENTO CREDENCIAMENTO'!EF28 -> 0 | EP28: 0 | EQ28: 0 | ER28: 0 | ES28: 0 | ET28: 0 | EU28: 0 | EV28: 0 | EX28: 0 | EY28: 0 | EZ28: 0 | FA28: 0 | FB28: 0 | FC28: 0 | FD28: 0 | GL28: 0 | HY28: 0 | HZ28: 0 | IA28: 0
A29: 022.524-00 | B29: 2022/0026000-001 | C29: FB | D29: 2022/0026000 | E29: DTD7389 | F29: 01/04/2026 | G29: 30/04/2026 | H29: ANTONIO CARLOS GOMES | I29: ANTONIO CARLOS GOMES | J29: NORMAL | K29: CEI | L29: 0 | M29: 0 | O29: 6020.2022/0026000-0 | P29: 0 | U29: =Q29+'APONTAMENTO CREDENCIAMENTO'!U29 -> 0 | V29: =R29+'APONTAMENTO CREDENCIAMENTO'!V29 -> 0 | W29: =S29+'APONTAMENTO CREDENCIAMENTO'!W29 -> 0 | X29: =T29+'APONTAMENTO CREDENCIAMENTO'!X29 -> 0 | Y29: =U29+'APONTAMENTO CREDENCIAMENTO'!Y29 -> 0 | Z29: =V29+'APONTAMENTO CREDENCIAMENTO'!Z29 -> 0 | AA29: =W29+'APONTAMENTO CREDENCIAMENTO'!AA29 -> 0 | AB29: =X29+'APONTAMENTO CREDENCIAMENTO'!AB29 -> 0 | ... EF29: =EB29+'APONTAMENTO CREDENCIAMENTO'!EF29 -> 0 | EP29: 0 | EQ29: 0 | ER29: 0 | ES29: 0 | ET29: 0 | EU29: 0 | EV29: 0 | EX29: 0 | EY29: 0 | EZ29: 0 | FA29: 0 | FB29: 0 | FC29: 0 | FD29: 0 | GL29: 0 | HY29: 0 | HZ29: 0 | IA29: 0
A30: 022.524-00 | B30: 2022/0026000-001 | C30: FB | D30: 2022/0026000 | E30: DTD7389 | F30: 01/04/2026 | G30: 30/04/2026 | H30: ANTONIO CARLOS GOMES | I30: ANTONIO CARLOS GOMES | J30: NORMAL | K30: CCA | L30: 0 | M30: 0 | O30: 6020.2022/0026000-0 | P30: 0 | U30: =Q30+'APONTAMENTO CREDENCIAMENTO'!U30 -> 0 | V30: =R30+'APONTAMENTO CREDENCIAMENTO'!V30 -> 0 | W30: =S30+'APONTAMENTO CREDENCIAMENTO'!W30 -> 0 | X30: =T30+'APONTAMENTO CREDENCIAMENTO'!X30 -> 0 | Y30: =U30+'APONTAMENTO CREDENCIAMENTO'!Y30 -> 0 | Z30: =V30+'APONTAMENTO CREDENCIAMENTO'!Z30 -> 0 | AA30: =W30+'APONTAMENTO CREDENCIAMENTO'!AA30 -> 0 | AB30: =X30+'APONTAMENTO CREDENCIAMENTO'!AB30 -> 0 | ... EF30: =EB30+'APONTAMENTO CREDENCIAMENTO'!EF30 -> 0 | EP30: 0 | EQ30: 0 | ER30: 0 | ES30: 0 | ET30: 0 | EU30: 0 | EV30: 0 | EX30: 0 | EY30: 0 | EZ30: 0 | FA30: 0 | FB30: 0 | FC30: 0 | FD30: 0 | FF30: 0 | FG30: 0 | FH30: 0 | FI30: 0 | FJ30: 0 | FK30: 0 | FL30: 0 | FM30: 0 | FN30: 0 | FO30: 0 | FP30: 0 | FQ30: 0 | FR30: 0 | FS30: 0 | FT30: 0 | FU30: 0 | FV30: 0 | FW30: 0 | FX30: 0 | FY30: 0 | FZ30: 0 | GA30: 0 | GB30: 0 | GC30: 0 | GD30: 0 | GE30: 0 | GF30: 0 | GG30: 0 | GH30: 0 | GI30: 0 | GJ30: 0 | GL30: 0 | HY30: 0 | HZ30: 0 | IA30: 0
A31: 005.388-00 | B31: 2022/0028814-001 | C31: 2 | D31: 2022/0028814 | E31: DTC6900 | F31: 01/04/2026 | G31: 30/04/2026 | H31: CARLOS OMAR ALVES | I31: CARLOS OMAR ALVES | J31: ADAPTADO | K31: EMEI | L31: 0 | M31: 0 | O31: 6020.2022/0028814-2 | P31: 0 | R31: 1 | U31: =Q31+'APONTAMENTO CREDENCIAMENTO'!U31 -> 0 | V31: =R31+'APONTAMENTO CREDENCIAMENTO'!V31 -> 1 | W31: =S31+'APONTAMENTO CREDENCIAMENTO'!W31 -> 0 | X31: =T31+'APONTAMENTO CREDENCIAMENTO'!X31 -> 0 | Y31: =U31+'APONTAMENTO CREDENCIAMENTO'!Y31 -> 0 | Z31: =V31+'APONTAMENTO CREDENCIAMENTO'!Z31 -> 1 | AA31: =W31+'APONTAMENTO CREDENCIAMENTO'!AA31 -> 0 | AB31: =X31+'APONTAMENTO CREDENCIAMENTO'!AB31 -> 0 | ... EF31: =EB31+'APONTAMENTO CREDENCIAMENTO'!EF31 -> 0 | EP31: 0 | EQ31: 0 | ER31: 0 | ES31: 1 | ET31: 0 | EU31: 0 | EV31: 1 | EW31: 0 | EX31: 14393.93 | EY31: 0 | EZ31: 0 | FA31: 0 | FB31: 0 | FC31: 0 | FD31: 0 | FE31: 14393.93 | FF31: 14393.93 | FG31: 0 | FH31: 0 | FI31: 0 | FJ31: 0 | FK31: 0 | FL31: 0 | FM31: 0 | FN31: 0 | FO31: 0 | FP31: 0 | FQ31: 0 | FR31: 0 | FS31: 0 | FT31: 0 | FU31: 0 | FV31: 0 | FW31: 0 | FX31: 0 | FY31: 0 | FZ31: 0 | GA31: 0 | GB31: 0 | GC31: 0 | GD31: 0 | GE31: 0 | GF31: 0 | GG31: 0 | GH31: 0 | GI31: 0 | GJ31: 0 | GL31: 0 | GN31: 0 | GO31: 0 | GP31: 0 | GQ31: 0 | GR31: 0 | GS31: 0 | GT31: 0 | GU31: 0 | GV31: 0 | GW31: 0 | GX31: 0 | GY31: 0 | GZ31: 0 | HA31: 0 | HB31: 0 | HC31: 0 | HD31: 0 | HE31: 0 | HF31: 0 | HG31: 0 | HH31: 0 | HI31: 0 | HJ31: 0 | HK31: 0 | HL31: 0 | HM31: 0 | HN31: 0 | HO31: 0 | HP31: 0 | HW31: 17629.31 | HY31: 0 | HZ31: 0 | IA31: 0 | IB31: FALSE
A32: 005.388-00 | B32: 2022/0028814-001 | C32: FB | D32: 2022/0028814 | E32: DTC6900 | F32: 01/04/2026 | G32: 30/04/2026 | H32: CARLOS OMAR ALVES | I32: CARLOS OMAR ALVES | J32: ADAPTADO | K32: EMEF | L32: 0 | M32: 0 | O32: 6020.2022/0028814-2 | P32: 0 | Q32: 1 | R32: 4 | S32: 1 | U32: =Q32+'APONTAMENTO CREDENCIAMENTO'!U32 -> 1 | V32: =R32+'APONTAMENTO CREDENCIAMENTO'!V32 -> 4 | W32: =S32+'APONTAMENTO CREDENCIAMENTO'!W32 -> 1 | X32: =T32+'APONTAMENTO CREDENCIAMENTO'!X32 -> 0 | Y32: =U32+'APONTAMENTO CREDENCIAMENTO'!Y32 -> 1 | Z32: =V32+'APONTAMENTO CREDENCIAMENTO'!Z32 -> 4 | AA32: =W32+'APONTAMENTO CREDENCIAMENTO'!AA32 -> 1 | AB32: =X32+'APONTAMENTO CREDENCIAMENTO'!AB32 -> 0 | ... EF32: =EB32+'APONTAMENTO CREDENCIAMENTO'!EF32 -> 0 | EP32: 1 | EQ32: 0 | ER32: 1 | ES32: 4 | ET32: 0 | EU32: 0 | EV32: 6 | EX32: 0 | EY32: 0 | EZ32: 0 | FA32: 0 | FB32: 0 | FC32: 0 | FD32: 0 | GL32: 0 | HY32: 0 | HZ32: 0 | IA32: 0
A33: 005.388-00 | B33: 2022/0028814-001 | C33: FB | D33: 2022/0028814 | E33: DTC6900 | F33: 01/04/2026 | G33: 30/04/2026 | H33: CARLOS OMAR ALVES | I33: CARLOS OMAR ALVES | J33: ADAPTADO | K33: EMEE | L33: 0 | M33: 0 | O33: 6020.2022/0028814-2 | P33: 0 | U33: =Q33+'APONTAMENTO CREDENCIAMENTO'!U33 -> 0 | V33: =R33+'APONTAMENTO CREDENCIAMENTO'!V33 -> 0 | W33: =S33+'APONTAMENTO CREDENCIAMENTO'!W33 -> 0 | X33: =T33+'APONTAMENTO CREDENCIAMENTO'!X33 -> 0 | Y33: =U33+'APONTAMENTO CREDENCIAMENTO'!Y33 -> 0 | Z33: =V33+'APONTAMENTO CREDENCIAMENTO'!Z33 -> 0 | AA33: =W33+'APONTAMENTO CREDENCIAMENTO'!AA33 -> 0 | AB33: =X33+'APONTAMENTO CREDENCIAMENTO'!AB33 -> 0 | ... EF33: =EB33+'APONTAMENTO CREDENCIAMENTO'!EF33 -> 0 | EP33: 0 | EQ33: 0 | ER33: 0 | ES33: 0 | ET33: 0 | EU33: 0 | EV33: 0 | EX33: 0 | EY33: 0 | EZ33: 0 | FA33: 0 | FB33: 0 | FC33: 0 | FD33: 0 | GL33: 0 | HY33: 0 | HZ33: 0 | IA33: 0
A34: 005.388-00 | B34: 2022/0028814-001 | C34: FB | D34: 2022/0028814 | E34: DTC6900 | F34: 01/04/2026 | G34: 30/04/2026 | H34: CARLOS OMAR ALVES | I34: CARLOS OMAR ALVES | J34: ADAPTADO | K34: CEI | L34: 0 | M34: 0 | O34: 6020.2022/0028814-2 | P34: 0 | U34: =Q34+'APONTAMENTO CREDENCIAMENTO'!U34 -> 0 | V34: =R34+'APONTAMENTO CREDENCIAMENTO'!V34 -> 0 | W34: =S34+'APONTAMENTO CREDENCIAMENTO'!W34 -> 0 | X34: =T34+'APONTAMENTO CREDENCIAMENTO'!X34 -> 0 | Y34: =U34+'APONTAMENTO CREDENCIAMENTO'!Y34 -> 0 | Z34: =V34+'APONTAMENTO CREDENCIAMENTO'!Z34 -> 0 | AA34: =W34+'APONTAMENTO CREDENCIAMENTO'!AA34 -> 0 | AB34: =X34+'APONTAMENTO CREDENCIAMENTO'!AB34 -> 0 | ... EF34: =EB34+'APONTAMENTO CREDENCIAMENTO'!EF34 -> 0 | EP34: 0 | EQ34: 0 | ER34: 0 | ES34: 0 | ET34: 0 | EU34: 0 | EV34: 0 | EX34: 0 | EY34: 0 | EZ34: 0 | FA34: 0 | FB34: 0 | FC34: 0 | FD34: 0 | GL34: 0 | HY34: 0 | HZ34: 0 | IA34: 0
A35: 005.388-00 | B35: 2022/0028814-001 | C35: FB | D35: 2022/0028814 | E35: DTC6900 | F35: 01/04/2026 | G35: 30/04/2026 | H35: CARLOS OMAR ALVES | I35: CARLOS OMAR ALVES | J35: ADAPTADO | K35: CCA | L35: 0 | M35: 0 | O35: 6020.2022/0028814-2 | P35: 0 | U35: =Q35+'APONTAMENTO CREDENCIAMENTO'!U35 -> 0 | V35: =R35+'APONTAMENTO CREDENCIAMENTO'!V35 -> 0 | W35: =S35+'APONTAMENTO CREDENCIAMENTO'!W35 -> 0 | X35: =T35+'APONTAMENTO CREDENCIAMENTO'!X35 -> 0 | Y35: =U35+'APONTAMENTO CREDENCIAMENTO'!Y35 -> 0 | Z35: =V35+'APONTAMENTO CREDENCIAMENTO'!Z35 -> 0 | AA35: =W35+'APONTAMENTO CREDENCIAMENTO'!AA35 -> 0 | AB35: =X35+'APONTAMENTO CREDENCIAMENTO'!AB35 -> 0 | ... EF35: =EB35+'APONTAMENTO CREDENCIAMENTO'!EF35 -> 0 | EP35: 0 | EQ35: 0 | ER35: 0 | ES35: 0 | ET35: 0 | EU35: 0 | EV35: 0 | EX35: 0 | EY35: 0 | EZ35: 0 | FA35: 0 | FB35: 0 | FC35: 0 | FD35: 0 | FF35: 0 | FG35: 0 | FH35: 0 | FI35: 0 | FJ35: 0 | FK35: 0 | FL35: 0 | FM35: 0 | FN35: 0 | FO35: 0 | FP35: 0 | FQ35: 0 | FR35: 0 | FS35: 0 | FT35: 0 | FU35: 0 | FV35: 0 | FW35: 0 | FX35: 0 | FY35: 0 | FZ35: 0 | GA35: 0 | GB35: 0 | GC35: 0 | GD35: 0 | GE35: 0 | GF35: 0 | GG35: 0 | GH35: 0 | GI35: 0 | GJ35: 0 | GL35: 0 | HY35: 0 | HZ35: 0 | IA35: 0
A36: 019.284-00 | B36: 2022/0031991-001 | C36: 1 | D36: 2022/0031991 | E36: DTA8459 | F36: 01/04/2026 | G36: 30/04/2026 | H36: CRISTIANE ROSIMEIRE DIAS | I36: CRISTIANE ROSIMEIRE DIAS | J36: NORMAL | K36: EMEI | L36: 0 | M36: 0 | O36: 6020.2022/0031991-9 | P36: 0 | Q36: 3 | U36: =Q36+'APONTAMENTO CREDENCIAMENTO'!U36 -> 3 | V36: =R36+'APONTAMENTO CREDENCIAMENTO'!V36 -> 0 | W36: =S36+'APONTAMENTO CREDENCIAMENTO'!W36 -> 0 | X36: =T36+'APONTAMENTO CREDENCIAMENTO'!X36 -> 0 | Y36: =U36+'APONTAMENTO CREDENCIAMENTO'!Y36 -> 3 | Z36: =V36+'APONTAMENTO CREDENCIAMENTO'!Z36 -> 0 | AA36: =W36+'APONTAMENTO CREDENCIAMENTO'!AA36 -> 0 | AB36: =X36+'APONTAMENTO CREDENCIAMENTO'!AB36 -> 0 | ... EF36: =EB36+'APONTAMENTO CREDENCIAMENTO'!EF36 -> 0 | EP36: 3 | EQ36: 0 | ER36: 0 | ES36: 0 | ET36: 0 | EU36: 0 | EV36: 3 | EW36: 0 | EX36: 12115.28 | EY36: 0 | EZ36: 0 | FA36: -372.389 | FB36: 0 | FC36: 0 | FD36: 0 | FE36: 11742.891 | FF36: 12115.28 | FG36: -372.389 | FH36: 0 | FI36: 0 | FJ36: 0 | FK36: 0 | FL36: 0 | FM36: 0 | FN36: 0 | FO36: 0 | FP36: 0 | FQ36: 0 | FR36: 0 | FS36: 0 | FT36: 0 | FU36: 0 | FV36: 0 | FW36: 0 | FX36: 0 | FY36: 0 | FZ36: 0 | GA36: 0 | GB36: 0 | GC36: 0 | GD36: 0 | GE36: 0 | GF36: 0 | GG36: 0 | GH36: 0 | GI36: 0 | GJ36: 0 | GL36: 0 | GN36: 0 | GO36: 0 | GP36: 0 | GQ36: 0 | GR36: 0 | GS36: 0 | GT36: 0 | GU36: 0 | GV36: 0 | GW36: 0 | GX36: 0 | GY36: 0 | GZ36: 0 | HA36: 0 | HB36: 0 | HC36: 0 | HD36: 0 | HE36: 0 | HF36: 0 | HG36: 0 | HH36: 0 | HI36: 0 | HJ36: 0 | HK36: 0 | HL36: 0 | HM36: 0 | HN36: 0 | HO36: 0 | HP36: 0 | HW36: 17629.31 | HY36: 0 | HZ36: 0 | IA36: 0 | IB36: FALSE
A37: 019.284-00 | B37: 2022/0031991-001 | C37: FB | D37: 2022/0031991 | E37: DTA8459 | F37: 01/04/2026 | G37: 30/04/2026 | H37: CRISTIANE ROSIMEIRE DIAS | I37: CRISTIANE ROSIMEIRE DIAS | J37: NORMAL | K37: EMEF | L37: 0 | M37: 0 | O37: 6020.2022/0031991-9 | P37: 0 | Q37: 25 | U37: =Q37+'APONTAMENTO CREDENCIAMENTO'!U37 -> 24 | V37: =R37+'APONTAMENTO CREDENCIAMENTO'!V37 -> 0 | W37: =S37+'APONTAMENTO CREDENCIAMENTO'!W37 -> 0 | X37: =T37+'APONTAMENTO CREDENCIAMENTO'!X37 -> 0 | Y37: =U37+'APONTAMENTO CREDENCIAMENTO'!Y37 -> 24 | Z37: =V37+'APONTAMENTO CREDENCIAMENTO'!Z37 -> 0 | AA37: =W37+'APONTAMENTO CREDENCIAMENTO'!AA37 -> 0 | AB37: =X37+'APONTAMENTO CREDENCIAMENTO'!AB37 -> 0 | ... EF37: =EB37+'APONTAMENTO CREDENCIAMENTO'!EF37 -> 0 | EP37: 25 | EQ37: -1 | ER37: 0 | ES37: 0 | ET37: 0 | EU37: 0 | EV37: 24 | EX37: 0 | EY37: 0 | EZ37: 0 | FA37: 0 | FB37: 0 | FC37: 0 | FD37: 0 | GL37: 0 | HY37: 0 | HZ37: 0 | IA37: 0
A38: 019.284-00 | B38: 2022/0031991-001 | C38: FB | D38: 2022/0031991 | E38: DTA8459 | F38: 01/04/2026 | G38: 30/04/2026 | H38: CRISTIANE ROSIMEIRE DIAS | I38: CRISTIANE ROSIMEIRE DIAS | J38: NORMAL | K38: EMEE | L38: 0 | M38: 0 | O38: 6020.2022/0031991-9 | P38: 0 | U38: =Q38+'APONTAMENTO CREDENCIAMENTO'!U38 -> 0 | V38: =R38+'APONTAMENTO CREDENCIAMENTO'!V38 -> 0 | W38: =S38+'APONTAMENTO CREDENCIAMENTO'!W38 -> 0 | X38: =T38+'APONTAMENTO CREDENCIAMENTO'!X38 -> 0 | Y38: =U38+'APONTAMENTO CREDENCIAMENTO'!Y38 -> 0 | Z38: =V38+'APONTAMENTO CREDENCIAMENTO'!Z38 -> 0 | AA38: =W38+'APONTAMENTO CREDENCIAMENTO'!AA38 -> 0 | AB38: =X38+'APONTAMENTO CREDENCIAMENTO'!AB38 -> 0 | ... EF38: =EB38+'APONTAMENTO CREDENCIAMENTO'!EF38 -> 0 | EP38: 0 | EQ38: 0 | ER38: 0 | ES38: 0 | ET38: 0 | EU38: 0 | EV38: 0 | EX38: 0 | EY38: 0 | EZ38: 0 | FA38: 0 | FB38: 0 | FC38: 0 | FD38: 0 | GL38: 0 | HY38: 0 | HZ38: 0 | IA38: 0
A39: 019.284-00 | B39: 2022/0031991-001 | C39: FB | D39: 2022/0031991 | E39: DTA8459 | F39: 01/04/2026 | G39: 30/04/2026 | H39: CRISTIANE ROSIMEIRE DIAS | I39: CRISTIANE ROSIMEIRE DIAS | J39: NORMAL | K39: CEI | L39: 0 | M39: 0 | O39: 6020.2022/0031991-9 | P39: 0 | U39: =Q39+'APONTAMENTO CREDENCIAMENTO'!U39 -> 0 | V39: =R39+'APONTAMENTO CREDENCIAMENTO'!V39 -> 0 | W39: =S39+'APONTAMENTO CREDENCIAMENTO'!W39 -> 0 | X39: =T39+'APONTAMENTO CREDENCIAMENTO'!X39 -> 0 | Y39: =U39+'APONTAMENTO CREDENCIAMENTO'!Y39 -> 0 | Z39: =V39+'APONTAMENTO CREDENCIAMENTO'!Z39 -> 0 | AA39: =W39+'APONTAMENTO CREDENCIAMENTO'!AA39 -> 0 | AB39: =X39+'APONTAMENTO CREDENCIAMENTO'!AB39 -> 0 | ... EF39: =EB39+'APONTAMENTO CREDENCIAMENTO'!EF39 -> 0 | EP39: 0 | EQ39: 0 | ER39: 0 | ES39: 0 | ET39: 0 | EU39: 0 | EV39: 0 | EX39: 0 | EY39: 0 | EZ39: 0 | FA39: 0 | FB39: 0 | FC39: 0 | FD39: 0 | GL39: 0 | HY39: 0 | HZ39: 0 | IA39: 0
A40: 019.284-00 | B40: 2022/0031991-001 | C40: FB | D40: 2022/0031991 | E40: DTA8459 | F40: 01/04/2026 | G40: 30/04/2026 | H40: CRISTIANE ROSIMEIRE DIAS | I40: CRISTIANE ROSIMEIRE DIAS | J40: NORMAL | K40: CCA | L40: 0 | M40: 0 | O40: 6020.2022/0031991-9 | P40: 0 | U40: =Q40+'APONTAMENTO CREDENCIAMENTO'!U40 -> 0 | V40: =R40+'APONTAMENTO CREDENCIAMENTO'!V40 -> 0 | W40: =S40+'APONTAMENTO CREDENCIAMENTO'!W40 -> 0 | X40: =T40+'APONTAMENTO CREDENCIAMENTO'!X40 -> 0 | Y40: =U40+'APONTAMENTO CREDENCIAMENTO'!Y40 -> 0 | Z40: =V40+'APONTAMENTO CREDENCIAMENTO'!Z40 -> 0 | AA40: =W40+'APONTAMENTO CREDENCIAMENTO'!AA40 -> 0 | AB40: =X40+'APONTAMENTO CREDENCIAMENTO'!AB40 -> 0 | ... EF40: =EB40+'APONTAMENTO CREDENCIAMENTO'!EF40 -> 0 | EP40: 0 | EQ40: 0 | ER40: 0 | ES40: 0 | ET40: 0 | EU40: 0 | EV40: 0 | EX40: 0 | EY40: 0 | EZ40: 0 | FA40: 0 | FB40: 0 | FC40: 0 | FD40: 0 | FF40: 0 | FG40: 0 | FH40: 0 | FI40: 0 | FJ40: 0 | FK40: 0 | FL40: 0 | FM40: 0 | FN40: 0 | FO40: 0 | FP40: 0 | FQ40: 0 | FR40: 0 | FS40: 0 | FT40: 0 | FU40: 0 | FV40: 0 | FW40: 0 | FX40: 0 | FY40: 0 | FZ40: 0 | GA40: 0 | GB40: 0 | GC40: 0 | GD40: 0 | GE40: 0 | GF40: 0 | GG40: 0 | GH40: 0 | GI40: 0 | GJ40: 0 | GL40: 0 | HY40: 0 | HZ40: 0 | IA40: 0
...

Sheet APONTAMENTO CREDENCIAMENTO
A1: Freguesia / Brasilândia | G1: ='BASE C'!E4 -> ABRIL | I1: APONTAMENTO CREDENCIAMENTO | EL1: ATENÇÃO
G2: 01/06 a 30/06/2025
A3: 1 | B3: =A3+1 -> 2 | C3: =B3+1 -> 3 | D3: 1 | E3: =D3+1 -> 2 | F3: =E3+1 -> 3 | G3: =F3+1 -> 4 | H3: =G3+1 -> 5 | I3: =H3+1 -> 6 | J3: =I3+1 -> 7 | K3: =J3+1 -> 8 | L3: =K3+1 -> 9 | M3: =L3+1 -> 10 | N3: 10 | O3: =N3+1 -> 11 | P3: 13 | Q3: =P3+1 -> 14 | R3: =Q3+1 -> 15 | S3: =R3+1 -> 16 | T3: =S3+1 -> 17 | U3: =T3+1 -> 18 | V3: =U3+1 -> 19 | W3: =V3+1 -> 20 | X3: =W3+1 -> 21 | ... EL3: =EK3+1 -> 139 | EM3: 140 | EN3: =EM3+1 -> 141 | EO3: =EN3+1 -> 142 | EP3: =EO3+1 -> 143 | EQ3: =EP3+1 -> 144 | ER3: =EQ3+1 -> 145 | ES3: =ER3+1 -> 146 | ET3: =ES3+1 -> 147 | EU3: =ET3+1 -> 148 | ... IA3: =HZ3+1 -> 232
A4: CRMC | B4: OS | C4: DRE | D4: CONTRATO | E4: PLACA | F4: PERÍODO | H4: EMPRESA | I4: NOME CONDUTOR | J4: TIPO DE VEÍCULO (NORMAL, ADAPTADO) | K4: TIPO DE ATENDIMENTO | L4: TOTAL CONT REG | M4: TOTAL CONT CAD | N4: KM ADICIONAL | O4: SEI | P4: Tipo Optante | Q4: =F5 -> 01/04/2026 | U4: =Q4+1 -> 46114 | Y4: =U4+1 -> 46115 | AC4: =Y4+1 -> 46116 | AG4: =AC4+1 -> 46117 | AK4: =AG4+1 -> 46118 | AO4: =AK4+1 -> 46119 | AS4: =AO4+1 -> 46120 | AW4: =AS4+1 -> 46121 | BA4: =AW4+1 -> 46122 | BE4: =BA4+1 -> 46123 | BI4: =BE4+1 -> 46124 | BM4: =BI4+1 -> 46125 | BQ4: =BM4+1 -> 46126 | BU4: =BQ4+1 -> 46127 | BY4: =BU4+1 -> 46128 | CC4: =BY4+1 -> 46129 | CG4: =CC4+1 -> 46130 | CK4: =CG4+1 -> 46131 | CO4: =CK4+1 -> 46132 | CS4: =CO4+1 -> 46133 | CW4: =CS4+1 -> 46134 | DA4: =CW4+1 -> 46135 | DE4: =DA4+1 -> 46136 | DI4: =DE4+1 -> 46137 | DM4: =DI4+1 -> 46138 | DQ4: =DM4+1 -> 46139 | DU4: =DQ4+1 -> 46140 | DY4: =DU4+1 -> 46141 | EC4: =DY4+1 -> 46142 | EK4: FALTAS - APONTAR AS DATAS | EL4: OBSERVAÇÕES ALUNO PRESENCIAL COLUNAS FINAIS | EM4: Ajuste positivo | EN4: Ajuste negativo | EO4: Desconto faltas | EP4: TOTAL ALUNOS N CAD(30 DIAS) | EQ4: TOTAL ALUNOS N CAD(MENOS DE 30 DIAS) | ER4: TOTAL ALUNOS ATIV.COMPL. N CAD | ES4: TOTAL ALUNOS CAD (30 DIAS) | ET4: TOTAL ALUNOS CAD (MENOS DE 30 DIAS) | EU4: TOTAL ALUNOS ATIV.COMPL. CAD | EV4: TOTAL GERAL | EW4: Contratos Especiais (Valor fixo) | EX4: Valor total alunos presenciais (30 dias) | EY4: Ativ.Complementar Continuada | EZ4: Valor alunos presenciais (menos de 30 dias) | FA4: Saida de alunos ao longo do mês | FB4: CCA | FC4: Valor km adicional | FD4: Outros apontamentos | FE4: VALOR ATESTE | FF4: 30 | FG4: =FF4-1 -> 29 | FH4: =FG4-1 -> 28 | FI4: =FH4-1 -> 27 | FJ4: =FI4-1 -> 26 | FK4: =FJ4-1 -> 25 | FL4: =FK4-1 -> 24 | FM4: =FL4-1 -> 23 | FN4: =FM4-1 -> 22 | ... GI4: =GH4-1 -> 1 | GJ4: 1 | GK4: Multa Contratual | GL4: CÁLCULO | GM4: DIAS | GN4: 29 | GO4: =GN4-1 -> 28 | GP4: =GO4-1 -> 27 | GQ4: =GP4-1 -> 26 | GR4: =GQ4-1 -> 25 | GS4: =GR4-1 -> 24 | GT4: =GS4-1 -> 23 | GU4: =GT4-1 -> 22 | GV4: =GU4-1 -> 21 | ... HP4: =HO4-1 -> 1 | HW4: VALOR ATESTE | HY4: Ajuste positivo | HZ4: Ajuste negativo | IA4: Desconto faltas
F5: 01/04/2026 | G5: 30/04/2026 | Q5: N CAD presencial | R5: CAD | S5: AT. COMPL. N CAD | T5: AT. COMPL. CAD | U5: N CAD presencial | V5: CAD | W5: AT. COMPL. N CAD | X5: AT. COMPL. CAD | Y5: N CAD presencial | Z5: CAD | AA5: AT. COMPL. N CAD | AB5: AT. COMPL. CAD | AC5: N CAD presencial | AD5: CAD | AE5: AT. COMPL. N CAD | AF5: AT. COMPL. CAD | AG5: N CAD presencial | AH5: CAD | AI5: AT. COMPL. N CAD | AJ5: AT. COMPL. CAD | AK5: N CAD presencial | AL5: CAD | AM5: AT. COMPL. N CAD | AN5: AT. COMPL. CAD | AO5: N CAD presencial | AP5: CAD | AQ5: AT. COMPL. N CAD | AR5: AT. COMPL. CAD | AS5: N CAD presencial | AT5: CAD | AU5: AT. COMPL. N CAD | AV5: AT. COMPL. CAD | AW5: N CAD presencial | AX5: CAD | AY5: AT. COMPL. N CAD | AZ5: AT. COMPL. CAD | BA5: N CAD presencial | BB5: CAD | BC5: AT. COMPL. N CAD | BD5: AT. COMPL. CAD | BE5: N CAD presencial | BF5: CAD | BG5: AT. COMPL. N CAD | BH5: AT. COMPL. CAD | BI5: N CAD presencial | BJ5: CAD | BK5: AT. COMPL. N CAD | BL5: AT. COMPL. CAD | BM5: N CAD presencial | BN5: CAD | BO5: AT. COMPL. N CAD | BP5: AT. COMPL. CAD | BQ5: N CAD presencial | BR5: CAD | BS5: AT. COMPL. N CAD | BT5: AT. COMPL. CAD | BU5: N CAD presencial | BV5: CAD | BW5: AT. COMPL. N CAD | BX5: AT. COMPL. CAD | BY5: N CAD presencial | BZ5: CAD | CA5: AT. COMPL. N CAD | CB5: AT. COMPL. CAD | CC5: N CAD presencial | CD5: CAD | CE5: AT. COMPL. N CAD | CF5: AT. COMPL. CAD | CG5: N CAD presencial | CH5: CAD | CI5: AT. COMPL. N CAD | CJ5: AT. COMPL. CAD | CK5: N CAD presencial | CL5: CAD | CM5: AT. COMPL. N CAD | CN5: AT. COMPL. CAD | CO5: N CAD presencial | CP5: CAD | CQ5: AT. COMPL. N CAD | CR5: AT. COMPL. CAD | CS5: N CAD presencial | CT5: CAD | CU5: AT. COMPL. N CAD | CV5: AT. COMPL. CAD | CW5: N CAD presencial | CX5: CAD | CY5: AT. COMPL. N CAD | CZ5: AT. COMPL. CAD | DA5: N CAD presencial | DB5: CAD | DC5: AT. COMPL. N CAD | DD5: AT. COMPL. CAD | DE5: N CAD presencial | DF5: CAD | DG5: AT. COMPL. N CAD | DH5: AT. COMPL. CAD | DI5: N CAD presencial | DJ5: CAD | DK5: AT. COMPL. N CAD | DL5: AT. COMPL. CAD | DM5: N CAD presencial | DN5: CAD | DO5: AT. COMPL. N CAD | DP5: AT. COMPL. CAD | DQ5: N CAD presencial | DR5: CAD | DS5: AT. COMPL. N CAD | DT5: AT. COMPL. CAD | DU5: N CAD presencial | DV5: CAD | DW5: AT. COMPL. N CAD | DX5: AT. COMPL. CAD | DY5: N CAD presencial | DZ5: CAD | EA5: AT. COMPL. N CAD | EB5: AT. COMPL. CAD | EC5: N CAD presencial | ED5: CAD | EE5: AT. COMPL. N CAD | EF5: AT. COMPL. CAD | EG5: N CAD presencial | EH5: CAD | EI5: AT. COMPL. N CAD | EJ5: AT. COMPL. CAD
