Workbook
Name \a: #REF!
Name \a: #REF!
Name \p: #REF!
Name \p: #REF!
Name _______xlnm.Print_Titles: #REF!
Name _______xlnm_Print_Titles: NA()
Name ______xlnm._FilterDatabase: "#ref!"
Name ______xlnm.Print_Titles: #REF!
Name ______xlnm__FilterDatabase: "#ref!"
Name ______xlnm_Print_Titles: NA()
Name _____xlfn_BAHTTEXT: NA()
Name _____xlfn_SUMIFS: NA()
Name _____xlnm._FilterDatabase: "#ref!"
Name _____xlnm.Print_Titles: #REF!
Name _____xlnm__FilterDatabase: "#ref!"
Name _____xlnm_Print_Titles: NA()
Name ____xlfn_BAHTTEXT: NA()
Name ____xlfn_SUMIFS: NA()
Name ____xlnm._FilterDatabase: "#ref!"
Name ____xlnm.Print_Titles: #REF!
Name ____xlnm__FilterDatabase: "#ref!"
Name ____xlnm_Print_Titles: NA()
Name ___xlfn_BAHTTEXT: NA()
Name ___xlfn_SUMIFS: NA()
Name ___xlnm._FilterDatabase: "#ref!"
Name ___xlnm.Print_Titles: #REF!
Name ___xlnm__FilterDatabase: "#ref!"
Name ___xlnm_Print_Titles: NA()
Name __TAB3688: #REF!
Name __xlfn_BAHTTEXT: NA()
Name __xlfn_SUMIFS: NA()
Name __xlnm._FilterDatabase: "#ref!"
Name __xlnm.Print_Titles: #REF!
Name __xlnm__FilterDatabase: "#ref!"
Name __xlnm_Print_Titles: NA()
Name _TAB3688: #REF!
Name _TAB3688: #REF!
Name a: #REF!
Name abr: #REF!
Name abr: #REF!
Name abril: #REF!
Name ACRESCENTAR: #REF!
Name ADAPTADO: '[1]APONTAMENTO CREDENCIAMENTO'!#REF!
Name ADAPTADO: 'APONTAMENTO CREDENCIAMENTO'!#REF!
Name AGOSTO: #REF!
Name AI: #REF!
Name AI: #REF!
Name AII: #REF!
Name AII: #REF!
Name AK: #REF!
Name AK: #REF!
Name AL: #REF!
Name AL: #REF!
Name AMPLIAR: #REF!
Name AMPLIAR: #REF!
Name ApagaAtesteFis: 'ATESTE-LIQ-FIS'!$A$4:$K$3898
Name ApagaBaseC: 'BASE C'!$A$11:$N$4950
Name ApagaDadosA: 'APONTAMENTO CREDENCIAMENTO'!$Q$6:$T$3059
Name ApagaDadosC: CONTINUA!$L$6:$BU$3077
Name ApagarDadosDigitados: #REF!

Sheet APONTAMENTO CREDENCIAMENTO
A1: Guaianases | G1: ='BASE C'!E4 -> ABRIL | I1: APONTAMENTO CREDENCIAMENTO
G2: 01/06 a 30/06/2025
A3: 1 | B3: =A3+1 -> 2 | C3: =B3+1 -> 3 | D3: 1 | E3: =D3+1 -> 2 | F3: =E3+1 -> 3 | G3: =F3+1 -> 4 | H3: =G3+1 -> 5 | I3: =H3+1 -> 6 | J3: =I3+1 -> 7 | K3: =J3+1 -> 8 | L3: =K3+1 -> 9 | M3: =L3+1 -> 10 | N3: 10 | O3: =N3+1 -> 11 | P3: 13 | Q3: =P3+1 -> 14 | R3: =Q3+1 -> 15 | S3: =R3+1 -> 16 | T3: =S3+1 -> 17
A4: CRMC | B4: OS | C4: DRE | D4: CONTRATO | E4: PLACA | F4: PERÍODO | H4: EMPRESA | I4: NOME CONDUTOR | J4: TIPO DE VEÍCULO (NORMAL, ADAPTADO) | K4: TIPO DE ATENDIMENTO | L4: TOTAL CONT REG | M4: TOTAL CONT CAD | N4: KM ADICIONAL | O4: SEI | P4: Tipo Optante | Q4: =F5 -> 01/04/2026 | W4: =Q4+1 -> 46114 | AC4: =W4+1 -> 46115 | AI4: =AC4+1 -> 46116 | AO4: =AI4+1 -> 46117 | AU4: =AO4+1 -> 46118 | BA4: =AU4+1 -> 46119 | BG4: =BA4+1 -> 46120 | BM4: =BG4+1 -> 46121 | BS4: =BM4+1 -> 46122 | BY4: =BS4+1 -> 46123 | CE4: =BY4+1 -> 46124 | CK4: =CE4+1 -> 46125 | CQ4: =CK4+1 -> 46126 | CW4: =CQ4+1 -> 46127 | DC4: =CW4+1 -> 46128 | DI4: =DC4 -> 46128 | DO4: =DI4+1 -> 46129 | DU4: =DO4+1 -> 46130 | EA4: =DU4+1 -> 46131 | EG4: =EA4+1 -> 46132 | EM4: =EG4+1 -> 46133 | ES4: =EM4+1 -> 46134 | EY4: =ES4+1 -> 46135 | FE4: =EY4+1 -> 46136 | FK4: =FE4+1 -> 46137 | FQ4: =FK4+1 -> 46138 | FW4: =FQ4+1 -> 46139 | GC4: =FW4+1 -> 46140 | GI4: =GC4+1 -> 46141 | GO4: =GI4+1 -> 46142 | GU4: =GO4+1 -> 46143
F5: 01/04/2026 | G5: 30/04/2026 | Q5: N CAD presencial | R5: CAD | S5: AT. COMPL. N CAD | T5: AT. COMPL. CAD | U5: Cont N CAD | V5: Cont CAD | W5: N CAD presencial | X5: CAD | Y5: AT. COMPL. N CAD | Z5: AT. COMPL. CAD | AA5: Cont N CAD | AB5: Cont CAD | AC5: N CAD presencial | AD5: CAD | AE5: AT. COMPL. N CAD | AF5: AT. COMPL. CAD | AG5: Cont N CAD | AH5: Cont CAD | AI5: N CAD presencial | AJ5: CAD | AK5: AT. COMPL. N CAD | AL5: AT. COMPL. CAD | AM5: Cont N CAD | AN5: Cont CAD | AO5: N CAD presencial | AP5: CAD | AQ5: AT. COMPL. N CAD | AR5: AT. COMPL. CAD | AS5: Cont N CAD | AT5: Cont CAD | AU5: N CAD presencial | AV5: CAD | AW5: AT. COMPL. N CAD | AX5: AT. COMPL. CAD | AY5: Cont N CAD | AZ5: Cont CAD | BA5: N CAD presencial | BB5: CAD | BC5: AT. COMPL. N CAD | BD5: AT. COMPL. CAD | BE5: Cont N CAD | BF5: Cont CAD | BG5: N CAD presencial | BH5: CAD | BI5: AT. COMPL. N CAD | BJ5: AT. COMPL. CAD | BK5: Cont N CAD | BL5: Cont CAD | BM5: N CAD presencial | BN5: CAD | BO5: AT. COMPL. N CAD | BP5: AT. COMPL. CAD | BQ5: Cont N CAD | BR5: Cont CAD | BS5: N CAD presencial | BT5: CAD | BU5: AT. COMPL. N CAD | BV5: AT. COMPL. CAD | BW5: Cont N CAD | BX5: Cont CAD | BY5: N CAD presencial | BZ5: CAD | CA5: AT. COMPL. N CAD | CB5: AT. COMPL. CAD | CC5: Cont N CAD | CD5: Cont CAD | CE5: N CAD presencial | CF5: CAD | CG5: AT. COMPL. N CAD | CH5: AT. COMPL. CAD | CI5: Cont N CAD | CJ5: Cont CAD | CK5: N CAD presencial | CL5: CAD | CM5: AT. COMPL. N CAD | CN5: AT. COMPL. CAD | CO5: Cont N CAD | CP5: Cont CAD | CQ5: N CAD presencial | CR5: CAD | CS5: AT. COMPL. N CAD | CT5: AT. COMPL. CAD | CU5: Cont N CAD | CV5: Cont CAD | CW5: N CAD presencial | CX5: CAD | CY5: AT. COMPL. N CAD | CZ5: AT. COMPL. CAD | DA5: Cont N CAD | DB5: Cont CAD | DC5: N CAD presencial | DD5: CAD | DE5: AT. COMPL. N CAD | DF5: AT. COMPL. CAD | DG5: Cont N CAD | DH5: Cont CAD | DI5: N CAD presencial | DJ5: CAD | DK5: AT. COMPL. N CAD | DL5: AT. COMPL. CAD | DM5: Cont N CAD | DN5: Cont CAD | DO5: N CAD presencial | DP5: CAD | DQ5: AT. COMPL. N CAD | DR5: AT. COMPL. CAD | DS5: Cont N CAD | DT5: Cont CAD | DU5: N CAD presencial | DV5: CAD | DW5: AT. COMPL. N CAD | DX5: AT. COMPL. CAD | DY5: Cont N CAD | DZ5: Cont CAD | EA5: N CAD presencial | EB5: CAD | EC5: AT. COMPL. N CAD | ED5: AT. COMPL. CAD | EE5: Cont N CAD | EF5: Cont CAD | EG5: N CAD presencial | EH5: CAD | EI5: AT. COMPL. N CAD | EJ5: AT. COMPL. CAD | EK5: Cont N CAD | EL5: Cont CAD | EM5: N CAD presencial | EN5: CAD | EO5: AT. COMPL. N CAD | EP5: AT. COMPL. CAD | EQ5: Cont N CAD | ER5: Cont CAD | ES5: N CAD presencial | ET5: CAD | EU5: AT. COMPL. N CAD | EV5: AT. COMPL. CAD | EW5: Cont N CAD | EX5: Cont CAD | EY5: N CAD presencial | EZ5: CAD | FA5: AT. COMPL. N CAD | FB5: AT. COMPL. CAD | FC5: Cont N CAD | FD5: Cont CAD | FE5: N CAD presencial | FF5: CAD | FG5: AT. COMPL. N CAD | FH5: AT. COMPL. CAD | FI5: Cont N CAD | FJ5: Cont CAD | FK5: N CAD presencial | FL5: CAD | FM5: AT. COMPL. N CAD | FN5: AT. COMPL. CAD | FO5: Cont N CAD | FP5: Cont CAD | FQ5: N CAD presencial | FR5: CAD | FS5: AT. COMPL. N CAD | FT5: AT. COMPL. CAD | FU5: Cont N CAD | FV5: Cont CAD | FW5: N CAD presencial | FX5: CAD | FY5: AT. COMPL. N CAD | FZ5: AT. COMPL. CAD | GA5: Cont N CAD | GB5: Cont CAD | GC5: N CAD presencial | GD5: CAD | GE5: AT. COMPL. N CAD | GF5: AT. COMPL. CAD | GG5: Cont N CAD | GH5: Cont CAD | GI5: N CAD presencial | GJ5: CAD | GK5: AT. COMPL. N CAD | GL5: AT. COMPL. CAD | GM5: Cont N CAD | GN5: Cont CAD | GO5: N CAD presencial | GP5: CAD | GQ5: AT. COMPL. N CAD | GR5: AT. COMPL. CAD | GS5: Cont N CAD | GT5: Cont CAD | GU5: N CAD presencial | GV5: CAD | GW5: AT. COMPL. N CAD | GX5: AT. COMPL. CAD | GY5: Cont N CAD | GZ5: Cont CAD
A6: 019.832-00 | B6: 2022/0031800-001 | C6: 1 | D6: 2022/0031800 | E6: DJB1584 | F6: 01/04/2026 | G6: 30/04/2026 | H6: AJENIAS PEREIRA | I6: AJENIAS PEREIRA | J6: NORMAL | K6: EMEI | L6: =CONTINUA!BV6 -> 0 | M6: =CONTINUA!BW6 -> 0 | O6: 6020.2022/0031800-9 | P6: 0 | Q6: 4 | S6: 0 | U6: 0 | V6: 0 | W6: 4 | Y6: 0 | AA6: 0 | AB6: 0 | AC6: 4 | AE6: 0 | AG6: 0 | AH6: 0 | AI6: 4 | AK6: 0 | AM6: 0 | AN6: 0 | AO6: 4 | AQ6: 0 | AS6: 0 | AT6: 0 | AU6: 4 | AW6: 0 | AY6: 0 | AZ6: 0 | BA6: 4 | BC6: 0 | BE6: 0 | BF6: 0 | BG6: 4 | BI6: 0 | BK6: 0 | BL6: 0 | BM6: 4 | BO6: 0 | BQ6: 0 | BR6: 0 | BS6: 4 | BU6: 0 | BW6: 0 | BX6: 0 | BY6: 4 | CA6: 0 | CC6: 0 | CD6: 0 | CE6: 4 | CG6: 0 | CI6: 0 | CJ6: 0 | CK6: 4 | CM6: 0 | CO6: 0 | CP6: 0 | CQ6: 4 | CS6: 0 | CU6: 0 | CV6: 0 | CW6: 4 | CY6: 0 | DA6: 0 | DB6: 0 | DC6: 4 | DE6: 0 | DG6: 0 | DH6: 0 | DI6: 4 | DK6: 0 | DM6: 0 | DN6: 0 | DO6: 4 | DQ6: 0 | DS6: 0 | DT6: 0 | DU6: 4 | DW6: 0 | DY6: 0 | DZ6: 0 | EA6: 4 | EC6: 0 | EE6: 0 | EF6: 0 | EG6: 4 | EI6: 0 | EK6: 0 | EL6: 0 | EM6: 4 | EO6: 0 | EQ6: 0 | ER6: 0 | ES6: 4 | EU6: 0 | EW6: 0 | EX6: 0 | EY6: 4 | FA6: 0 | FC6: 0 | FD6: 0 | FE6: 4 | FG6: 0 | FI6: 0 | FJ6: 0 | FK6: 4 | FM6: 0 | FO6: 0 | FP6: 0 | FQ6: 4 | FS6: 0 | FU6: 0 | FV6: 0 | FW6: 4 | FY6: 0 | GA6: 0 | GB6: 0 | GC6: 4 | GE6: 0 | GG6: 0 | GH6: 0 | GI6: 4 | GK6: 0 | GM6: 0 | GN6: 0 | GO6: 4 | GQ6: 0 | GS6: 0 | GT6: 0 | GU6: 4 | GW6: 0 | GY6: 0 | GZ6: 0
A7: 019.832-00 | B7: 2022/0031800-001 | C7: G | D7: 2022/0031800 | E7: DJB1584 | F7: 01/04/2026 | G7: 30/04/2026 | H7: AJENIAS PEREIRA | I7: AJENIAS PEREIRA | J7: NORMAL | K7: EMEF | L7: =CONTINUA!BV7 -> 0 | M7: =CONTINUA!BW7 -> 0 | O7: 6020.2022/0031800-9 | P7: 0 | Q7: 49 | S7: 0 | U7: 0 | V7: 0 | W7: 49 | Y7: 0 | AA7: 0 | AB7: 0 | AC7: 49 | AE7: 0 | AG7: 0 | AH7: 0 | AI7: 49 | AK7: 0 | AM7: 0 | AN7: 0 | AO7: 49 | AQ7: 0 | AS7: 0 | AT7: 0 | AU7: 49 | AW7: 0 | AY7: 0 | AZ7: 0 | BA7: 49 | BC7: 0 | BE7: 0 | BF7: 0 | BG7: 49 | BI7: 0 | BK7: 0 | BL7: 0 | BM7: 49 | BO7: 0 | BQ7: 0 | BR7: 0 | BS7: 49 | BU7: 0 | BW7: 0 | BX7: 0 | BY7: 49 | CA7: 0 | CC7: 0 | CD7: 0 | CE7: 49 | CG7: 0 | CI7: 0 | CJ7: 0 | CK7: 49 | CM7: 0 | CO7: 0 | CP7: 0 | CQ7: 49 | CS7: 0 | CU7: 0 | CV7: 0 | CW7: 49 | CY7: 0 | DA7: 0 | DB7: 0 | DC7: 49 | DE7: 0 | DG7: 0 | DH7: 0 | DI7: 49 | DK7: 0 | DM7: 0 | DN7: 0 | DO7: 49 | DQ7: 0 | DS7: 0 | DT7: 0 | DU7: 49 | DW7: 0 | DY7: 0 | DZ7: 0 | EA7: 49 | EC7: 0 | EE7: 0 | EF7: 0 | EG7: 49 | EI7: 0 | EK7: 0 | EL7: 0 | EM7: 49 | EO7: 0 | EQ7: 0 | ER7: 0 | ES7: 49 | EU7: 0 | EW7: 0 | EX7: 0 | EY7: 49 | FA7: 0 | FC7: 0 | FD7: 0 | FE7: 49 | FG7: 0 | FI7: 0 | FJ7: 0 | FK7: 49 | FM7: 0 | FO7: 0 | FP7: 0 | FQ7: 49 | FS7: 0 | FU7: 0 | FV7: 0 | FW7: 49 | FY7: 0 | GA7: 0 | GB7: 0 | GC7: 49 | GE7: 0 | GG7: 0 | GH7: 0 | GI7: 49 | GK7: 0 | GM7: 0 | GN7: 0 | GO7: 49 | GQ7: 0 | GS7: 0 | GT7: 0 | GU7: 49 | GW7: 0 | GY7: 0 | GZ7: 0
A8: 019.832-00 | B8: 2022/0031800-001 | C8: G | D8: 2022/0031800 | E8: DJB1584 | F8: 01/04/2026 | G8: 30/04/2026 | H8: AJENIAS PEREIRA | I8: AJENIAS PEREIRA | J8: NORMAL | K8: EMEE | L8: =CONTINUA!BV8 -> 0 | M8: =CONTINUA!BW8 -> 0 | O8: 6020.2022/0031800-9 | P8: 0 | Q8: 0 | S8: 0 | U8: 0 | V8: 0 | W8: 0 | Y8: 0 | AA8: 0 | AB8: 0 | AC8: 0 | AE8: 0 | AG8: 0 | AH8: 0 | AI8: 0 | AK8: 0 | AM8: 0 | AN8: 0 | AO8: 0 | AQ8: 0 | AS8: 0 | AT8: 0 | AU8: 0 | AW8: 0 | AY8: 0 | AZ8: 0 | BA8: 0 | BC8: 0 | BE8: 0 | BF8: 0 | BG8: 0 | BI8: 0 | BK8: 0 | BL8: 0 | BM8: 0 | BO8: 0 | BQ8: 0 | BR8: 0 | BS8: 0 | BU8: 0 | BW8: 0 | BX8: 0 | BY8: 0 | CA8: 0 | CC8: 0 | CD8: 0 | CE8: 0 | CG8: 0 | CI8: 0 | CJ8: 0 | CK8: 0 | CM8: 0 | CO8: 0 | CP8: 0 | CQ8: 0 | CS8: 0 | CU8: 0 | CV8: 0 | CW8: 0 | CY8: 0 | DA8: 0 | DB8: 0 | DC8: 0 | DE8: 0 | DG8: 0 | DH8: 0 | DI8: 0 | DK8: 0 | DM8: 0 | DN8: 0 | DO8: 0 | DQ8: 0 | DS8: 0 | DT8: 0 | DU8: 0 | DW8: 0 | DY8: 0 | DZ8: 0 | EA8: 0 | EC8: 0 | EE8: 0 | EF8: 0 | EG8: 0 | EI8: 0 | EK8: 0 | EL8: 0 | EM8: 0 | EO8: 0 | EQ8: 0 | ER8: 0 | ES8: 0 | EU8: 0 | EW8: 0 | EX8: 0 | EY8: 0 | FA8: 0 | FC8: 0 | FD8: 0 | FE8: 0 | FG8: 0 | FI8: 0 | FJ8: 0 | FK8: 0 | FM8: 0 | FO8: 0 | FP8: 0 | FQ8: 0 | FS8: 0 | FU8: 0 | FV8: 0 | FW8: 0 | FY8: 0 | GA8: 0 | GB8: 0 | GC8: 0 | GE8: 0 | GG8: 0 | GH8: 0 | GI8: 0 | GK8: 0 | GM8: 0 | GN8: 0 | GO8: 0 | GQ8: 0 | GS8: 0 | GT8: 0 | GU8: 0 | GW8: 0 | GY8: 0 | GZ8: 0
A9: 019.832-00 | B9: 2022/0031800-001 | C9: G | D9: 2022/0031800 | E9: DJB1584 | F9: 01/04/2026 | G9: 30/04/2026 | H9: AJENIAS PEREIRA | I9: AJENIAS PEREIRA | J9: NORMAL | K9: CEI | L9: =CONTINUA!BV9 -> 0 | M9: =CONTINUA!BW9 -> 0 | O9: 6020.2022/0031800-9 | P9: 0 | Q9: 0 | S9: 0 | U9: 0 | V9: 0 | W9: 0 | Y9: 0 | AA9: 0 | AB9: 0 | AC9: 0 | AE9: 0 | AG9: 0 | AH9: 0 | AI9: 0 | AK9: 0 | AM9: 0 | AN9: 0 | AO9: 0 | AQ9: 0 | AS9: 0 | AT9: 0 | AU9: 0 | AW9: 0 | AY9: 0 | AZ9: 0 | BA9: 0 | BC9: 0 | BE9: 0 | BF9: 0 | BG9: 0 | BI9: 0 | BK9: 0 | BL9: 0 | BM9: 0 | BO9: 0 | BQ9: 0 | BR9: 0 | BS9: 0 | BU9: 0 | BW9: 0 | BX9: 0 | BY9: 0 | CA9: 0 | CC9: 0 | CD9: 0 | CE9: 0 | CG9: 0 | CI9: 0 | CJ9: 0 | CK9: 0 | CM9: 0 | CO9: 0 | CP9: 0 | CQ9: 0 | CS9: 0 | CU9: 0 | CV9: 0 | CW9: 0 | CY9: 0 | DA9: 0 | DB9: 0 | DC9: 0 | DE9: 0 | DG9: 0 | DH9: 0 | DI9: 0 | DK9: 0 | DM9: 0 | DN9: 0 | DO9: 0 | DQ9: 0 | DS9: 0 | DT9: 0 | DU9: 0 | DW9: 0 | DY9: 0 | DZ9: 0 | EA9: 0 | EC9: 0 | EE9: 0 | EF9: 0 | EG9: 0 | EI9: 0 | EK9: 0 | EL9: 0 | EM9: 0 | EO9: 0 | EQ9: 0 | ER9: 0 | ES9: 0 | EU9: 0 | EW9: 0 | EX9: 0 | EY9: 0 | FA9: 0 | FC9: 0 | FD9: 0 | FE9: 0 | FG9: 0 | FI9: 0 | FJ9: 0 | FK9: 0 | FM9: 0 | FO9: 0 | FP9: 0 | FQ9: 0 | FS9: 0 | FU9: 0 | FV9: 0 | FW9: 0 | FY9: 0 | GA9: 0 | GB9: 0 | GC9: 0 | GE9: 0 | GG9: 0 | GH9: 0 | GI9: 0 | GK9: 0 | GM9: 0 | GN9: 0 | GO9: 0 | GQ9: 0 | GS9: 0 | GT9: 0 | GU9: 0 | GW9: 0 | GY9: 0 | GZ9: 0
A10: 019.832-00 | B10: 2022/0031800-001 | C10: G | D10: 2022/0031800 | E10: DJB1584 | F10: 01/04/2026 | G10: 30/04/2026 | H10: AJENIAS PEREIRA | I10: AJENIAS PEREIRA | J10: NORMAL | K10: CCA | L10: =CONTINUA!BV10 -> 0 | M10: =CONTINUA!BW10 -> 0 | O10: 6020.2022/0031800-9 | P10: 0 | Q10: 0 | S10: 0 | U10: 0 | V10: 0 | W10: 0 | Y10: 0 | AA10: 0 | AB10: 0 | AC10: 0 | AE10: 0 | AG10: 0 | AH10: 0 | AI10: 0 | AK10: 0 | AM10: 0 | AN10: 0 | AO10: 0 | AQ10: 0 | AS10: 0 | AT10: 0 | AU10: 0 | AW10: 0 | AY10: 0 | AZ10: 0 | BA10: 0 | BC10: 0 | BE10: 0 | BF10: 0 | BG10: 0 | BI10: 0 | BK10: 0 | BL10: 0 | BM10: 0 | BO10: 0 | BQ10: 0 | BR10: 0 | BS10: 0 | BU10: 0 | BW10: 0 | BX10: 0 | BY10: 0 | CA10: 0 | CC10: 0 | CD10: 0 | CE10: 0 | CG10: 0 | CI10: 0 | CJ10: 0 | CK10: 0 | CM10: 0 | CO10: 0 | CP10: 0 | CQ10: 0 | CS10: 0 | CU10: 0 | CV10: 0 | CW10: 0 | CY10: 0 | DA10: 0 | DB10: 0 | DC10: 0 | DE10: 0 | DG10: 0 | DH10: 0 | DI10: 0 | DK10: 0 | DM10: 0 | DN10: 0 | DO10: 0 | DQ10: 0 | DS10: 0 | DT10: 0 | DU10: 0 | DW10: 0 | DY10: 0 | DZ10: 0 | EA10: 0 | EC10: 0 | EE10: 0 | EF10: 0 | EG10: 0 | EI10: 0 | EK10: 0 | EL10: 0 | EM10: 0 | EO10: 0 | EQ10: 0 | ER10: 0 | ES10: 0 | EU10: 0 | EW10: 0 | EX10: 0 | EY10: 0 | FA10: 0 | FC10: 0 | FD10: 0 | FE10: 0 | FG10: 0 | FI10: 0 | FJ10: 0 | FK10: 0 | FM10: 0 | FO10: 0 | FP10: 0 | FQ10: 0 | FS10: 0 | FU10: 0 | FV10: 0 | FW10: 0 | FY10: 0 | GA10: 0 | GB10: 0 | GC10: 0 | GE10: 0 | GG10: 0 | GH10: 0 | GI10: 0 | GK10: 0 | GM10: 0 | GN10: 0 | GO10: 0 | GQ10: 0 | GS10: 0 | GT10: 0 | GU10: 0 | GW10: 0 | GY10: 0 | GZ10: 0
A11: 017.554-00 | B11: 2022/0029218-001 | C11: 1 | D11: 2022/0029218 | E11: CZX5065 | F11: 01/04/2026 | G11: 30/04/2026 | H11: ALTAIR ELIAS CARNEIRO | I11: ALTAIR ELIAS CARNEIRO | J11: NORMAL | K11: EMEI | L11: =CONTINUA!BV11 -> 0 | M11: =CONTINUA!BW11 -> 0 | O11: 6020.2022/0029218-2 | P11: 0 | Q11: 19 | S11: 0 | U11: 0 | V11: 0 | W11: 19 | Y11: 0 | AA11: 0 | AB11: 0 | AC11: 19 | AE11: 0 | AG11: 0 | AH11: 0 | AI11: 19 | AK11: 0 | AM11: 0 | AN11: 0 | AO11: 19 | AQ11: 0 | AS11: 0 | AT11: 0 | AU11: 19 | AW11: 0 | AY11: 0 | AZ11: 0 | BA11: 19 | BC11: 0 | BE11: 0 | BF11: 0 | BG11: 19 | BI11: 0 | BK11: 0 | BL11: 0 | BM11: 19 | BO11: 0 | BQ11: 0 | BR11: 0 | BS11: 19 | BU11: 0 | BW11: 0 | BX11: 0 | BY11: 19 | CA11: 0 | CC11: 0 | CD11: 0 | CE11: 19 | CG11: 0 | CI11: 0 | CJ11: 0 | CK11: 19 | CM11: 0 | CO11: 0 | CP11: 0 | CQ11: 19 | CS11: 0 | CU11: 0 | CV11: 0 | CW11: 19 | CY11: 0 | DA11: 0 | DB11: 0 | DC11: 19 | DE11: 0 | DG11: 0 | DH11: 0 | DI11: 19 | DK11: 0 | DM11: 0 | DN11: 0 | DO11: 19 | DQ11: 0 | DS11: 0 | DT11: 0 | DU11: 19 | DW11: 0 | DY11: 0 | DZ11: 0 | EA11: 19 | EC11: 0 | EE11: 0 | EF11: 0 | EG11: 19 | EI11: 0 | EK11: 0 | EL11: 0 | EM11: 19 | EO11: 0 | EQ11: 0 | ER11: 0 | ES11: 19 | EU11: 0 | EW11: 0 | EX11: 0 | EY11: 19 | FA11: 0 | FC11: 0 | FD11: 0 | FE11: 19 | FG11: 0 | FI11: 0 | FJ11: 0 | FK11: 19 | FM11: 0 | FO11: 0 | FP11: 0 | FQ11: 19 | FS11: 0 | FU11: 0 | FV11: 0 | FW11: 19 | FY11: 0 | GA11: 0 | GB11: 0 | GC11: 19 | GE11: 0 | GG11: 0 | GH11: 0 | GI11: 19 | GK11: 0 | GM11: 0 | GN11: 0 | GO11: 19 | GQ11: 0 | GS11: 0 | GT11: 0 | GU11: 19 | GW11: 0 | GY11: 0 | GZ11: 0
A12: 017.554-00 | B12: 2022/0029218-001 | C12: G | D12: 2022/0029218 | E12: CZX5065 | F12: 01/04/2026 | G12: 30/04/2026 | H12: ALTAIR ELIAS CARNEIRO | I12: ALTAIR ELIAS CARNEIRO | J12: NORMAL | K12: EMEF | L12: =CONTINUA!BV12 -> 0 | M12: =CONTINUA!BW12 -> 0 | O12: 6020.2022/0029218-2 | P12: 0 | Q12: 6 | S12: 0 | U12: 0 | V12: 0 | W12: 6 | Y12: 0 | AA12: 0 | AB12: 0 | AC12: 6 | AE12: 0 | AG12: 0 | AH12: 0 | AI12: 6 | AK12: 0 | AM12: 0 | AN12: 0 | AO12: 6 | AQ12: 0 | AS12: 0 | AT12: 0 | AU12: 6 | AW12: 0 | AY12: 0 | AZ12: 0 | BA12: 6 | BC12: 0 | BE12: 0 | BF12: 0 | BG12: 6 | BI12: 0 | BK12: 0 | BL12: 0 | BM12: 6 | BO12: 0 | BQ12: 0 | BR12: 0 | BS12: 6 | BU12: 0 | BW12: 0 | BX12: 0 | BY12: 6 | CA12: 0 | CC12: 0 | CD12: 0 | CE12: 6 | CG12: 0 | CI12: 0 | CJ12: 0 | CK12: 6 | CM12: 0 | CO12: 0 | CP12: 0 | CQ12: 6 | CS12: 0 | CU12: 0 | CV12: 0 | CW12: 6 | CY12: 0 | DA12: 0 | DB12: 0 | DC12: 6 | DE12: 0 | DG12: 0 | DH12: 0 | DI12: 6 | DK12: 0 | DM12: 0 | DN12: 0 | DO12: 6 | DQ12: 0 | DS12: 0 | DT12: 0 | DU12: 6 | DW12: 0 | DY12: 0 | DZ12: 0 | EA12: 6 | EC12: 0 | EE12: 0 | EF12: 0 | EG12: 6 | EI12: 0 | EK12: 0 | EL12: 0 | EM12: 6 | EO12: 0 | EQ12: 0 | ER12: 0 | ES12: 6 | EU12: 0 | EW12: 0 | EX12: 0 | EY12: 6 | FA12: 0 | FC12: 0 | FD12: 0 | FE12: 6 | FG12: 0 | FI12: 0 | FJ12: 0 | FK12: 6 | FM12: 0 | FO12: 0 | FP12: 0 | FQ12: 6 | FS12: 0 | FU12: 0 | FV12: 0 | FW12: 6 | FY12: 0 | GA12: 0 | GB12: 0 | GC12: 6 | GE12: 0 | GG12: 0 | GH12: 0 | GI12: 6 | GK12: 0 | GM12: 0 | GN12: 0 | GO12: 6 | GQ12: 0 | GS12: 0 | GT12: 0 | GU12: 6 | GW12: 0 | GY12: 0 | GZ12: 0
A13: 017.554-00 | B13: 2022/0029218-001 | C13: G | D13: 2022/0029218 | E13: CZX5065 | F13: 01/04/2026 | G13: 30/04/2026 | H13: ALTAIR ELIAS CARNEIRO | I13: ALTAIR ELIAS CARNEIRO | J13: NORMAL | K13: EMEE | L13: =CONTINUA!BV13 -> 0 | M13: =CONTINUA!BW13 -> 0 | O13: 6020.2022/0029218-2 | P13: 0 | Q13: 0 | S13: 0 | U13: 0 | V13: 0 | W13: 0 | Y13: 0 | AA13: 0 | AB13: 0 | AC13: 0 | AE13: 0 | AG13: 0 | AH13: 0 | AI13: 0 | AK13: 0 | AM13: 0 | AN13: 0 | AO13: 0 | AQ13: 0 | AS13: 0 | AT13: 0 | AU13: 0 | AW13: 0 | AY13: 0 | AZ13: 0 | BA13: 0 | BC13: 0 | BE13: 0 | BF13: 0 | BG13: 0 | BI13: 0 | BK13: 0 | BL13: 0 | BM13: 0 | BO13: 0 | BQ13: 0 | BR13: 0 | BS13: 0 | BU13: 0 | BW13: 0 | BX13: 0 | BY13: 0 | CA13: 0 | CC13: 0 | CD13: 0 | CE13: 0 | CG13: 0 | CI13: 0 | CJ13: 0 | CK13: 0 | CM13: 0 | CO13: 0 | CP13: 0 | CQ13: 0 | CS13: 0 | CU13: 0 | CV13: 0 | CW13: 0 | CY13: 0 | DA13: 0 | DB13: 0 | DC13: 0 | DE13: 0 | DG13: 0 | DH13: 0 | DI13: 0 | DK13: 0 | DM13: 0 | DN13: 0 | DO13: 0 | DQ13: 0 | DS13: 0 | DT13: 0 | DU13: 0 | DW13: 0 | DY13: 0 | DZ13: 0 | EA13: 0 | EC13: 0 | EE13: 0 | EF13: 0 | EG13: 0 | EI13: 0 | EK13: 0 | EL13: 0 | EM13: 0 | EO13: 0 | EQ13: 0 | ER13: 0 | ES13: 0 | EU13: 0 | EW13: 0 | EX13: 0 | EY13: 0 | FA13: 0 | FC13: 0 | FD13: 0 | FE13: 0 | FG13: 0 | FI13: 0 | FJ13: 0 | FK13: 0 | FM13: 0 | FO13: 0 | FP13: 0 | FQ13: 0 | FS13: 0 | FU13: 0 | FV13: 0 | FW13: 0 | FY13: 0 | GA13: 0 | GB13: 0 | GC13: 0 | GE13: 0 | GG13: 0 | GH13: 0 | GI13: 0 | GK13: 0 | GM13: 0 | GN13: 0 | GO13: 0 | GQ13: 0 | GS13: 0 | GT13: 0 | GU13: 0 | GW13: 0 | GY13: 0 | GZ13: 0
A14: 017.554-00 | B14: 2022/0029218-001 | C14: G | D14: 2022/0029218 | E14: CZX5065 | F14: 01/04/2026 | G14: 30/04/2026 | H14: ALTAIR ELIAS CARNEIRO | I14: ALTAIR ELIAS CARNEIRO | J14: NORMAL | K14: CEI | L14: =CONTINUA!BV14 -> 0 | M14: =CONTINUA!BW14 -> 0 | O14: 6020.2022/0029218-2 | P14: 0 | Q14: 0 | S14: 0 | U14: 0 | V14: 0 | W14: 0 | Y14: 0 | AA14: 0 | AB14: 0 | AC14: 0 | AE14: 0 | AG14: 0 | AH14: 0 | AI14: 0 | AK14: 0 | AM14: 0 | AN14: 0 | AO14: 0 | AQ14: 0 | AS14: 0 | AT14: 0 | AU14: 0 | AW14: 0 | AY14: 0 | AZ14: 0 | BA14: 0 | BC14: 0 | BE14: 0 | BF14: 0 | BG14: 0 | BI14: 0 | BK14: 0 | BL14: 0 | BM14: 0 | BO14: 0 | BQ14: 0 | BR14: 0 | BS14: 0 | BU14: 0 | BW14: 0 | BX14: 0 | BY14: 0 | CA14: 0 | CC14: 0 | CD14: 0 | CE14: 0 | CG14: 0 | CI14: 0 | CJ14: 0 | CK14: 0 | CM14: 0 | CO14: 0 | CP14: 0 | CQ14: 0 | CS14: 0 | CU14: 0 | CV14: 0 | CW14: 0 | CY14: 0 | DA14: 0 | DB14: 0 | DC14: 0 | DE14: 0 | DG14: 0 | DH14: 0 | DI14: 0 | DK14: 0 | DM14: 0 | DN14: 0 | DO14: 0 | DQ14: 0 | DS14: 0 | DT14: 0 | DU14: 0 | DW14: 0 | DY14: 0 | DZ14: 0 | EA14: 0 | EC14: 0 | EE14: 0 | EF14: 0 | EG14: 0 | EI14: 0 | EK14: 0 | EL14: 0 | EM14: 0 | EO14: 0 | EQ14: 0 | ER14: 0 | ES14: 0 | EU14: 0 | EW14: 0 | EX14: 0 | EY14: 0 | FA14: 0 | FC14: 0 | FD14: 0 | FE14: 0 | FG14: 0 | FI14: 0 | FJ14: 0 | FK14: 0 | FM14: 0 | FO14: 0 | FP14: 0 | FQ14: 0 | FS14: 0 | FU14: 0 | FV14: 0 | FW14: 0 | FY14: 0 | GA14: 0 | GB14: 0 | GC14: 0 | GE14: 0 | GG14: 0 | GH14: 0 | GI14: 0 | GK14: 0 | GM14: 0 | GN14: 0 | GO14: 0 | GQ14: 0 | GS14: 0 | GT14: 0 | GU14: 0 | GW14: 0 | GY14: 0 | GZ14: 0
A15: 017.554-00 | B15: 2022/0029218-001 | C15: G | D15: 2022/0029218 | E15: CZX5065 | F15: 01/04/2026 | G15: 30/04/2026 | H15: ALTAIR ELIAS CARNEIRO | I15: ALTAIR ELIAS CARNEIRO | J15: NORMAL | K15: CCA | L15: =CONTINUA!BV15 -> 0 | M15: =CONTINUA!BW15 -> 0 | O15: 6020.2022/0029218-2 | P15: 0 | Q15: 0 | S15: 0 | U15: 0 | V15: 0 | W15: 0 | Y15: 0 | AA15: 0 | AB15: 0 | AC15: 0 | AE15: 0 | AG15: 0 | AH15: 0 | AI15: 0 | AK15: 0 | AM15: 0 | AN15: 0 | AO15: 0 | AQ15: 0 | AS15: 0 | AT15: 0 | AU15: 0 | AW15: 0 | AY15: 0 | AZ15: 0 | BA15: 0 | BC15: 0 | BE15: 0 | BF15: 0 | BG15: 0 | BI15: 0 | BK15: 0 | BL15: 0 | BM15: 0 | BO15: 0 | BQ15: 0 | BR15: 0 | BS15: 0 | BU15: 0 | BW15: 0 | BX15: 0 | BY15: 0 | CA15: 0 | CC15: 0 | CD15: 0 | CE15: 0 | CG15: 0 | CI15: 0 | CJ15: 0 | CK15: 0 | CM15: 0 | CO15: 0 | CP15: 0 | CQ15: 0 | CS15: 0 | CU15: 0 | CV15: 0 | CW15: 0 | CY15: 0 | DA15: 0 | DB15: 0 | DC15: 0 | DE15: 0 | DG15: 0 | DH15: 0 | DI15: 0 | DK15: 0 | DM15: 0 | DN15: 0 | DO15: 0 | DQ15: 0 | DS15: 0 | DT15: 0 | DU15: 0 | DW15: 0 | DY15: 0 | DZ15: 0 | EA15: 0 | EC15: 0 | EE15: 0 | EF15: 0 | EG15: 0 | EI15: 0 | EK15: 0 | EL15: 0 | EM15: 0 | EO15: 0 | EQ15: 0 | ER15: 0 | ES15: 0 | EU15: 0 | EW15: 0 | EX15: 0 | EY15: 0 | FA15: 0 | FC15: 0 | FD15: 0 | FE15: 0 | FG15: 0 | FI15: 0 | FJ15: 0 | FK15: 0 | FM15: 0 | FO15: 0 | FP15: 0 | FQ15: 0 | FS15: 0 | FU15: 0 | FV15: 0 | FW15: 0 | FY15: 0 | GA15: 0 | GB15: 0 | GC15: 0 | GE15: 0 | GG15: 0 | GH15: 0 | GI15: 0 | GK15: 0 | GM15: 0 | GN15: 0 | GO15: 0 | GQ15: 0 | GS15: 0 | GT15: 0 | GU15: 0 | GW15: 0 | GY15: 0 | GZ15: 0
A16: 001.119-00 | B16: 2023/0026116-001 | C16: 1 | D16: 2023/0026116 | E16: DTD4303 | F16: 01/04/2026 | G16: 30/04/2026 | H16: ANTONIO ROBERTO GOMES | I16: ANTONIO ROBERTO GOMES | J16: NORMAL | K16: EMEI | L16: =CONTINUA!BV16 -> 0 | M16: =CONTINUA!BW16 -> 0 | O16: 6020.2023/0026116-5 | P16: 0 | Q16: 0 | S16: 0 | U16: 0 | V16: 0 | W16: 0 | Y16: 0 | AA16: 0 | AB16: 0 | AC16: 0 | AE16: 0 | AG16: 0 | AH16: 0 | AI16: 0 | AK16: 0 | AM16: 0 | AN16: 0 | AO16: 0 | AQ16: 0 | AS16: 0 | AT16: 0 | AU16: 0 | AW16: 0 | AY16: 0 | AZ16: 0 | BA16: 0 | BC16: 0 | BE16: 0 | BF16: 0 | BG16: 0 | BI16: 0 | BK16: 0 | BL16: 0 | BM16: 0 | BO16: 0 | BQ16: 0 | BR16: 0 | BS16: 0 | BU16: 0 | BW16: 0 | BX16: 0 | BY16: 0 | CA16: 0 | CC16: 0 | CD16: 0 | CE16: 0 | CG16: 0 | CI16: 0 | CJ16: 0 | CK16: 0 | CM16: 0 | CO16: 0 | CP16: 0 | CQ16: 0 | CS16: 0 | CU16: 0 | CV16: 0 | CW16: 0 | CY16: 0 | DA16: 0 | DB16: 0 | DC16: 0 | DE16: 0 | DG16: 0 | DH16: 0 | DI16: 0 | DK16: 0 | DM16: 0 | DN16: 0 | DO16: 0 | DQ16: 0 | DS16: 0 | DT16: 0 | DU16: 0 | DW16: 0 | DY16: 0 | DZ16: 0 | EA16: 0 | EC16: 0 | EE16: 0 | EF16: 0 | EG16: 0 | EI16: 0 | EK16: 0 | EL16: 0 | EM16: 0 | EO16: 0 | EQ16: 0 | ER16: 0 | ES16: 0 | EU16: 0 | EW16: 0 | EX16: 0 | EY16: 0 | FA16: 0 | FC16: 0 | FD16: 0 | FE16: 0 | FG16: 0 | FI16: 0 | FJ16: 0 | FK16: 0 | FM16: 0 | FO16: 0 | FP16: 0 | FQ16: 0 | FS16: 0 | FU16: 0 | FV16: 0 | FW16: 0 | FY16: 0 | GA16: 0 | GB16: 0 | GC16: 0 | GE16: 0 | GG16: 0 | GH16: 0 | GI16: 0 | GK16: 0 | GM16: 0 | GN16: 0 | GO16: 0 | GQ16: 0 | GS16: 0 | GT16: 0 | GU16: 0 | GW16: 0 | GY16: 0 | GZ16: 0
A17: 001.119-00 | B17: 2023/0026116-001 | C17: G | D17: 2023/0026116 | E17: DTD4303 | F17: 01/04/2026 | G17: 30/04/2026 | H17: ANTONIO ROBERTO GOMES | I17: ANTONIO ROBERTO GOMES | J17: NORMAL | K17: EMEF | L17: =CONTINUA!BV17 -> 24 | M17: =CONTINUA!BW17 -> 0 | O17: 6020.2023/0026116-5 | P17: 0 | Q17: 48 | S17: 5 | U17: 0 | V17: 0 | W17: 48 | Y17: 5 | AA17: 0 | AB17: 0 | AC17: 48 | AE17: 5 | AG17: 0 | AH17: 0 | AI17: 48 | AK17: 5 | AM17: 0 | AN17: 0 | AO17: 48 | AQ17: 5 | AS17: 0 | AT17: 0 | AU17: 48 | AW17: 5 | AY17: 0 | AZ17: 0 | BA17: 48 | BC17: 5 | BE17: 0 | BF17: 0 | BG17: 48 | BI17: 5 | BK17: 0 | BL17: 0 | BM17: 48 | BO17: 5 | BQ17: 0 | BR17: 0 | BS17: 48 | BU17: 5 | BW17: 0 | BX17: 0 | BY17: 48 | CA17: 5 | CC17: 0 | CD17: 0 | CE17: 48 | CG17: 5 | CI17: 0 | CJ17: 0 | CK17: 48 | CM17: 5 | CO17: 0 | CP17: 0 | CQ17: 48 | CS17: 5 | CU17: 0 | CV17: 0 | CW17: 48 | CY17: 5 | DA17: 0 | DB17: 0 | DC17: 48 | DE17: 5 | DG17: 0 | DH17: 0 | DI17: 48 | DK17: 5 | DM17: 0 | DN17: 0 | DO17: 48 | DQ17: 5 | DS17: 0 | DT17: 0 | DU17: 48 | DW17: 5 | DY17: 0 | DZ17: 0 | EA17: 48 | EC17: 5 | EE17: 0 | EF17: 0 | EG17: 48 | EI17: 5 | EK17: 0 | EL17: 0 | EM17: 48 | EO17: 5 | EQ17: 0 | ER17: 0 | ES17: 48 | EU17: 5 | EW17: 0 | EX17: 0 | EY17: 48 | FA17: 5 | FC17: 0 | FD17: 0 | FE17: 48 | FG17: 5 | FI17: 0 | FJ17: 0 | FK17: 48 | FM17: 5 | FO17: 0 | FP17: 0 | FQ17: 48 | FS17: 5 | FU17: 0 | FV17: 0 | FW17: 48 | FY17: 5 | GA17: 0 | GB17: 0 | GC17: 48 | GE17: 5 | GG17: 0 | GH17: 0 | GI17: 48 | GK17: 5 | GM17: 0 | GN17: 0 | GO17: 48 | GQ17: 5 | GS17: 0 | GT17: 0 | GU17: 48 | GW17: 5 | GY17: 0 | GZ17: 0
A18: 001.119-00 | B18: 2023/0026116-001 | C18: G | D18: 2023/0026116 | E18: DTD4303 | F18: 01/04/2026 | G18: 30/04/2026 | H18: ANTONIO ROBERTO GOMES | I18: ANTONIO ROBERTO GOMES | J18: NORMAL | K18: EMEE | L18: =CONTINUA!BV18 -> 0 | M18: =CONTINUA!BW18 -> 0 | O18: 6020.2023/0026116-5 | P18: 0 | Q18: 0 | S18: 0 | U18: 0 | V18: 0 | W18: 0 | Y18: 0 | AA18: 0 | AB18: 0 | AC18: 0 | AE18: 0 | AG18: 0 | AH18: 0 | AI18: 0 | AK18: 0 | AM18: 0 | AN18: 0 | AO18: 0 | AQ18: 0 | AS18: 0 | AT18: 0 | AU18: 0 | AW18: 0 | AY18: 0 | AZ18: 0 | BA18: 0 | BC18: 0 | BE18: 0 | BF18: 0 | BG18: 0 | BI18: 0 | BK18: 0 | BL18: 0 | BM18: 0 | BO18: 0 | BQ18: 0 | BR18: 0 | BS18: 0 | BU18: 0 | BW18: 0 | BX18: 0 | BY18: 0 | CA18: 0 | CC18: 0 | CD18: 0 | CE18: 0 | CG18: 0 | CI18: 0 | CJ18: 0 | CK18: 0 | CM18: 0 | CO18: 0 | CP18: 0 | CQ18: 0 | CS18: 0 | CU18: 0 | CV18: 0 | CW18: 0 | CY18: 0 | DA18: 0 | DB18: 0 | DC18: 0 | DE18: 0 | DG18: 0 | DH18: 0 | DI18: 0 | DK18: 0 | DM18: 0 | DN18: 0 | DO18: 0 | DQ18: 0 | DS18: 0 | DT18: 0 | DU18: 0 | DW18: 0 | DY18: 0 | DZ18: 0 | EA18: 0 | EC18: 0 | EE18: 0 | EF18: 0 | EG18: 0 | EI18: 0 | EK18: 0 | EL18: 0 | EM18: 0 | EO18: 0 | EQ18: 0 | ER18: 0 | ES18: 0 | EU18: 0 | EW18: 0 | EX18: 0 | EY18: 0 | FA18: 0 | FC18: 0 | FD18: 0 | FE18: 0 | FG18: 0 | FI18: 0 | FJ18: 0 | FK18: 0 | FM18: 0 | FO18: 0 | FP18: 0 | FQ18: 0 | FS18: 0 | FU18: 0 | FV18: 0 | FW18: 0 | FY18: 0 | GA18: 0 | GB18: 0 | GC18: 0 | GE18: 0 | GG18: 0 | GH18: 0 | GI18: 0 | GK18: 0 | GM18: 0 | GN18: 0 | GO18: 0 | GQ18: 0 | GS18: 0 | GT18: 0 | GU18: 0 | GW18: 0 | GY18: 0 | GZ18: 0
A19: 001.119-00 | B19: 2023/0026116-001 | C19: G | D19: 2023/0026116 | E19: DTD4303 | F19: 01/04/2026 | G19: 30/04/2026 | H19: ANTONIO ROBERTO GOMES | I19: ANTONIO ROBERTO GOMES | J19: NORMAL | K19: CEI | L19: =CONTINUA!BV19 -> 0 | M19: =CONTINUA!BW19 -> 0 | O19: 6020.2023/0026116-5 | P19: 0 | Q19: 0 | S19: 0 | U19: 0 | V19: 0 | W19: 0 | Y19: 0 | AA19: 0 | AB19: 0 | AC19: 0 | AE19: 0 | AG19: 0 | AH19: 0 | AI19: 0 | AK19: 0 | AM19: 0 | AN19: 0 | AO19: 0 | AQ19: 0 | AS19: 0 | AT19: 0 | AU19: 0 | AW19: 0 | AY19: 0 | AZ19: 0 | BA19: 0 | BC19: 0 | BE19: 0 | BF19: 0 | BG19: 0 | BI19: 0 | BK19: 0 | BL19: 0 | BM19: 0 | BO19: 0 | BQ19: 0 | BR19: 0 | BS19: 0 | BU19: 0 | BW19: 0 | BX19: 0 | BY19: 0 | CA19: 0 | CC19: 0 | CD19: 0 | CE19: 0 | CG19: 0 | CI19: 0 | CJ19: 0 | CK19: 0 | CM19: 0 | CO19: 0 | CP19: 0 | CQ19: 0 | CS19: 0 | CU19: 0 | CV19: 0 | CW19: 0 | CY19: 0 | DA19: 0 | DB19: 0 | DC19: 0 | DE19: 0 | DG19: 0 | DH19: 0 | DI19: 0 | DK19: 0 | DM19: 0 | DN19: 0 | DO19: 0 | DQ19: 0 | DS19: 0 | DT19: 0 | DU19: 0 | DW19: 0 | DY19: 0 | DZ19: 0 | EA19: 0 | EC19: 0 | EE19: 0 | EF19: 0 | EG19: 0 | EI19: 0 | EK19: 0 | EL19: 0 | EM19: 0 | EO19: 0 | EQ19: 0 | ER19: 0 | ES19: 0 | EU19: 0 | EW19: 0 | EX19: 0 | EY19: 0 | FA19: 0 | FC19: 0 | FD19: 0 | FE19: 0 | FG19: 0 | FI19: 0 | FJ19: 0 | FK19: 0 | FM19: 0 | FO19: 0 | FP19: 0 | FQ19: 0 | FS19: 0 | FU19: 0 | FV19: 0 | FW19: 0 | FY19: 0 | GA19: 0 | GB19: 0 | GC19: 0 | GE19: 0 | GG19: 0 | GH19: 0 | GI19: 0 | GK19: 0 | GM19: 0 | GN19: 0 | GO19: 0 | GQ19: 0 | GS19: 0 | GT19: 0 | GU19: 0 | GW19: 0 | GY19: 0 | GZ19: 0
A20: 001.119-00 | B20: 2023/0026116-001 | C20: G | D20: 2023/0026116 | E20: DTD4303 | F20: 01/04/2026 | G20: 30/04/2026 | H20: ANTONIO ROBERTO GOMES | I20: ANTONIO ROBERTO GOMES | J20: NORMAL | K20: CCA | L20: =CONTINUA!BV20 -> 0 | M20: =CONTINUA!BW20 -> 0 | O20: 6020.2023/0026116-5 | P20: 0 | Q20: 0 | S20: 0 | U20: 0 | V20: 0 | W20: 0 | Y20: 0 | AA20: 0 | AB20: 0 | AC20: 0 | AE20: 0 | AG20: 0 | AH20: 0 | AI20: 0 | AK20: 0 | AM20: 0 | AN20: 0 | AO20: 0 | AQ20: 0 | AS20: 0 | AT20: 0 | AU20: 0 | AW20: 0 | AY20: 0 | AZ20: 0 | BA20: 0 | BC20: 0 | BE20: 0 | BF20: 0 | BG20: 0 | BI20: 0 | BK20: 0 | BL20: 0 | BM20: 0 | BO20: 0 | BQ20: 0 | BR20: 0 | BS20: 0 | BU20: 0 | BW20: 0 | BX20: 0 | BY20: 0 | CA20: 0 | CC20: 0 | CD20: 0 | CE20: 0 | CG20: 0 | CI20: 0 | CJ20: 0 | CK20: 0 | CM20: 0 | CO20: 0 | CP20: 0 | CQ20: 0 | CS20: 0 | CU20: 0 | CV20: 0 | CW20: 0 | CY20: 0 | DA20: 0 | DB20: 0 | DC20: 0 | DE20: 0 | DG20: 0 | DH20: 0 | DI20: 0 | DK20: 0 | DM20: 0 | DN20: 0 | DO20: 0 | DQ20: 0 | DS20: 0 | DT20: 0 | DU20: 0 | DW20: 0 | DY20: 0 | DZ20: 0 | EA20: 0 | EC20: 0 | EE20: 0 | EF20: 0 | EG20: 0 | EI20: 0 | EK20: 0 | EL20: 0 | EM20: 0 | EO20: 0 | EQ20: 0 | ER20: 0 | ES20: 0 | EU20: 0 | EW20: 0 | EX20: 0 | EY20: 0 | FA20: 0 | FC20: 0 | FD20: 0 | FE20: 0 | FG20: 0 | FI20: 0 | FJ20: 0 | FK20: 0 | FM20: 0 | FO20: 0 | FP20: 0 | FQ20: 0 | FS20: 0 | FU20: 0 | FV20: 0 | FW20: 0 | FY20: 0 | GA20: 0 | GB20: 0 | GC20: 0 | GE20: 0 | GG20: 0 | GH20: 0 | GI20: 0 | GK20: 0 | GM20: 0 | GN20: 0 | GO20: 0 | GQ20: 0 | GS20: 0 | GT20: 0 | GU20: 0 | GW20: 0 | GY20: 0 | GZ20: 0
A21: 034.861-00 | B21: 2022/0033315-001A | C21: 1 | D21: 2022/0033315 | E21: FQH5J83 | F21: 01/04/2026 | G21: 30/04/2026 | H21: BRUNO EDUARDO BARBOSA | I21: BRUNO EDUARDO BARBOSA | J21: NORMAL | K21: EMEI | L21: =CONTINUA!BV21 -> 0 | M21: =CONTINUA!BW21 -> 0 | O21: 6020.2022/0033315-6 | P21: 0 | Q21: 0 | S21: 0 | U21: 0 | V21: 0 | W21: 0 | Y21: 0 | AA21: 0 | AB21: 0 | AC21: 0 | AE21: 0 | AG21: 0 | AH21: 0 | AI21: 0 | AK21: 0 | AM21: 0 | AN21: 0 | AO21: 0 | AQ21: 0 | AS21: 0 | AT21: 0 | AU21: 0 | AW21: 0 | AY21: 0 | AZ21: 0 | BA21: 0 | BC21: 0 | BE21: 0 | BF21: 0 | BG21: 0 | BI21: 0 | BK21: 0 | BL21: 0 | BM21: 0 | BO21: 0 | BQ21: 0 | BR21: 0 | BS21: 0 | BU21: 0 | BW21: 0 | BX21: 0 | BY21: 0 | CA21: 0 | CC21: 0 | CD21: 0 | CE21: 0 | CG21: 0 | CI21: 0 | CJ21: 0 | CK21: 0 | CM21: 0 | CO21: 0 | CP21: 0 | CQ21: 0 | CS21: 0 | CU21: 0 | CV21: 0 | CW21: 0 | CY21: 0 | DA21: 0 | DB21: 0 | DC21: 0 | DE21: 0 | DG21: 0 | DH21: 0 | DI21: 0 | DK21: 0 | DM21: 0 | DN21: 0 | DO21: 0 | DQ21: 0 | DS21: 0 | DT21: 0 | DU21: 0 | DW21: 0 | DY21: 0 | DZ21: 0 | EA21: 0 | EC21: 0 | EE21: 0 | EF21: 0 | EG21: 0 | EI21: 0 | EK21: 0 | EL21: 0 | EM21: 0 | EO21: 0 | EQ21: 0 | ER21: 0 | ES21: 0 | EU21: 0 | EW21: 0 | EX21: 0 | EY21: 0 | FA21: 0 | FC21: 0 | FD21: 0 | FE21: 0 | FG21: 0 | FI21: 0 | FJ21: 0 | FK21: 0 | FM21: 0 | FO21: 0 | FP21: 0 | FQ21: 0 | FS21: 0 | FU21: 0 | FV21: 0 | FW21: 0 | FY21: 0 | GA21: 0 | GB21: 0 | GC21: 0 | GE21: 0 | GG21: 0 | GH21: 0 | GI21: 0 | GK21: 0 | GM21: 0 | GN21: 0 | GO21: 0 | GQ21: 0 | GS21: 0 | GT21: 0 | GU21: 0 | GW21: 0 | GY21: 0 | GZ21: 0
A22: 034.861-00 | B22: 2022/0033315-001A | C22: G | D22: 2022/0033315 | E22: FQH5J83 | F22: 01/04/2026 | G22: 30/04/2026 | H22: BRUNO EDUARDO BARBOSA | I22: BRUNO EDUARDO BARBOSA | J22: NORMAL | K22: EMEF | L22: =CONTINUA!BV22 -> 16 | M22: =CONTINUA!BW22 -> 0 | O22: 6020.2022/0033315-6 | P22: 0 | Q22: 45 | S22: 0 | U22: 0 | V22: 0 | W22: 45 | Y22: 0 | AA22: 0 | AB22: 0 | AC22: 45 | AE22: 0 | AG22: 0 | AH22: 0 | AI22: 45 | AK22: 0 | AM22: 0 | AN22: 0 | AO22: 45 | AQ22: 0 | AS22: 0 | AT22: 0 | AU22: 45 | AW22: 0 | AY22: 0 | AZ22: 0 | BA22: 45 | BC22: 0 | BE22: 0 | BF22: 0 | BG22: 45 | BI22: 0 | BK22: 0 | BL22: 0 | BM22: 45 | BO22: 0 | BQ22: 0 | BR22: 0 | BS22: 45 | BU22: 0 | BW22: 0 | BX22: 0 | BY22: 45 | CA22: 0 | CC22: 0 | CD22: 0 | CE22: 45 | CG22: 0 | CI22: 0 | CJ22: 0 | CK22: 45 | CM22: 0 | CO22: 0 | CP22: 0 | CQ22: 45 | CS22: 0 | CU22: 0 | CV22: 0 | CW22: 45 | CY22: 0 | DA22: 0 | DB22: 0 | DC22: 45 | DE22: 0 | DG22: 0 | DH22: 0 | DI22: 45 | DK22: 0 | DM22: 0 | DN22: 0 | DO22: 45 | DQ22: 0 | DS22: 0 | DT22: 0 | DU22: 45 | DW22: 0 | DY22: 0 | DZ22: 0 | EA22: 45 | EC22: 0 | EE22: 0 | EF22: 0 | EG22: 45 | EI22: 0 | EK22: 0 | EL22: 0 | EM22: 45 | EO22: 0 | EQ22: 0 | ER22: 0 | ES22: 45 | EU22: 0 | EW22: 0 | EX22: 0 | EY22: 45 | FA22: 0 | FC22: 0 | FD22: 0 | FE22: 45 | FG22: 0 | FI22: 0 | FJ22: 0 | FK22: 45 | FM22: 0 | FO22: 0 | FP22: 0 | FQ22: 45 | FS22: 0 | FU22: 0 | FV22: 0 | FW22: 45 | FY22: 0 | GA22: 0 | GB22: 0 | GC22: 45 | GE22: 0 | GG22: 0 | GH22: 0 | GI22: 45 | GK22: 0 | GM22: 0 | GN22: 0 | GO22: 45 | GQ22: 0 | GS22: 0 | GT22: 0 | GU22: 45 | GW22: 0 | GY22: 0 | GZ22: 0
A23: 034.861-00 | B23: 2022/0033315-001A | C23: G | D23: 2022/0033315 | E23: FQH5J83 | F23: 01/04/2026 | G23: 30/04/2026 | H23: BRUNO EDUARDO BARBOSA | I23: BRUNO EDUARDO BARBOSA | J23: NORMAL | K23: EMEE | L23: =CONTINUA!BV23 -> 0 | M23: =CONTINUA!BW23 -> 0 | O23: 6020.2022/0033315-6 | P23: 0 | Q23: 0 | S23: 0 | U23: 0 | V23: 0 | W23: 0 | Y23: 0 | AA23: 0 | AB23: 0 | AC23: 0 | AE23: 0 | AG23: 0 | AH23: 0 | AI23: 0 | AK23: 0 | AM23: 0 | AN23: 0 | AO23: 0 | AQ23: 0 | AS23: 0 | AT23: 0 | AU23: 0 | AW23: 0 | AY23: 0 | AZ23: 0 | BA23: 0 | BC23: 0 | BE23: 0 | BF23: 0 | BG23: 0 | BI23: 0 | BK23: 0 | BL23: 0 | BM23: 0 | BO23: 0 | BQ23: 0 | BR23: 0 | BS23: 0 | BU23: 0 | BW23: 0 | BX23: 0 | BY23: 0 | CA23: 0 | CC23: 0 | CD23: 0 | CE23: 0 | CG23: 0 | CI23: 0 | CJ23: 0 | CK23: 0 | CM23: 0 | CO23: 0 | CP23: 0 | CQ23: 0 | CS23: 0 | CU23: 0 | CV23: 0 | CW23: 0 | CY23: 0 | DA23: 0 | DB23: 0 | DC23: 0 | DE23: 0 | DG23: 0 | DH23: 0 | DI23: 0 | DK23: 0 | DM23: 0 | DN23: 0 | DO23: 0 | DQ23: 0 | DS23: 0 | DT23: 0 | DU23: 0 | DW23: 0 | DY23: 0 | DZ23: 0 | EA23: 0 | EC23: 0 | EE23: 0 | EF23: 0 | EG23: 0 | EI23: 0 | EK23: 0 | EL23: 0 | EM23: 0 | EO23: 0 | EQ23: 0 | ER23: 0 | ES23: 0 | EU23: 0 | EW23: 0 | EX23: 0 | EY23: 0 | FA23: 0 | FC23: 0 | FD23: 0 | FE23: 0 | FG23: 0 | FI23: 0 | FJ23: 0 | FK23: 0 | FM23: 0 | FO23: 0 | FP23: 0 | FQ23: 0 | FS23: 0 | FU23: 0 | FV23: 0 | FW23: 0 | FY23: 0 | GA23: 0 | GB23: 0 | GC23: 0 | GE23: 0 | GG23: 0 | GH23: 0 | GI23: 0 | GK23: 0 | GM23: 0 | GN23: 0 | GO23: 0 | GQ23: 0 | GS23: 0 | GT23: 0 | GU23: 0 | GW23: 0 | GY23: 0 | GZ23: 0
A24: 034.861-00 | B24: 2022/0033315-001A | C24: G | D24: 2022/0033315 | E24: FQH5J83 | F24: 01/04/2026 | G24: 30/04/2026 | H24: BRUNO EDUARDO BARBOSA | I24: BRUNO EDUARDO BARBOSA | J24: NORMAL | K24: CEI | L24: =CONTINUA!BV24 -> 0 | M24: =CONTINUA!BW24 -> 0 | O24: 6020.2022/0033315-6 | P24: 0 | Q24: 0 | S24: 0 | U24: 0 | V24: 0 | W24: 0 | Y24: 0 | AA24: 0 | AB24: 0 | AC24: 0 | AE24: 0 | AG24: 0 | AH24: 0 | AI24: 0 | AK24: 0 | AM24: 0 | AN24: 0 | AO24: 0 | AQ24: 0 | AS24: 0 | AT24: 0 | AU24: 0 | AW24: 0 | AY24: 0 | AZ24: 0 | BA24: 0 | BC24: 0 | BE24: 0 | BF24: 0 | BG24: 0 | BI24: 0 | BK24: 0 | BL24: 0 | BM24: 0 | BO24: 0 | BQ24: 0 | BR24: 0 | BS24: 0 | BU24: 0 | BW24: 0 | BX24: 0 | BY24: 0 | CA24: 0 | CC24: 0 | CD24: 0 | CE24: 0 | CG24: 0 | CI24: 0 | CJ24: 0 | CK24: 0 | CM24: 0 | CO24: 0 | CP24: 0 | CQ24: 0 | CS24: 0 | CU24: 0 | CV24: 0 | CW24: 0 | CY24: 0 | DA24: 0 | DB24: 0 | DC24: 0 | DE24: 0 | DG24: 0 | DH24: 0 | DI24: 0 | DK24: 0 | DM24: 0 | DN24: 0 | DO24: 0 | DQ24: 0 | DS24: 0 | DT24: 0 | DU24: 0 | DW24: 0 | DY24: 0 | DZ24: 0 | EA24: 0 | EC24: 0 | EE24: 0 | EF24: 0 | EG24: 0 | EI24: 0 | EK24: 0 | EL24: 0 | EM24: 0 | EO24: 0 | EQ24: 0 | ER24: 0 | ES24: 0 | EU24: 0 | EW24: 0 | EX24: 0 | EY24: 0 | FA24: 0 | FC24: 0 | FD24: 0 | FE24: 0 | FG24: 0 | FI24: 0 | FJ24: 0 | FK24: 0 | FM24: 0 | FO24: 0 | FP24: 0 | FQ24: 0 | FS24: 0 | FU24: 0 | FV24: 0 | FW24: 0 | FY24: 0 | GA24: 0 | GB24: 0 | GC24: 0 | GE24: 0 | GG24: 0 | GH24: 0 | GI24: 0 | GK24: 0 | GM24: 0 | GN24: 0 | GO24: 0 | GQ24: 0 | GS24: 0 | GT24: 0 | GU24: 0 | GW24: 0 | GY24: 0 | GZ24: 0
A25: 034.861-00 | B25: 2022/0033315-001A | C25: G | D25: 2022/0033315 | E25: FQH5J83 | F25: 01/04/2026 | G25: 30/04/2026 | H25: BRUNO EDUARDO BARBOSA | I25: BRUNO EDUARDO BARBOSA | J25: NORMAL | K25: CCA | L25: =CONTINUA!BV25 -> 0 | M25: =CONTINUA!BW25 -> 0 | O25: 6020.2022/0033315-6 | P25: 0 | Q25: 0 | S25: 0 | U25: 0 | V25: 0 | W25: 0 | Y25: 0 | AA25: 0 | AB25: 0 | AC25: 0 | AE25: 0 | AG25: 0 | AH25: 0 | AI25: 0 | AK25: 0 | AM25: 0 | AN25: 0 | AO25: 0 | AQ25: 0 | AS25: 0 | AT25: 0 | AU25: 0 | AW25: 0 | AY25: 0 | AZ25: 0 | BA25: 0 | BC25: 0 | BE25: 0 | BF25: 0 | BG25: 0 | BI25: 0 | BK25: 0 | BL25: 0 | BM25: 0 | BO25: 0 | BQ25: 0 | BR25: 0 | BS25: 0 | BU25: 0 | BW25: 0 | BX25: 0 | BY25: 0 | CA25: 0 | CC25: 0 | CD25: 0 | CE25: 0 | CG25: 0 | CI25: 0 | CJ25: 0 | CK25: 0 | CM25: 0 | CO25: 0 | CP25: 0 | CQ25: 0 | CS25: 0 | CU25: 0 | CV25: 0 | CW25: 0 | CY25: 0 | DA25: 0 | DB25: 0 | DC25: 0 | DE25: 0 | DG25: 0 | DH25: 0 | DI25: 0 | DK25: 0 | DM25: 0 | DN25: 0 | DO25: 0 | DQ25: 0 | DS25: 0 | DT25: 0 | DU25: 0 | DW25: 0 | DY25: 0 | DZ25: 0 | EA25: 0 | EC25: 0 | EE25: 0 | EF25: 0 | EG25: 0 | EI25: 0 | EK25: 0 | EL25: 0 | EM25: 0 | EO25: 0 | EQ25: 0 | ER25: 0 | ES25: 0 | EU25: 0 | EW25: 0 | EX25: 0 | EY25: 0 | FA25: 0 | FC25: 0 | FD25: 0 | FE25: 0 | FG25: 0 | FI25: 0 | FJ25: 0 | FK25: 0 | FM25: 0 | FO25: 0 | FP25: 0 | FQ25: 0 | FS25: 0 | FU25: 0 | FV25: 0 | FW25: 0 | FY25: 0 | GA25: 0 | GB25: 0 | GC25: 0 | GE25: 0 | GG25: 0 | GH25: 0 | GI25: 0 | GK25: 0 | GM25: 0 | GN25: 0 | GO25: 0 | GQ25: 0 | GS25: 0 | GT25: 0 | GU25: 0 | GW25: 0 | GY25: 0 | GZ25: 0
A26: 020.989-00 | B26: 2022/0034309-001B | C26: 2 | D26: 2022/0034309 | E26: FRC8739 | F26: 01/04/2026 | G26: 30/04/2026 | H26: CARLOS ALBERTO DE ARAUJO | I26: CARLOS ALBERTO DE ARAUJO | J26: ADAPTADO | K26: EMEI | L26: =CONTINUA!BV26 -> 0 | M26: =CONTINUA!BW26 -> 0 | O26: 6020.2022/0034309-7 | P26: 0 | Q26: 0 | R26: 2 | S26: 0 | T26: 0 | U26: 0 | V26: 0 | W26: 0 | X26: 2 | Y26: 0 | Z26: 0 | AA26: 0 | AB26: 0 | AC26: 0 | AD26: 2 | AE26: 0 | AF26: 0 | AG26: 0 | AH26: 0 | AI26: 0 | AJ26: 2 | AK26: 0 | AL26: 0 | AM26: 0 | AN26: 0 | AO26: 0 | AP26: 2 | AQ26: 0 | AR26: 0 | AS26: 0 | AT26: 0 | AU26: 0 | AV26: 2 | AW26: 0 | AX26: 0 | AY26: 0 | AZ26: 0 | BA26: 0 | BB26: 2 | BC26: 0 | BD26: 0 | BE26: 0 | BF26: 0 | BG26: 0 | BH26: 2 | BI26: 0 | BJ26: 0 | BK26: 0 | BL26: 0 | BM26: 0 | BN26: 2 | BO26: 0 | BP26: 0 | BQ26: 0 | BR26: 0 | BS26: 0 | BT26: 2 | BU26: 0 | BV26: 0 | BW26: 0 | BX26: 0 | BY26: 0 | BZ26: 2 | CA26: 0 | CB26: 0 | CC26: 0 | CD26: 0 | CE26: 0 | CF26: 2 | CG26: 0 | CH26: 0 | CI26: 0 | CJ26: 0 | CK26: 0 | CL26: 2 | CM26: 0 | CN26: 0 | CO26: 0 | CP26: 0 | CQ26: 0 | CR26: 2 | CS26: 0 | CT26: 0 | CU26: 0 | CV26: 0 | CW26: 0 | CX26: 2 | CY26: 0 | CZ26: 0 | DA26: 0 | DB26: 0 | DC26: 0 | DD26: 2 | DE26: 0 | DF26: 0 | DG26: 0 | DH26: 0 | DI26: 0 | DJ26: 2 | DK26: 0 | DL26: 0 | DM26: 0 | DN26: 0 | DO26: 0 | DP26: 2 | DQ26: 0 | DR26: 0 | DS26: 0 | DT26: 0 | DU26: 0 | DV26: 2 | DW26: 0 | DX26: 0 | DY26: 0 | DZ26: 0 | EA26: 0 | EB26: 2 | EC26: 0 | ED26: 0 | EE26: 0 | EF26: 0 | EG26: 0 | EH26: 2 | EI26: 0 | EJ26: 0 | EK26: 0 | EL26: 0 | EM26: 0 | EN26: 2 | EO26: 0 | EP26: 0 | EQ26: 0 | ER26: 0 | ES26: 0 | ET26: 2 | EU26: 0 | EV26: 0 | EW26: 0 | EX26: 0 | EY26: 0 | EZ26: 2 | FA26: 0 | FB26: 0 | FC26: 0 | FD26: 0 | FE26: 0 | FF26: 2 | FG26: 0 | FH26: 0 | FI26: 0 | FJ26: 0 | FK26: 0 | FL26: 2 | FM26: 0 | FN26: 0 | FO26: 0 | FP26: 0 | FQ26: 0 | FR26: 2 | FS26: 0 | FT26: 0 | FU26: 0 | FV26: 0 | FW26: 0 | FX26: 2 | FY26: 0 | FZ26: 0 | GA26: 0 | GB26: 0 | GC26: 0 | GD26: 2 | GE26: 0 | GF26: 0 | GG26: 0 | GH26: 0 | GI26: 0 | GJ26: 2 | GK26: 0 | GL26: 0 | GM26: 0 | GN26: 0 | GO26: 0 | GP26: 2 | GQ26: 0 | GR26: 0 | GS26: 0 | GT26: 0 | GU26: 0 | GV26: 2 | GW26: 0 | GX26: 0 | GY26: 0 | GZ26: 0
A27: 020.989-00 | B27: 2022/0034309-001B | C27: G | D27: 2022/0034309 | E27: FRC8739 | F27: 01/04/2026 | G27: 30/04/2026 | H27: CARLOS ALBERTO DE ARAUJO | I27: CARLOS ALBERTO DE ARAUJO | J27: ADAPTADO | K27: EMEF | L27: =CONTINUA!BV27 -> 0 | M27: =CONTINUA!BW27 -> 0 | O27: 6020.2022/0034309-7 | P27: 0 | Q27: 14 | R27: 2 | S27: 8 | T27: 0 | U27: 0 | V27: 0 | W27: 14 | X27: 2 | Y27: 8 | Z27: 0 | AA27: 0 | AB27: 0 | AC27: 14 | AD27: 2 | AE27: 8 | AF27: 0 | AG27: 0 | AH27: 0 | AI27: 14 | AJ27: 2 | AK27: 8 | AL27: 0 | AM27: 0 | AN27: 0 | AO27: 14 | AP27: 2 | AQ27: 8 | AR27: 0 | AS27: 0 | AT27: 0 | AU27: 14 | AV27: 2 | AW27: 8 | AX27: 0 | AY27: 0 | AZ27: 0 | BA27: 14 | BB27: 2 | BC27: 8 | BD27: 0 | BE27: 0 | BF27: 0 | BG27: 14 | BH27: 2 | BI27: 8 | BJ27: 0 | BK27: 0 | BL27: 0 | BM27: 14 | BN27: 2 | BO27: 8 | BP27: 0 | BQ27: 0 | BR27: 0 | BS27: 14 | BT27: 2 | BU27: 8 | BV27: 0 | BW27: 0 | BX27: 0 | BY27: 14 | BZ27: 2 | CA27: 8 | CB27: 0 | CC27: 0 | CD27: 0 | CE27: 14 | CF27: 2 | CG27: 8 | CH27: 0 | CI27: 0 | CJ27: 0 | CK27: 14 | CL27: 2 | CM27: 8 | CN27: 0 | CO27: 0 | CP27: 0 | CQ27: 14 | CR27: 2 | CS27: 8 | CT27: 0 | CU27: 0 | CV27: 0 | CW27: 14 | CX27: 2 | CY27: 8 | CZ27: 0 | DA27: 0 | DB27: 0 | DC27: 14 | DD27: 2 | DE27: 8 | DF27: 0 | DG27: 0 | DH27: 0 | DI27: 14 | DJ27: 2 | DK27: 8 | DL27: 0 | DM27: 0 | DN27: 0 | DO27: 14 | DP27: 2 | DQ27: 8 | DR27: 0 | DS27: 0 | DT27: 0 | DU27: 14 | DV27: 2 | DW27: 8 | DX27: 0 | DY27: 0 | DZ27: 0 | EA27: 14 | EB27: 2 | EC27: 8 | ED27: 0 | EE27: 0 | EF27: 0 | EG27: 14 | EH27: 2 | EI27: 8 | EJ27: 0 | EK27: 0 | EL27: 0 | EM27: 14 | EN27: 2 | EO27: 8 | EP27: 0 | EQ27: 0 | ER27: 0 | ES27: 14 | ET27: 2 | EU27: 8 | EV27: 0 | EW27: 0 | EX27: 0 | EY27: 14 | EZ27: 2 | FA27: 8 | FB27: 0 | FC27: 0 | FD27: 0 | FE27: 14 | FF27: 2 | FG27: 8 | FH27: 0 | FI27: 0 | FJ27: 0 | FK27: 14 | FL27: 2 | FM27: 8 | FN27: 0 | FO27: 0 | FP27: 0 | FQ27: 14 | FR27: 2 | FS27: 8 | FT27: 0 | FU27: 0 | FV27: 0 | FW27: 14 | FX27: 2 | FY27: 8 | FZ27: 0 | GA27: 0 | GB27: 0 | GC27: 14 | GD27: 2 | GE27: 8 | GF27: 0 | GG27: 0 | GH27: 0 | GI27: 14 | GJ27: 2 | GK27: 8 | GL27: 0 | GM27: 0 | GN27: 0 | GO27: 14 | GP27: 2 | GQ27: 8 | GR27: 0 | GS27: 0 | GT27: 0 | GU27: 14 | GV27: 2 | GW27: 8 | GX27: 0 | GY27: 0 | GZ27: 0
A28: 020.989-00 | B28: 2022/0034309-001B | C28: G | D28: 2022/0034309 | E28: FRC8739 | F28: 01/04/2026 | G28: 30/04/2026 | H28: CARLOS ALBERTO DE ARAUJO | I28: CARLOS ALBERTO DE ARAUJO | J28: ADAPTADO | K28: EMEE | L28: =CONTINUA!BV28 -> 0 | M28: =CONTINUA!BW28 -> 0 | O28: 6020.2022/0034309-7 | P28: 0 | Q28: 0 | R28: 0 | S28: 0 | T28: 0 | U28: 0 | V28: 0 | W28: 0 | X28: 0 | Y28: 0 | Z28: 0 | AA28: 0 | AB28: 0 | AC28: 0 | AD28: 0 | AE28: 0 | AF28: 0 | AG28: 0 | AH28: 0 | AI28: 0 | AJ28: 0 | AK28: 0 | AL28: 0 | AM28: 0 | AN28: 0 | AO28: 0 | AP28: 0 | AQ28: 0 | AR28: 0 | AS28: 0 | AT28: 0 | AU28: 0 | AV28: 0 | AW28: 0 | AX28: 0 | AY28: 0 | AZ28: 0 | BA28: 0 | BB28: 0 | BC28: 0 | BD28: 0 | BE28: 0 | BF28: 0 | BG28: 0 | BH28: 0 | BI28: 0 | BJ28: 0 | BK28: 0 | BL28: 0 | BM28: 0 | BN28: 0 | BO28: 0 | BP28: 0 | BQ28: 0 | BR28: 0 | BS28: 0 | BT28: 0 | BU28: 0 | BV28: 0 | BW28: 0 | BX28: 0 | BY28: 0 | BZ28: 0 | CA28: 0 | CB28: 0 | CC28: 0 | CD28: 0 | CE28: 0 | CF28: 0 | CG28: 0 | CH28: 0 | CI28: 0 | CJ28: 0 | CK28: 0 | CL28: 0 | CM28: 0 | CN28: 0 | CO28: 0 | CP28: 0 | CQ28: 0 | CR28: 0 | CS28: 0 | CT28: 0 | CU28: 0 | CV28: 0 | CW28: 0 | CX28: 0 | CY28: 0 | CZ28: 0 | DA28: 0 | DB28: 0 | DC28: 0 | DD28: 0 | DE28: 0 | DF28: 0 | DG28: 0 | DH28: 0 | DI28: 0 | DJ28: 0 | DK28: 0 | DL28: 0 | DM28: 0 | DN28: 0 | DO28: 0 | DP28: 0 | DQ28: 0 | DR28: 0 | DS28: 0 | DT28: 0 | DU28: 0 | DV28: 0 | DW28: 0 | DX28: 0 | DY28: 0 | DZ28: 0 | EA28: 0 | EB28: 0 | EC28: 0 | ED28: 0 | EE28: 0 | EF28: 0 | EG28: 0 | EH28: 0 | EI28: 0 | EJ28: 0 | EK28: 0 | EL28: 0 | EM28: 0 | EN28: 0 | EO28: 0 | EP28: 0 | EQ28: 0 | ER28: 0 | ES28: 0 | ET28: 0 | EU28: 0 | EV28: 0 | EW28: 0 | EX28: 0 | EY28: 0 | EZ28: 0 | FA28: 0 | FB28: 0 | FC28: 0 | FD28: 0 | FE28: 0 | FF28: 0 | FG28: 0 | FH28: 0 | FI28: 0 | FJ28: 0 | FK28: 0 | FL28: 0 | FM28: 0 | FN28: 0 | FO28: 0 | FP28: 0 | FQ28: 0 | FR28: 0 | FS28: 0 | FT28: 0 | FU28: 0 | FV28: 0 | FW28: 0 | FX28: 0 | FY28: 0 | FZ28: 0 | GA28: 0 | GB28: 0 | GC28: 0 | GD28: 0 | GE28: 0 | GF28: 0 | GG28: 0 | GH28: 0 | GI28: 0 | GJ28: 0 | GK28: 0 | GL28: 0 | GM28: 0 | GN28: 0 | GO28: 0 | GP28: 0 | GQ28: 0 | GR28: 0 | GS28: 0 | GT28: 0 | GU28: 0 | GV28: 0 | GW28: 0 | GX28: 0 | GY28: 0 | GZ28: 0
A29: 020.989-00 | B29: 2022/0034309-001B | C29: G | D29: 2022/0034309 | E29: FRC8739 | F29: 01/04/2026 | G29: 30/04/2026 | H29: CARLOS ALBERTO DE ARAUJO | I29: CARLOS ALBERTO DE ARAUJO | J29: ADAPTADO | K29: CEI | L29: =CONTINUA!BV29 -> 0 | M29: =CONTINUA!BW29 -> 0 | O29: 6020.2022/0034309-7 | P29: 0 | Q29: 0 | R29: 0 | S29: 0 | T29: 0 | U29: 0 | V29: 0 | W29: 0 | X29: 0 | Y29: 0 | Z29: 0 | AA29: 0 | AB29: 0 | AC29: 0 | AD29: 0 | AE29: 0 | AF29: 0 | AG29: 0 | AH29: 0 | AI29: 0 | AJ29: 0 | AK29: 0 | AL29: 0 | AM29: 0 | AN29: 0 | AO29: 0 | AP29: 0 | AQ29: 0 | AR29: 0 | AS29: 0 | AT29: 0 | AU29: 0 | AV29: 0 | AW29: 0 | AX29: 0 | AY29: 0 | AZ29: 0 | BA29: 0 | BB29: 0 | BC29: 0 | BD29: 0 | BE29: 0 | BF29: 0 | BG29: 0 | BH29: 0 | BI29: 0 | BJ29: 0 | BK29: 0 | BL29: 0 | BM29: 0 | BN29: 0 | BO29: 0 | BP29: 0 | BQ29: 0 | BR29: 0 | BS29: 0 | BT29: 0 | BU29: 0 | BV29: 0 | BW29: 0 | BX29: 0 | BY29: 0 | BZ29: 0 | CA29: 0 | CB29: 0 | CC29: 0 | CD29: 0 | CE29: 0 | CF29: 0 | CG29: 0 | CH29: 0 | CI29: 0 | CJ29: 0 | CK29: 0 | CL29: 0 | CM29: 0 | CN29: 0 | CO29: 0 | CP29: 0 | CQ29: 0 | CR29: 0 | CS29: 0 | CT29: 0 | CU29: 0 | CV29: 0 | CW29: 0 | CX29: 0 | CY29: 0 | CZ29: 0 | DA29: 0 | DB29: 0 | DC29: 0 | DD29: 0 | DE29: 0 | DF29: 0 | DG29: 0 | DH29: 0 | DI29: 0 | DJ29: 0 | DK29: 0 | DL29: 0 | DM29: 0 | DN29: 0 | DO29: 0 | DP29: 0 | DQ29: 0 | DR29: 0 | DS29: 0 | DT29: 0 | DU29: 0 | DV29: 0 | DW29: 0 | DX29: 0 | DY29: 0 | DZ29: 0 | EA29: 0 | EB29: 0 | EC29: 0 | ED29: 0 | EE29: 0 | EF29: 0 | EG29: 0 | EH29: 0 | EI29: 0 | EJ29: 0 | EK29: 0 | EL29: 0 | EM29: 0 | EN29: 0 | EO29: 0 | EP29: 0 | EQ29: 0 | ER29: 0 | ES29: 0 | ET29: 0 | EU29: 0 | EV29: 0 | EW29: 0 | EX29: 0 | EY29: 0 | EZ29: 0 | FA29: 0 | FB29: 0 | FC29: 0 | FD29: 0 | FE29: 0 | FF29: 0 | FG29: 0 | FH29: 0 | FI29: 0 | FJ29: 0 | FK29: 0 | FL29: 0 | FM29: 0 | FN29: 0 | FO29: 0 | FP29: 0 | FQ29: 0 | FR29: 0 | FS29: 0 | FT29: 0 | FU29: 0 | FV29: 0 | FW29: 0 | FX29: 0 | FY29: 0 | FZ29: 0 | GA29: 0 | GB29: 0 | GC29: 0 | GD29: 0 | GE29: 0 | GF29: 0 | GG29: 0 | GH29: 0 | GI29: 0 | GJ29: 0 | GK29: 0 | GL29: 0 | GM29: 0 | GN29: 0 | GO29: 0 | GP29: 0 | GQ29: 0 | GR29: 0 | GS29: 0 | GT29: 0 | GU29: 0 | GV29: 0 | GW29: 0 | GX29: 0 | GY29: 0 | GZ29: 0
A30: 020.989-00 | B30: 2022/0034309-001B | C30: G | D30: 2022/0034309 | E30: FRC8739 | F30: 01/04/2026 | G30: 30/04/2026 | H30: CARLOS ALBERTO DE ARAUJO | I30: CARLOS ALBERTO DE ARAUJO | J30: ADAPTADO | K30: CCA | L30: =CONTINUA!BV30 -> 0 | M30: =CONTINUA!BW30 -> 0 | O30: 6020.2022/0034309-7 | P30: 0 | Q30: 0 | R30: 0 | S30: 0 | T30: 0 | U30: 0 | V30: 0 | W30: 0 | X30: 0 | Y30: 0 | Z30: 0 | AA30: 0 | AB30: 0 | AC30: 0 | AD30: 0 | AE30: 0 | AF30: 0 | AG30: 0 | AH30: 0 | AI30: 0 | AJ30: 0 | AK30: 0 | AL30: 0 | AM30: 0 | AN30: 0 | AO30: 0 | AP30: 0 | AQ30: 0 | AR30: 0 | AS30: 0 | AT30: 0 | AU30: 0 | AV30: 0 | AW30: 0 | AX30: 0 | AY30: 0 | AZ30: 0 | BA30: 0 | BB30: 0 | BC30: 0 | BD30: 0 | BE30: 0 | BF30: 0 | BG30: 0 | BH30: 0 | BI30: 0 | BJ30: 0 | BK30: 0 | BL30: 0 | BM30: 0 | BN30: 0 | BO30: 0 | BP30: 0 | BQ30: 0 | BR30: 0 | BS30: 0 | BT30: 0 | BU30: 0 | BV30: 0 | BW30: 0 | BX30: 0 | BY30: 0 | BZ30: 0 | CA30: 0 | CB30: 0 | CC30: 0 | CD30: 0 | CE30: 0 | CF30: 0 | CG30: 0 | CH30: 0 | CI30: 0 | CJ30: 0 | CK30: 0 | CL30: 0 | CM30: 0 | CN30: 0 | CO30: 0 | CP30: 0 | CQ30: 0 | CR30: 0 | CS30: 0 | CT30: 0 | CU30: 0 | CV30: 0 | CW30: 0 | CX30: 0 | CY30: 0 | CZ30: 0 | DA30: 0 | DB30: 0 | DC30: 0 | DD30: 0 | DE30: 0 | DF30: 0 | DG30: 0 | DH30: 0 | DI30: 0 | DJ30: 0 | DK30: 0 | DL30: 0 | DM30: 0 | DN30: 0 | DO30: 0 | DP30: 0 | DQ30: 0 | DR30: 0 | DS30: 0 | DT30: 0 | DU30: 0 | DV30: 0 | DW30: 0 | DX30: 0 | DY30: 0 | DZ30: 0 | EA30: 0 | EB30: 0 | EC30: 0 | ED30: 0 | EE30: 0 | EF30: 0 | EG30: 0 | EH30: 0 | EI30: 0 | EJ30: 0 | EK30: 0 | EL30: 0 | EM30: 0 | EN30: 0 | EO30: 0 | EP30: 0 | EQ30: 0 | ER30: 0 | ES30: 0 | ET30: 0 | EU30: 0 | EV30: 0 | EW30: 0 | EX30: 0 | EY30: 0 | EZ30: 0 | FA30: 0 | FB30: 0 | FC30: 0 | FD30: 0 | FE30: 0 | FF30: 0 | FG30: 0 | FH30: 0 | FI30: 0 | FJ30: 0 | FK30: 0 | FL30: 0 | FM30: 0 | FN30: 0 | FO30: 0 | FP30: 0 | FQ30: 0 | FR30: 0 | FS30: 0 | FT30: 0 | FU30: 0 | FV30: 0 | FW30: 0 | FX30: 0 | FY30: 0 | FZ30: 0 | GA30: 0 | GB30: 0 | GC30: 0 | GD30: 0 | GE30: 0 | GF30: 0 | GG30: 0 | GH30: 0 | GI30: 0 | GJ30: 0 | GK30: 0 | GL30: 0 | GM30: 0 | GN30: 0 | GO30: 0 | GP30: 0 | GQ30: 0 | GR30: 0 | GS30: 0 | GT30: 0 | GU30: 0 | GV30: 0 | GW30: 0 | GX30: 0 | GY30: 0 | GZ30: 0
A31: 017.507-00 | B31: 2022/0032326-001 | C31: 2 | D31: 2022/0032326 | E31: ECT4953 | F31: 01/04/2026 | G31: 30/04/2026 | H31: CARLOS GONCALVES DOS SANTOS | I31: CARLOS GONCALVES DOS SANTOS | J31: ADAPTADO | K31: EMEI | L31: =CONTINUA!BV31 -> 0 | M31: =CONTINUA!BW31 -> 4 | O31: 6020.2022/0032326-6 | P31: 0 | Q31: 0 | R31: 2 | S31: 0 | T31: 1 | U31: 0 | V31: 0 | W31: 0 | X31: 2 | Y31: 0 | Z31: 1 | AA31: 0 | AB31: 0 | AC31: 0 | AD31: 2 | AE31: 0 | AF31: 1 | AG31: 0 | AH31: 0 | AI31: 0 | AJ31: 2 | AK31: 0 | AL31: 1 | AM31: 0 | AN31: 0 | AO31: 0 | AP31: 2 | AQ31: 0 | AR31: 1 | AS31: 0 | AT31: 0 | AU31: 0 | AV31: 2 | AW31: 0 | AX31: 1 | AY31: 0 | AZ31: 0 | BA31: 0 | BB31: 2 | BC31: 0 | BD31: 1 | BE31: 0 | BF31: 0 | BG31: 0 | BH31: 2 | BI31: 0 | BJ31: 1 | BK31: 0 | BL31: 0 | BM31: 0 | BN31: 2 | BO31: 0 | BP31: 1 | BQ31: 0 | BR31: 0 | BS31: 0 | BT31: 2 | BU31: 0 | BV31: 1 | BW31: 0 | BX31: 0 | BY31: 0 | BZ31: 2 | CA31: 0 | CB31: 1 | CC31: 0 | CD31: 0 | CE31: 0 | CF31: 2 | CG31: 0 | CH31: 1 | CI31: 0 | CJ31: 0 | CK31: 0 | CL31: 2 | CM31: 0 | CN31: 1 | CO31: 0 | CP31: 0 | CQ31: 0 | CR31: 2 | CS31: 0 | CT31: 1 | CU31: 0 | CV31: 0 | CW31: 0 | CX31: 2 | CY31: 0 | CZ31: 1 | DA31: 0 | DB31: 0 | DC31: 0 | DD31: 2 | DE31: 0 | DF31: 1 | DG31: 0 | DH31: 0 | DI31: 0 | DJ31: 2 | DK31: 0 | DL31: 1 | DM31: 0 | DN31: 0 | DO31: 0 | DP31: 2 | DQ31: 0 | DR31: 1 | DS31: 0 | DT31: 0 | DU31: 0 | DV31: 2 | DW31: 0 | DX31: 1 | DY31: 0 | DZ31: 0 | EA31: 0 | EB31: 2 | EC31: 0 | ED31: 1 | EE31: 0 | EF31: 0 | EG31: 0 | EH31: 2 | EI31: 0 | EJ31: 1 | EK31: 0 | EL31: 0 | EM31: 0 | EN31: 2 | EO31: 0 | EP31: 1 | EQ31: 0 | ER31: 0 | ES31: 0 | ET31: 2 | EU31: 0 | EV31: 1 | EW31: 0 | EX31: 0 | EY31: 0 | EZ31: 2 | FA31: 0 | FB31: 1 | FC31: 0 | FD31: 0 | FE31: 0 | FF31: 2 | FG31: 0 | FH31: 1 | FI31: 0 | FJ31: 0 | FK31: 0 | FL31: 2 | FM31: 0 | FN31: 1 | FO31: 0 | FP31: 0 | FQ31: 0 | FR31: 2 | FS31: 0 | FT31: 1 | FU31: 0 | FV31: 0 | FW31: 0 | FX31: 2 | FY31: 0 | FZ31: 1 | GA31: 0 | GB31: 0 | GC31: 0 | GD31: 2 | GE31: 0 | GF31: 1 | GG31: 0 | GH31: 0 | GI31: 0 | GJ31: 2 | GK31: 0 | GL31: 1 | GM31: 0 | GN31: 0 | GO31: 0 | GP31: 2 | GQ31: 0 | GR31: 1 | GS31: 0 | GT31: 0 | GU31: 0 | GV31: 2 | GW31: 0 | GX31: 1 | GY31: 0 | GZ31: 0
A32: 017.507-00 | B32: 2022/0032326-001 | C32: G | D32: 2022/0032326 | E32: ECT4953 | F32: 01/04/2026 | G32: 30/04/2026 | H32: CARLOS GONCALVES DOS SANTOS | I32: CARLOS GONCALVES DOS SANTOS | J32: ADAPTADO | K32: EMEF | L32: =CONTINUA!BV32 -> 12 | M32: =CONTINUA!BW32 -> 0 | O32: 6020.2022/0032326-6 | P32: 0 | Q32: 10 | R32: 2 | S32: 0 | T32: 0 | U32: 0 | V32: 0 | W32: 10 | X32: 2 | Y32: 0 | Z32: 0 | AA32: 0 | AB32: 0 | AC32: 10 | AD32: 2 | AE32: 0 | AF32: 0 | AG32: 0 | AH32: 0 | AI32: 10 | AJ32: 2 | AK32: 0 | AL32: 0 | AM32: 0 | AN32: 0 | AO32: 10 | AP32: 2 | AQ32: 0 | AR32: 0 | AS32: 0 | AT32: 0 | AU32: 10 | AV32: 2 | AW32: 0 | AX32: 0 | AY32: 0 | AZ32: 0 | BA32: 10 | BB32: 2 | BC32: 0 | BD32: 0 | BE32: 0 | BF32: 0 | BG32: 10 | BH32: 2 | BI32: 0 | BJ32: 0 | BK32: 0 | BL32: 0 | BM32: 10 | BN32: 2 | BO32: 0 | BP32: 0 | BQ32: 0 | BR32: 0 | BS32: 10 | BT32: 2 | BU32: 0 | BV32: 0 | BW32: 0 | BX32: 0 | BY32: 10 | BZ32: 2 | CA32: 0 | CB32: 0 | CC32: 0 | CD32: 0 | CE32: 10 | CF32: 2 | CG32: 0 | CH32: 0 | CI32: 0 | CJ32: 0 | CK32: 10 | CL32: 2 | CM32: 0 | CN32: 0 | CO32: 0 | CP32: 0 | CQ32: 10 | CR32: 2 | CS32: 0 | CT32: 0 | CU32: 0 | CV32: 0 | CW32: 10 | CX32: 2 | CY32: 0 | CZ32: 0 | DA32: 0 | DB32: 0 | DC32: 10 | DD32: 2 | DE32: 0 | DF32: 0 | DG32: 0 | DH32: 0 | DI32: 10 | DJ32: 2 | DK32: 0 | DL32: 0 | DM32: 0 | DN32: 0 | DO32: 10 | DP32: 2 | DQ32: 0 | DR32: 0 | DS32: 0 | DT32: 0 | DU32: 10 | DV32: 2 | DW32: 0 | DX32: 0 | DY32: 0 | DZ32: 0 | EA32: 10 | EB32: 2 | EC32: 0 | ED32: 0 | EE32: 0 | EF32: 0 | EG32: 10 | EH32: 2 | EI32: 0 | EJ32: 0 | EK32: 0 | EL32: 0 | EM32: 10 | EN32: 2 | EO32: 0 | EP32: 0 | EQ32: 0 | ER32: 0 | ES32: 10 | ET32: 2 | EU32: 0 | EV32: 0 | EW32: 0 | EX32: 0 | EY32: 10 | EZ32: 2 | FA32: 0 | FB32: 0 | FC32: 0 | FD32: 0 | FE32: 10 | FF32: 2 | FG32: 0 | FH32: 0 | FI32: 0 | FJ32: 0 | FK32: 10 | FL32: 2 | FM32: 0 | FN32: 0 | FO32: 0 | FP32: 0 | FQ32: 10 | FR32: 2 | FS32: 0 | FT32: 0 | FU32: 0 | FV32: 0 | FW32: 10 | FX32: 2 | FY32: 0 | FZ32: 0 | GA32: 0 | GB32: 0 | GC32: 10 | GD32: 2 | GE32: 0 | GF32: 0 | GG32: 0 | GH32: 0 | GI32: 10 | GJ32: 2 | GK32: 0 | GL32: 0 | GM32: 0 | GN32: 0 | GO32: 10 | GP32: 2 | GQ32: 0 | GR32: 0 | GS32: 0 | GT32: 0 | GU32: 10 | GV32: 2 | GW32: 0 | GX32: 0 | GY32: 0 | GZ32: 0
A33: 017.507-00 | B33: 2022/0032326-001 | C33: G | D33: 2022/0032326 | E33: ECT4953 | F33: 01/04/2026 | G33: 30/04/2026 | H33: CARLOS GONCALVES DOS SANTOS | I33: CARLOS GONCALVES DOS SANTOS | J33: ADAPTADO | K33: EMEE | L33: =CONTINUA!BV33 -> 0 | M33: =CONTINUA!BW33 -> 0 | O33: 6020.2022/0032326-6 | P33: 0 | Q33: 0 | R33: 0 | S33: 0 | T33: 0 | U33: 0 | V33: 0 | W33: 0 | X33: 0 | Y33: 0 | Z33: 0 | AA33: 0 | AB33: 0 | AC33: 0 | AD33: 0 | AE33: 0 | AF33: 0 | AG33: 0 | AH33: 0 | AI33: 0 | AJ33: 0 | AK33: 0 | AL33: 0 | AM33: 0 | AN33: 0 | AO33: 0 | AP33: 0 | AQ33: 0 | AR33: 0 | AS33: 0 | AT33: 0 | AU33: 0 | AV33: 0 | AW33: 0 | AX33: 0 | AY33: 0 | AZ33: 0 | BA33: 0 | BB33: 0 | BC33: 0 | BD33: 0 | BE33: 0 | BF33: 0 | BG33: 0 | BH33: 0 | BI33: 0 | BJ33: 0 | BK33: 0 | BL33: 0 | BM33: 0 | BN33: 0 | BO33: 0 | BP33: 0 | BQ33: 0 | BR33: 0 | BS33: 0 | BT33: 0 | BU33: 0 | BV33: 0 | BW33: 0 | BX33: 0 | BY33: 0 | BZ33: 0 | CA33: 0 | CB33: 0 | CC33: 0 | CD33: 0 | CE33: 0 | CF33: 0 | CG33: 0 | CH33: 0 | CI33: 0 | CJ33: 0 | CK33: 0 | CL33: 0 | CM33: 0 | CN33: 0 | CO33: 0 | CP33: 0 | CQ33: 0 | CR33: 0 | CS33: 0 | CT33: 0 | CU33: 0 | CV33: 0 | CW33: 0 | CX33: 0 | CY33: 0 | CZ33: 0 | DA33: 0 | DB33: 0 | DC33: 0 | DD33: 0 | DE33: 0 | DF33: 0 | DG33: 0 | DH33: 0 | DI33: 0 | DJ33: 0 | DK33: 0 | DL33: 0 | DM33: 0 | DN33: 0 | DO33: 0 | DP33: 0 | DQ33: 0 | DR33: 0 | DS33: 0 | DT33: 0 | DU33: 0 | DV33: 0 | DW33: 0 | DX33: 0 | DY33: 0 | DZ33: 0 | EA33: 0 | EB33: 0 | EC33: 0 | ED33: 0 | EE33: 0 | EF33: 0 | EG33: 0 | EH33: 0 | EI33: 0 | EJ33: 0 | EK33: 0 | EL33: 0 | EM33: 0 | EN33: 0 | EO33: 0 | EP33: 0 | EQ33: 0 | ER33: 0 | ES33: 0 | ET33: 0 | EU33: 0 | EV33: 0 | EW33: 0 | EX33: 0 | EY33: 0 | EZ33: 0 | FA33: 0 | FB33: 0 | FC33: 0 | FD33: 0 | FE33: 0 | FF33: 0 | FG33: 0 | FH33: 0 | FI33: 0 | FJ33: 0 | FK33: 0 | FL33: 0 | FM33: 0 | FN33: 0 | FO33: 0 | FP33: 0 | FQ33: 0 | FR33: 0 | FS33: 0 | FT33: 0 | FU33: 0 | FV33: 0 | FW33: 0 | FX33: 0 | FY33: 0 | FZ33: 0 | GA33: 0 | GB33: 0 | GC33: 0 | GD33: 0 | GE33: 0 | GF33: 0 | GG33: 0 | GH33: 0 | GI33: 0 | GJ33: 0 | GK33: 0 | GL33: 0 | GM33: 0 | GN33: 0 | GO33: 0 | GP33: 0 | GQ33: 0 | GR33: 0 | GS33: 0 | GT33: 0 | GU33: 0 | GV33: 0 | GW33: 0 | GX33: 0 | GY33: 0 | GZ33: 0
A34: 017.507-00 | B34: 2022/0032326-001 | C34: G | D34: 2022/0032326 | E34: ECT4953 | F34: 01/04/2026 | G34: 30/04/2026 | H34: CARLOS GONCALVES DOS SANTOS | I34: CARLOS GONCALVES DOS SANTOS | J34: ADAPTADO | K34: CEI | L34: =CONTINUA!BV34 -> 0 | M34: =CONTINUA!BW34 -> 0 | O34: 6020.2022/0032326-6 | P34: 0 | Q34: 0 | R34: 0 | S34: 0 | T34: 0 | U34: 0 | V34: 0 | W34: 0 | X34: 0 | Y34: 0 | Z34: 0 | AA34: 0 | AB34: 0 | AC34: 0 | AD34: 0 | AE34: 0 | AF34: 0 | AG34: 0 | AH34: 0 | AI34: 0 | AJ34: 0 | AK34: 0 | AL34: 0 | AM34: 0 | AN34: 0 | AO34: 0 | AP34: 0 | AQ34: 0 | AR34: 0 | AS34: 0 | AT34: 0 | AU34: 0 | AV34: 0 | AW34: 0 | AX34: 0 | AY34: 0 | AZ34: 0 | BA34: 0 | BB34: 0 | BC34: 0 | BD34: 0 | BE34: 0 | BF34: 0 | BG34: 0 | BH34: 0 | BI34: 0 | BJ34: 0 | BK34: 0 | BL34: 0 | BM34: 0 | BN34: 0 | BO34: 0 | BP34: 0 | BQ34: 0 | BR34: 0 | BS34: 0 | BT34: 0 | BU34: 0 | BV34: 0 | BW34: 0 | BX34: 0 | BY34: 0 | BZ34: 0 | CA34: 0 | CB34: 0 | CC34: 0 | CD34: 0 | CE34: 0 | CF34: 0 | CG34: 0 | CH34: 0 | CI34: 0 | CJ34: 0 | CK34: 0 | CL34: 0 | CM34: 0 | CN34: 0 | CO34: 0 | CP34: 0 | CQ34: 0 | CR34: 0 | CS34: 0 | CT34: 0 | CU34: 0 | CV34: 0 | CW34: 0 | CX34: 0 | CY34: 0 | CZ34: 0 | DA34: 0 | DB34: 0 | DC34: 0 | DD34: 0 | DE34: 0 | DF34: 0 | DG34: 0 | DH34: 0 | DI34: 0 | DJ34: 0 | DK34: 0 | DL34: 0 | DM34: 0 | DN34: 0 | DO34: 0 | DP34: 0 | DQ34: 0 | DR34: 0 | DS34: 0 | DT34: 0 | DU34: 0 | DV34: 0 | DW34: 0 | DX34: 0 | DY34: 0 | DZ34: 0 | EA34: 0 | EB34: 0 | EC34: 0 | ED34: 0 | EE34: 0 | EF34: 0 | EG34: 0 | EH34: 0 | EI34: 0 | EJ34: 0 | EK34: 0 | EL34: 0 | EM34: 0 | EN34: 0 | EO34: 0 | EP34: 0 | EQ34: 0 | ER34: 0 | ES34: 0 | ET34: 0 | EU34: 0 | EV34: 0 | EW34: 0 | EX34: 0 | EY34: 0 | EZ34: 0 | FA34: 0 | FB34: 0 | FC34: 0 | FD34: 0 | FE34: 0 | FF34: 0 | FG34: 0 | FH34: 0 | FI34: 0 | FJ34: 0 | FK34: 0 | FL34: 0 | FM34: 0 | FN34: 0 | FO34: 0 | FP34: 0 | FQ34: 0 | FR34: 0 | FS34: 0 | FT34: 0 | FU34: 0 | FV34: 0 | FW34: 0 | FX34: 0 | FY34: 0 | FZ34: 0 | GA34: 0 | GB34: 0 | GC34: 0 | GD34: 0 | GE34: 0 | GF34: 0 | GG34: 0 | GH34: 0 | GI34: 0 | GJ34: 0 | GK34: 0 | GL34: 0 | GM34: 0 | GN34: 0 | GO34: 0 | GP34: 0 | GQ34: 0 | GR34: 0 | GS34: 0 | GT34: 0 | GU34: 0 | GV34: 0 | GW34: 0 | GX34: 0 | GY34: 0 | GZ34: 0
A35: 017.507-00 | B35: 2022/0032326-001 | C35: G | D35: 2022/0032326 | E35: ECT4953 | F35: 01/04/2026 | G35: 30/04/2026 | H35: CARLOS GONCALVES DOS SANTOS | I35: CARLOS GONCALVES DOS SANTOS | J35: ADAPTADO | K35: CCA | L35: =CONTINUA!BV35 -> 0 | M35: =CONTINUA!BW35 -> 0 | O35: 6020.2022/0032326-6 | P35: 0 | Q35: 0 | R35: 0 | S35: 0 | T35: 0 | U35: 0 | V35: 0 | W35: 0 | X35: 0 | Y35: 0 | Z35: 0 | AA35: 0 | AB35: 0 | AC35: 0 | AD35: 0 | AE35: 0 | AF35: 0 | AG35: 0 | AH35: 0 | AI35: 0 | AJ35: 0 | AK35: 0 | AL35: 0 | AM35: 0 | AN35: 0 | AO35: 0 | AP35: 0 | AQ35: 0 | AR35: 0 | AS35: 0 | AT35: 0 | AU35: 0 | AV35: 0 | AW35: 0 | AX35: 0 | AY35: 0 | AZ35: 0 | BA35: 0 | BB35: 0 | BC35: 0 | BD35: 0 | BE35: 0 | BF35: 0 | BG35: 0 | BH35: 0 | BI35: 0 | BJ35: 0 | BK35: 0 | BL35: 0 | BM35: 0 | BN35: 0 | BO35: 0 | BP35: 0 | BQ35: 0 | BR35: 0 | BS35: 0 | BT35: 0 | BU35: 0 | BV35: 0 | BW35: 0 | BX35: 0 | BY35: 0 | BZ35: 0 | CA35: 0 | CB35: 0 | CC35: 0 | CD35: 0 | CE35: 0 | CF35: 0 | CG35: 0 | CH35: 0 | CI35: 0 | CJ35: 0 | CK35: 0 | CL35: 0 | CM35: 0 | CN35: 0 | CO35: 0 | CP35: 0 | CQ35: 0 | CR35: 0 | CS35: 0 | CT35: 0 | CU35: 0 | CV35: 0 | CW35: 0 | CX35: 0 | CY35: 0 | CZ35: 0 | DA35: 0 | DB35: 0 | DC35: 0 | DD35: 0 | DE35: 0 | DF35: 0 | DG35: 0 | DH35: 0 | DI35: 0 | DJ35: 0 | DK35: 0 | DL35: 0 | DM35: 0 | DN35: 0 | DO35: 0 | DP35: 0 | DQ35: 0 | DR35: 0 | DS35: 0 | DT35: 0 | DU35: 0 | DV35: 0 | DW35: 0 | DX35: 0 | DY35: 0 | DZ35: 0 | EA35: 0 | EB35: 0 | EC35: 0 | ED35: 0 | EE35: 0 | EF35: 0 | EG35: 0 | EH35: 0 | EI35: 0 | EJ35: 0 | EK35: 0 | EL35: 0 | EM35: 0 | EN35: 0 | EO35: 0 | EP35: 0 | EQ35: 0 | ER35: 0 | ES35: 0 | ET35: 0 | EU35: 0 | EV35: 0 | EW35: 0 | EX35: 0 | EY35: 0 | EZ35: 0 | FA35: 0 | FB35: 0 | FC35: 0 | FD35: 0 | FE35: 0 | FF35: 0 | FG35: 0 | FH35: 0 | FI35: 0 | FJ35: 0 | FK35: 0 | FL35: 0 | FM35: 0 | FN35: 0 | FO35: 0 | FP35: 0 | FQ35: 0 | FR35: 0 | FS35: 0 | FT35: 0 | FU35: 0 | FV35: 0 | FW35: 0 | FX35: 0 | FY35: 0 | FZ35: 0 | GA35: 0 | GB35: 0 | GC35: 0 | GD35: 0 | GE35: 0 | GF35: 0 | GG35: 0 | GH35: 0 | GI35: 0 | GJ35: 0 | GK35: 0 | GL35: 0 | GM35: 0 | GN35: 0 | GO35: 0 | GP35: 0 | GQ35: 0 | GR35: 0 | GS35: 0 | GT35: 0 | GU35: 0 | GV35: 0 | GW35: 0 | GX35: 0 | GY35: 0 | GZ35: 0
