Workbook
Name \a: #REF!
Name \a: #REF!
Name \p: #REF!
Name \p: #REF!
Name _______xlnm.Print_Titles: #REF!
Name _______xlnm_Print_Titles: NA()
Name ______xlnm._FilterDatabase: "#ref!"
Name ______xlnm.Print_Titles: #REF!
Name ______xlnm__FilterDatabase: "#ref!"
Name ______xlnm_Print_Titles: NA()
Name _____xlfn_BAHTTEXT: NA()
Name _____xlfn_SUMIFS: NA()
Name _____xlnm._FilterDatabase: "#ref!"
Name _____xlnm.Print_Titles: #REF!
Name _____xlnm__FilterDatabase: "#ref!"
Name _____xlnm_Print_Titles: NA()
Name ____xlfn_BAHTTEXT: NA()
Name ____xlfn_SUMIFS: NA()
Name ____xlnm._FilterDatabase: "#ref!"
Name ____xlnm.Print_Titles: #REF!
Name ____xlnm__FilterDatabase: "#ref!"
Name ____xlnm_Print_Titles: NA()
Name ___xlfn_BAHTTEXT: NA()
Name ___xlfn_SUMIFS: NA()
Name ___xlnm._FilterDatabase: "#ref!"
Name ___xlnm.Print_Titles: #REF!
Name ___xlnm__FilterDatabase: "#ref!"
Name ___xlnm_Print_Titles: NA()
Name __TAB3688: #REF!
Name __xlfn_BAHTTEXT: NA()
Name __xlfn_SUMIFS: NA()
Name __xlnm._FilterDatabase: "#ref!"
Name __xlnm.Print_Titles: #REF!
Name __xlnm__FilterDatabase: "#ref!"
Name __xlnm_Print_Titles: NA()
Name _TAB3688: #REF!
Name _TAB3688: #REF!
Name a: #REF!
Name abr: #REF!
Name abr: #REF!
Name abril: #REF!
Name ACRESCENTAR: #REF!
Name ADAPTADO: '[1]APONTAMENTO CREDENCIAMENTO'!#REF!
Name ADAPTADO: 'APONTAMENTO CREDENCIAMENTO'!$FF$7:$GJ$7
Name AGOSTO: #REF!
Name AI: #REF!
Name AI: #REF!
Name AII: #REF!
Name AII: #REF!
Name AK: #REF!
Name AK: #REF!
Name AL: #REF!
Name AL: #REF!
Name AMPLIAR: #REF!
Name AMPLIAR: #REF!
Name ApagaAtesteFis: 'ATESTE-LIQ-FIS'!$A$4:$K$3908
Name ApagaBaseC: 'BASE C'!$A$11:$N$4950
Name ApagaDadosA: 'APONTAMENTO CREDENCIAMENTO'!$Q$6:$EL$3994
Name ApagaDadosC: CONTINUA!$L$6:$BU$4012
Name ApagarDadosDigitados: #REF!

Sheet APONTAMENTO CREDENCIAMENTO
A1: Butantã | G1: ='BASE C'!E4 -> ABRIL | I1: APONTAMENTO CREDENCIAMENTO | EL1: ATENÇÃO
G2: 01/06 a 30/06/2025
A3: 1 | B3: =A3+1 -> 2 | C3: =B3+1 -> 3 | D3: 1 | E3: =D3+1 -> 2 | F3: =E3+1 -> 3 | G3: =F3+1 -> 4 | H3: =G3+1 -> 5 | I3: =H3+1 -> 6 | J3: =I3+1 -> 7 | K3: =J3+1 -> 8 | L3: =K3+1 -> 9 | M3: =L3+1 -> 10 | N3: 10 | O3: =N3+1 -> 11 | P3: 13 | Q3: =P3+1 -> 14 | R3: =Q3+1 -> 15 | S3: =R3+1 -> 16 | T3: =S3+1 -> 17 | U3: =T3+1 -> 18 | V3: =U3+1 -> 19 | W3: =V3+1 -> 20 | X3: =W3+1 -> 21 | ... EL3: =EK3+1 -> 139 | EM3: 140 | EN3: =EM3+1 -> 141 | EO3: =EN3+1 -> 142 | EP3: =EO3+1 -> 143 | EQ3: =EP3+1 -> 144 | ER3: =EQ3+1 -> 145 | ES3: =ER3+1 -> 146 | ET3: =ES3+1 -> 147 | EU3: =ET3+1 -> 148 | ... IA3: =HZ3+1 -> 232
A4: CRMC | B4: OS | C4: DRE | D4: CONTRATO | E4: PLACA | F4: PERÍODO | H4: EMPRESA | I4: NOME CONDUTOR | J4: TIPO DE VEÍCULO (NORMAL, ADAPTADO) | K4: TIPO DE ATENDIMENTO | L4: TOTAL CONT REG | M4: TOTAL CONT CAD | N4: KM ADICIONAL | O4: SEI | P4: Tipo Optante | Q4: =F5 -> 01/04/2026 | U4: =Q4+1 -> 46114 | Y4: =U4+1 -> 46115 | AC4: =Y4+1 -> 46116 | AG4: =AC4+1 -> 46117 | AK4: =AG4+1 -> 46118 | AO4: =AK4+1 -> 46119 | AS4: =AO4+1 -> 46120 | AW4: =AS4+1 -> 46121 | BA4: =AW4+1 -> 46122 | BE4: =BA4+1 -> 46123 | BI4: =BE4+1 -> 46124 | BM4: =BI4+1 -> 46125 | BQ4: =BM4+1 -> 46126 | BU4: =BQ4+1 -> 46127 | BY4: =BU4+1 -> 46128 | CC4: =BY4+1 -> 46129 | CG4: =CC4+1 -> 46130 | CK4: =CG4+1 -> 46131 | CO4: =CK4+1 -> 46132 | CS4: =CO4+1 -> 46133 | CW4: =CS4+1 -> 46134 | DA4: =CW4+1 -> 46135 | DE4: =DA4+1 -> 46136 | DI4: =DE4+1 -> 46137 | DM4: =DI4+1 -> 46138 | DQ4: =DM4+1 -> 46139 | DU4: =DQ4+1 -> 46140 | DY4: =DU4+1 -> 46141 | EC4: =DY4+1 -> 46142 | EK4: FALTAS - APONTAR AS DATAS | EL4: OBSERVAÇÕES ALUNO PRESENCIAL COLUNAS FINAIS | EM4: Ajuste positivo | EN4: Ajuste negativo | EO4: Desconto faltas | EP4: TOTAL ALUNOS N CAD(30 DIAS) | EQ4: TOTAL ALUNOS N CAD(MENOS DE 30 DIAS) | ER4: TOTAL ALUNOS ATIV.COMPL. N CAD | ES4: TOTAL ALUNOS CAD (30 DIAS) | ET4: TOTAL ALUNOS CAD (MENOS DE 30 DIAS) | EU4: TOTAL ALUNOS ATIV.COMPL. CAD | EV4: TOTAL GERAL | EW4: Contratos Especiais (Valor fixo) | EX4: Valor total alunos presenciais (30 dias) | EY4: Ativ.Complementar Continuada | EZ4: Valor alunos presenciais (menos de 30 dias) | FA4: Saida de alunos ao longo do mês | FB4: CCA | FC4: Valor km adicional | FD4: Outros apontamentos | FE4: VALOR ATESTE | FF4: 30 | FG4: =FF4-1 -> 29 | FH4: =FG4-1 -> 28 | FI4: =FH4-1 -> 27 | FJ4: =FI4-1 -> 26 | FK4: =FJ4-1 -> 25 | FL4: =FK4-1 -> 24 | FM4: =FL4-1 -> 23 | FN4: =FM4-1 -> 22 | ... GI4: =GH4-1 -> 1 | GJ4: 1 | GK4: Multa Contratual | GL4: CÁLCULO | GM4: DIAS | GN4: 29 | GO4: =GN4-1 -> 28 | GP4: =GO4-1 -> 27 | GQ4: =GP4-1 -> 26 | GR4: =GQ4-1 -> 25 | GS4: =GR4-1 -> 24 | GT4: =GS4-1 -> 23 | GU4: =GT4-1 -> 22 | GV4: =GU4-1 -> 21 | ... HP4: =HO4-1 -> 1 | HW4: VALOR ATESTE | HY4: Ajuste positivo | HZ4: Ajuste negativo | IA4: Desconto faltas
F5: 01/04/2026 | G5: 30/04/2026 | Q5: N CAD presencial | R5: CAD | S5: AT. COMPL. N CAD | T5: AT. COMPL. CAD | U5: N CAD presencial | V5: CAD | W5: AT. COMPL. N CAD | X5: AT. COMPL. CAD | Y5: N CAD presencial | Z5: CAD | AA5: AT. COMPL. N CAD | AB5: AT. COMPL. CAD | AC5: N CAD presencial | AD5: CAD | AE5: AT. COMPL. N CAD | AF5: AT. COMPL. CAD | AG5: N CAD presencial | AH5: CAD | AI5: AT. COMPL. N CAD | AJ5: AT. COMPL. CAD | AK5: N CAD presencial | AL5: CAD | AM5: AT. COMPL. N CAD | AN5: AT. COMPL. CAD | AO5: N CAD presencial | AP5: CAD | AQ5: AT. COMPL. N CAD | AR5: AT. COMPL. CAD | AS5: N CAD presencial | AT5: CAD | AU5: AT. COMPL. N CAD | AV5: AT. COMPL. CAD | AW5: N CAD presencial | AX5: CAD | AY5: AT. COMPL. N CAD | AZ5: AT. COMPL. CAD | BA5: N CAD presencial | BB5: CAD | BC5: AT. COMPL. N CAD | BD5: AT. COMPL. CAD | BE5: N CAD presencial | BF5: CAD | BG5: AT. COMPL. N CAD | BH5: AT. COMPL. CAD | BI5: N CAD presencial | BJ5: CAD | BK5: AT. COMPL. N CAD | BL5: AT. COMPL. CAD | BM5: N CAD presencial | BN5: CAD | BO5: AT. COMPL. N CAD | BP5: AT. COMPL. CAD | BQ5: N CAD presencial | BR5: CAD | BS5: AT. COMPL. N CAD | BT5: AT. COMPL. CAD | BU5: N CAD presencial | BV5: CAD | BW5: AT. COMPL. N CAD | BX5: AT. COMPL. CAD | BY5: N CAD presencial | BZ5: CAD | CA5: AT. COMPL. N CAD | CB5: AT. COMPL. CAD | CC5: N CAD presencial | CD5: CAD | CE5: AT. COMPL. N CAD | CF5: AT. COMPL. CAD | CG5: N CAD presencial | CH5: CAD | CI5: AT. COMPL. N CAD | CJ5: AT. COMPL. CAD | CK5: N CAD presencial | CL5: CAD | CM5: AT. COMPL. N CAD | CN5: AT. COMPL. CAD | CO5: N CAD presencial | CP5: CAD | CQ5: AT. COMPL. N CAD | CR5: AT. COMPL. CAD | CS5: N CAD presencial | CT5: CAD | CU5: AT. COMPL. N CAD | CV5: AT. COMPL. CAD | CW5: N CAD presencial | CX5: CAD | CY5: AT. COMPL. N CAD | CZ5: AT. COMPL. CAD | DA5: N CAD presencial | DB5: CAD | DC5: AT. COMPL. N CAD | DD5: AT. COMPL. CAD | DE5: N CAD presencial | DF5: CAD | DG5: AT. COMPL. N CAD | DH5: AT. COMPL. CAD | DI5: N CAD presencial | DJ5: CAD | DK5: AT. COMPL. N CAD | DL5: AT. COMPL. CAD | DM5: N CAD presencial | DN5: CAD | DO5: AT. COMPL. N CAD | DP5: AT. COMPL. CAD | DQ5: N CAD presencial | DR5: CAD | DS5: AT. COMPL. N CAD | DT5: AT. COMPL. CAD | DU5: N CAD presencial | DV5: CAD | DW5: AT. COMPL. N CAD | DX5: AT. COMPL. CAD | DY5: N CAD presencial | DZ5: CAD | EA5: AT. COMPL. N CAD | EB5: AT. COMPL. CAD | EC5: N CAD presencial | ED5: CAD | EE5: AT. COMPL. N CAD | EF5: AT. COMPL. CAD | EG5: N CAD presencial | EH5: CAD | EI5: AT. COMPL. N CAD | EJ5: AT. COMPL. CAD
A6: 028.293-00 | B6: 2024/0058910-001 | C6: 1 | D6: 2024/0058910 | E6: EFV2108 | F6: 01/04/2026 | G6: 30/04/2026 | H6: A.C.G. TRANSPORTE ESCOLAR LTDA | I6: ANDREIA PEREIRA DA SILVA | J6: NORMAL | K6: EMEI | L6: =CONTINUA!BV6 -> 0 | M6: =CONTINUA!BW6 -> 0 | O6: 6020.2024/0058910-3 | P6: O | EP6: =Q6 -> 0 | EQ6: =U6+Y6+AC6+AG6+AK6+AO6+AS6+AW6+BA6+BE6+BI6+BM6+BQ6+BU6+BY6+CC6+CG6+CK6+CO6+CS6+CW6+DA6+DE6+DI6+DM6+DQ6+DU6+DY6+EC6+EG6 -> 0 | ER6: =S6+W6+AA6+AE6+AI6+AM6+AQ6+AU6+AY6+BC6+BG6+BK6+BO6+BS6+BW6+CA6+CE6+CI6+CM6+CQ6+CU6+CY6+DC6+DG6+DK6+DO6+DS6+DW6+EA6+EE6+EI6 -> 0 | ES6: =R6 -> 0 | ET6: =V6+Z6+AD6+AH6+AL6+AP6+AT6+AX6+BB6+BF6+BJ6+BN6+BR6+BV6+BZ6+CD6+CH6+CL6+CP6+CT6+CX6+DB6+DF6+DJ6+DN6+DR6+DV6+DZ6+ED6+EH6 -> 0 | EU6: =T6+X6+AB6+AF6+AJ6+AN6+AR6+AV6+AZ6+BD6+BH6+BL6+BP6+BT6+BX6+CB6+CF6+CJ6+CN6+CR6+CV6+CZ6+DD6+DH6+DL6+DP6+DT6+DX6+EB6+EF6+EJ6 -> 0 | EV6: =EP6+EQ6+ES6+ET6+ER6+EU6 -> 0 | EW6: =IF(C6=4,IF(MAX(Q6:EJ8)>0,(Especiall/30*(IF(($G6-$F6)=($G$5-$F$5),30,IF(DAY($G6)=31,($G6-$F6),($G6-$F6)+1)))),0),0) -> 0 | EX6: =FF6 -> 20205.11 | EY6: =(L6*regular)+(M6*Cadeirantee) -> 0 | EZ6: =SUMIF(FG6:GJ6,">0") -> 295.343 | FA6: =SUMIF(FG6:GJ6,"<0")+SUMIF(GN6:HP6,"<0") -> 0 | FB6: 0 | FC6: =N6*km*'VALORES TABELA'!$B$13 -> 0 | FD6: =GL6 -> 0 | FE6: =(EW6+EW7+EW8+EW9+EX6+EX7+EX8+EX9+EY6+EY7+EY8+EY9+EY10+EZ6+EZ7+EZ8+EZ9+FA6+FA7+FA8+FA9+FC6+FC7+FC8+FC9+HY6-HZ6-IA6+FD6+FD7+FD8+FD9+FB10) -> 20943.893 | FF6: =IF(C6=4,SUM(Q6+Q7+Q8+S6+S7+S8)*Percapita/30*FF$4+(R6+R7+R8+T6+T7+T8)*Cadeirante/30*FF$4,IF(C6=3,IF(Q9+S9=10,Fixo/30*FF$4+(Q6+Q7+Q8+S6+S7+S8)*Percapita/30*FF$4+(R9+T9)*Cadeirante/30*FF$4,IF(Q9+S9<=9,(Q9+S9)*Crechee/30*FF$4)+(R9+T9)*Cadeirante/30*FF$4+(Q6+Q7+Q8+S6+S7+S8)*Percapita/30*FF$4)+IF(Q9+S9>=11,Fixo/30*FF$4+(Q9+S9-10)*Crechee/30*FF$4,0),IF(C6=2,IF(R6+R7+R8+R9+T6+T7+T8+T9=1,Cadeirante/30*FF$4,IF(R6+R7+R8+R9+T6+T7+T8+T9=2,Fixo/30*FF$4,IF(R6+R7+R8+R9+T6+T7+T8+T9>2,Fixo/30*FF$4+(R6+R7+R8+R9+T6+T7+T8+T9-2)*Cadeirante/30*FF$4)))+(Q6+Q7+Q8+S6+S7+S8)*Percapita/30*FF$4+(Q9+S9)*Crechee/30*FF$4,IF(C6=1,IF(Q6+Q7+Q8+R6+R7+R8+S6+S7+S8+T6+T7+T8<=15,(Q6+Q7+Q8+S6+S7+S8)*Percapita/30*FF$4,IF(Q6+Q7+Q8+R6+R7+R8+S6+S7+S8+T6+T7+T8>=16,Fixo/30*FF$4+(Q6+Q7+Q8+R6+R7+R8+S6+S7+S8+T6+T7-16)*Percapita/30*FF$4)))))) -> 20205.11 | FG6: =IF(C6=4,SUM(U6+U7+U8+W6+W7+W8)*Percapita/30*FG$4+(V6+V7+V8+X6+X7+X8)*Cadeirante/30*FG$4,IF(C6=3,IF(U9+W9=10,Fixo/30*FG$4+(U6+U7+U8+W6+W7+W8)*Percapita/30*FG$4+(V9+X9)*Cadeirante/30*FG$4,IF(U9+W9<=9,(U9+W9)*Crechee/30*FG$4)+(V9+X9)*Cadeirante/30*FG$4+(U6+U7+U8+W6+W7+W8)*Percapita/30*FG$4)+IF(U9+W9>=11,Fixo/30*FG$4+(U9+W9-10)*Crechee/30*FG$4,0),IF(C6=2,IF(V6+V7+V8+V9+X6+X7+X8+X9=1,Cadeirante/30*FG$4,IF(V6+V7+V8+V9+X6+X7+X8+X9=2,Fixo/30*FG$4,IF(V6+V7+V8+V9+X6+X7+X8+X9>2,Fixo/30*FG$4+(V6+V7+V8+V9+X6+X7+X8+X9-2)*Cadeirante/30*FG$4)))+(U6+U7+U8+W6+W7+W8)*Percapita/30*FG$4+(U9+W9)*Crechee/30*FG$4,IF(C6=1,IF(U6+U7+U8+V6+V7+V8+W6+W7+W8+X6+X7+X8<=15,(U6+U7+U8+W6+W7+W8)*Percapita/30*FG$4,IF(U6+U7+U8+V6+V7+V8+W6+W7+W8+X6+X7+X8>=16,Fixo/30*FG$4+(U6+U7+U8+V6+V7+V8+W6+W7+W8+X6+X7-16)*Percapita/30*FG$4)))))) -> 0 | FH6: =IF(C6=4,SUM(Y6+Y7+Y8+AA6+AA7+AA8)*Percapita/30*FH$4+(Z6+Z7+Z8+AB6+AB7+AB8)*Cadeirante/30*FH$4,IF(C6=3,IF(Y9+AA9=10,Fixo/30*FH$4+(Y6+Y7+Y8+AA6+AA7+AA8)*Percapita/30*FH$4+(Z9+AB9)*Cadeirante/30*FH$4,IF(Y9+AA9<=9,(Y9+AA9)*Crechee/30*FH$4)+(Z9+AB9)*Cadeirante/30*FH$4+(Y6+Y7+Y8+AA6+AA7+AA8)*Percapita/30*FH$4)+IF(Y9+AA9>=11,Fixo/30*FH$4+(Y9+AA9-10)*Crechee/30*FH$4,0),IF(C6=2,IF(Z6+Z7+Z8+Z9+AB6+AB7+AB8+AB9=1,Cadeirante/30*FH$4,IF(Z6+Z7+Z8+Z9+AB6+AB7+AB8+AB9=2,Fixo/30*FH$4,IF(Z6+Z7+Z8+Z9+AB6+AB7+AB8+AB9>2,Fixo/30*FH$4+(Z6+Z7+Z8+Z9+AB6+AB7+AB8+AB9-2)*Cadeirante/30*FH$4)))+(Y6+Y7+Y8+AA6+AA7+AA8)*Percapita/30*FH$4+(Y9+AA9)*Crechee/30*FH$4,IF(C6=1,IF(Y6+Y7+Y8+Z6+Z7+Z8+AA6+AA7+AA8+AB6+AB7+AB8<=15,(Y6+Y7+Y8+AA6+AA7+AA8)*Percapita/30*FH$4,IF(Y6+Y7+Y8+Z6+Z7+Z8+AA6+AA7+AA8+AB6+AB7+AB8>=16,Fixo/30*FH$4+(Y6+Y7+Y8+Z6+Z7+Z8+AA6+AA7+AA8+AB6+AB7-16)*Percapita/30*FH$4)))))) -> 0 | FI6: =IF(C6=4,SUM(AC6+AC7+AC8+AE6+AE7+AE8)*Percapita/30*FI$4+(AD6+AD7+AD8+AF6+AF7+AF8)*Cadeirante/30*FI$4,IF(C6=3,IF(AC9+AE9=10,Fixo/30*FI$4+(AC6+AC7+AC8+AE6+AE7+AE8)*Percapita/30*FI$4+(AD9+AF9)*Cadeirante/30*FI$4,IF(AC9+AE9<=9,(AC9+AE9)*Crechee/30*FI$4)+(AD9+AF9)*Cadeirante/30*FI$4+(AC6+AC7+AC8+AE6+AE7+AE8)*Percapita/30*FI$4)+IF(AC9+AE9>=11,Fixo/30*FI$4+(AC9+AE9-10)*Crechee/30*FI$4,0),IF(C6=2,IF(AD6+AD7+AD8+AD9+AF6+AF7+AF8+AF9=1,Cadeirante/30*FI$4,IF(AD6+AD7+AD8+AD9+AF6+AF7+AF8+AF9=2,Fixo/30*FI$4,IF(AD6+AD7+AD8+AD9+AF6+AF7+AF8+AF9>2,Fixo/30*FI$4+(AD6+AD7+AD8+AD9+AF6+AF7+AF8+AF9-2)*Cadeirante/30*FI$4)))+(AC6+AC7+AC8+AE6+AE7+AE8)*Percapita/30*FI$4+(AC9+AE9)*Crechee/30*FI$4,IF(C6=1,IF(AC6+AC7+AC8+AD6+AD7+AD8+AE6+AE7+AE8+AF6+AF7+AF8<=15,(AC6+AC7+AC8+AE6+AE7+AE8)*Percapita/30*FI$4,IF(AC6+AC7+AC8+AD6+AD7+AD8+AE6+AE7+AE8+AF6+AF7+AF8>=16,Fixo/30*FI$4+(AC6+AC7+AC8+AD6+AD7+AD8+AE6+AE7+AE8+AF6+AF7-16)*Percapita/30*FI$4)))))) -> 0 | FJ6: =IF(C6=4,SUM(AG6+AG7+AG8+AI6+AI7+AI8)*Percapita/30*FJ$4+(AH6+AH7+AH8+AJ6+AJ7+AJ8)*Cadeirante/30*FJ$4,IF(C6=3,IF(AG9+AI9=10,Fixo/30*FJ$4+(AG6+AG7+AG8+AI6+AI7+AI8)*Percapita/30*FJ$4+(AH9+AJ9)*Cadeirante/30*FJ$4,IF(AG9+AI9<=9,(AG9+AI9)*Crechee/30*FJ$4)+(AH9+AJ9)*Cadeirante/30*FJ$4+(AG6+AG7+AG8+AI6+AI7+AI8)*Percapita/30*FJ$4)+IF(AG9+AI9>=11,Fixo/30*FJ$4+(AG9+AI9-10)*Crechee/30*FJ$4,0),IF(C6=2,IF(AH6+AH7+AH8+AH9+AJ6+AJ7+AJ8+AJ9=1,Cadeirante/30*FJ$4,IF(AH6+AH7+AH8+AH9+AJ6+AJ7+AJ8+AJ9=2,Fixo/30*FJ$4,IF(AH6+AH7+AH8+AH9+AJ6+AJ7+AJ8+AJ9>2,Fixo/30*FJ$4+(AH6+AH7+AH8+AH9+AJ6+AJ7+AJ8+AJ9-2)*Cadeirante/30*FJ$4)))+(AG6+AG7+AG8+AI6+AI7+AI8)*Percapita/30*FJ$4+(AG9+AI9)*Crechee/30*FJ$4,IF(C6=1,IF(AG6+AG7+AG8+AH6+AH7+AH8+AI6+AI7+AI8+AJ6+AJ7+AJ8<=15,(AG6+AG7+AG8+AI6+AI7+AI8)*Percapita/30*FJ$4,IF(AG6+AG7+AG8+AH6+AH7+AH8+AI6+AI7+AI8+AJ6+AJ7+AJ8>=16,Fixo/30*FJ$4+(AG6+AG7+AG8+AH6+AH7+AH8+AI6+AI7+AI8+AJ6+AJ7-16)*Percapita/30*FJ$4)))))) -> 0 | FK6: =IF(C6=4,SUM(AK6+AK7+AK8+AM6+AM7+AM8)*Percapita/30*FK$4+(AL6+AL7+AL8+AN6+AN7+AN8)*Cadeirante/30*FK$4,IF(C6=3,IF(AK9+AM9=10,Fixo/30*FK$4+(AK6+AK7+AK8+AM6+AM7+AM8)*Percapita/30*FK$4+(AL9+AN9)*Cadeirante/30*FK$4,IF(AK9+AM9<=9,(AK9+AM9)*Crechee/30*FK$4)+(AL9+AN9)*Cadeirante/30*FK$4+(AK6+AK7+AK8+AM6+AM7+AM8)*Percapita/30*FK$4)+IF(AK9+AM9>=11,Fixo/30*FK$4+(AK9+AM9-10)*Crechee/30*FK$4,0),IF(C6=2,IF(AL6+AL7+AL8+AL9+AN6+AN7+AN8+AN9=1,Cadeirante/30*FK$4,IF(AL6+AL7+AL8+AL9+AN6+AN7+AN8+AN9=2,Fixo/30*FK$4,IF(AL6+AL7+AL8+AL9+AN6+AN7+AN8+AN9>2,Fixo/30*FK$4+(AL6+AL7+AL8+AL9+AN6+AN7+AN8+AN9-2)*Cadeirante/30*FK$4)))+(AK6+AK7+AK8+AM6+AM7+AM8)*Percapita/30*FK$4+(AK9+AM9)*Crechee/30*FK$4,IF(C6=1,IF(AK6+AK7+AK8+AL6+AL7+AL8+AM6+AM7+AM8+AN6+AN7+AN8<=15,(AK6+AK7+AK8+AM6+AM7+AM8)*Percapita/30*FK$4,IF(AK6+AK7+AK8+AL6+AL7+AL8+AM6+AM7+AM8+AN6+AN7+AN8>=16,Fixo/30*FK$4+(AK6+AK7+AK8+AL6+AL7+AL8+AM6+AM7+AM8+AN6+AN7-16)*Percapita/30*FK$4)))))) -> 0 | FL6: =IF(C6=4,SUM(AO6+AO7+AO8+AQ6+AQ7+AQ8)*Percapita/30*FL$4+(AP6+AP7+AP8+AR6+AR7+AR8)*Cadeirante/30*FL$4,IF(C6=3,IF(AO9+AQ9=10,Fixo/30*FL$4+(AO6+AO7+AO8+AQ6+AQ7+AQ8)*Percapita/30*FL$4+(AP9+AR9)*Cadeirante/30*FL$4,IF(AO9+AQ9<=9,(AO9+AQ9)*Crechee/30*FL$4)+(AP9+AR9)*Cadeirante/30*FL$4+(AO6+AO7+AO8+AQ6+AQ7+AQ8)*Percapita/30*FL$4)+IF(AO9+AQ9>=11,Fixo/30*FL$4+(AO9+AQ9-10)*Crechee/30*FL$4,0),IF(C6=2,IF(AP6+AP7+AP8+AP9+AR6+AR7+AR8+AR9=1,Cadeirante/30*FL$4,IF(AP6+AP7+AP8+AP9+AR6+AR7+AR8+AR9=2,Fixo/30*FL$4,IF(AP6+AP7+AP8+AP9+AR6+AR7+AR8+AR9>2,Fixo/30*FL$4+(AP6+AP7+AP8+AP9+AR6+AR7+AR8+AR9-2)*Cadeirante/30*FL$4)))+(AO6+AO7+AO8+AQ6+AQ7+AQ8)*Percapita/30*FL$4+(AO9+AQ9)*Crechee/30*FL$4,IF(C6=1,IF(AO6+AO7+AO8+AP6+AP7+AP8+AQ6+AQ7+AQ8+AR6+AR7+AR8<=15,(AO6+AO7+AO8+AQ6+AQ7+AQ8)*Percapita/30*FL$4,IF(AO6+AO7+AO8+AP6+AP7+AP8+AQ6+AQ7+AQ8+AR6+AR7+AR8>=16,Fixo/30*FL$4+(AO6+AO7+AO8+AP6+AP7+AP8+AQ6+AQ7+AQ8+AR6+AR7-16)*Percapita/30*FL$4)))))) -> 0 | FM6: =IF(C6=4,SUM(AS6+AS7+AS8+AU6+AU7+AU8)*Percapita/30*FM$4+(AT6+AT7+AT8+AV6+AV7+AV8)*Cadeirante/30*FM$4,IF(C6=3,IF(AS9+AU9=10,Fixo/30*FM$4+(AS6+AS7+AS8+AU6+AU7+AU8)*Percapita/30*FM$4+(AT9+AV9)*Cadeirante/30*FM$4,IF(AS9+AU9<=9,(AS9+AU9)*Crechee/30*FM$4)+(AT9+AV9)*Cadeirante/30*FM$4+(AS6+AS7+AS8+AU6+AU7+AU8)*Percapita/30*FM$4)+IF(AS9+AU9>=11,Fixo/30*FM$4+(AS9+AU9-10)*Crechee/30*FM$4,0),IF(C6=2,IF(AT6+AT7+AT8+AT9+AV6+AV7+AV8+AV9=1,Cadeirante/30*FM$4,IF(AT6+AT7+AT8+AT9+AV6+AV7+AV8+AV9=2,Fixo/30*FM$4,IF(AT6+AT7+AT8+AT9+AV6+AV7+AV8+AV9>2,Fixo/30*FM$4+(AT6+AT7+AT8+AT9+AV6+AV7+AV8+AV9-2)*Cadeirante/30*FM$4)))+(AS6+AS7+AS8+AU6+AU7+AU8)*Percapita/30*FM$4+(AS9+AU9)*Crechee/30*FM$4,IF(C6=1,IF(AS6+AS7+AS8+AT6+AT7+AT8+AU6+AU7+AU8+AV6+AV7+AV8<=15,(AS6+AS7+AS8+AU6+AU7+AU8)*Percapita/30*FM$4,IF(AS6+AS7+AS8+AT6+AT7+AT8+AU6+AU7+AU8+AV6+AV7+AV8>=16,Fixo/30*FM$4+(AS6+AS7+AS8+AT6+AT7+AT8+AU6+AU7+AU8+AV6+AV7-16)*Percapita/30*FM$4)))))) -> 0 | FN6: =IF(C6=4,SUM(AW6+AW7+AW8+AY6+AY7+AY8)*Percapita/30*FN$4+(AX6+AX7+AX8+AZ6+AZ7+AZ8)*Cadeirante/30*FN$4,IF(C6=3,IF(AW9+AY9=10,Fixo/30*FN$4+(AW6+AW7+AW8+AY6+AY7+AY8)*Percapita/30*FN$4+(AX9+AZ9)*Cadeirante/30*FN$4,IF(AW9+AY9<=9,(AW9+AY9)*Crechee/30*FN$4)+(AX9+AZ9)*Cadeirante/30*FN$4+(AW6+AW7+AW8+AY6+AY7+AY8)*Percapita/30*FN$4)+IF(AW9+AY9>=11,Fixo/30*FN$4+(AW9+AY9-10)*Crechee/30*FN$4,0),IF(C6=2,IF(AX6+AX7+AX8+AX9+AZ6+AZ7+AZ8+AZ9=1,Cadeirante/30*FN$4,IF(AX6+AX7+AX8+AX9+AZ6+AZ7+AZ8+AZ9=2,Fixo/30*FN$4,IF(AX6+AX7+AX8+AX9+AZ6+AZ7+AZ8+AZ9>2,Fixo/30*FN$4+(AX6+AX7+AX8+AX9+AZ6+AZ7+AZ8+AZ9-2)*Cadeirante/30*FN$4)))+(AW6+AW7+AW8+AY6+AY7+AY8)*Percapita/30*FN$4+(AW9+AY9)*Crechee/30*FN$4,IF(C6=1,IF(AW6+AW7+AW8+AX6+AX7+AX8+AY6+AY7+AY8+AZ6+AZ7+AZ8<=15,(AW6+AW7+AW8+AY6+AY7+AY8)*Percapita/30*FN$4,IF(AW6+AW7+AW8+AX6+AX7+AX8+AY6+AY7+AY8+AZ6+AZ7+AZ8>=16,Fixo/30*FN$4+(AW6+AW7+AW8+AX6+AX7+AX8+AY6+AY7+AY8+AZ6+AZ7-16)*Percapita/30*FN$4)))))) -> 0 | FO6: =IF(C6=4,SUM(BA6+BA7+BA8+BC6+BC7+BC8)*Percapita/30*FO$4+(BB6+BB7+BB8+BD6+BD7+BD8)*Cadeirante/30*FO$4,IF(C6=3,IF(BA9+BC9=10,Fixo/30*FO$4+(BA6+BA7+BA8+BC6+BC7+BC8)*Percapita/30*FO$4+(BB9+BD9)*Cadeirante/30*FO$4,IF(BA9+BC9<=9,(BA9+BC9)*Crechee/30*FO$4)+(BB9+BD9)*Cadeirante/30*FO$4+(BA6+BA7+BA8+BC6+BC7+BC8)*Percapita/30*FO$4)+IF(BA9+BC9>=11,Fixo/30*FO$4+(BA9+BC9-10)*Crechee/30*FO$4,0),IF(C6=2,IF(BB6+BB7+BB8+BB9+BD6+BD7+BD8+BD9=1,Cadeirante/30*FO$4,IF(BB6+BB7+BB8+BB9+BD6+BD7+BD8+BD9=2,Fixo/30*FO$4,IF(BB6+BB7+BB8+BB9+BD6+BD7+BD8+BD9>2,Fixo/30*FO$4+(BB6+BB7+BB8+BB9+BD6+BD7+BD8+BD9-2)*Cadeirante/30*FO$4)))+(BA6+BA7+BA8+BC6+BC7+BC8)*Percapita/30*FO$4+(BA9+BC9)*Crechee/30*FO$4,IF(C6=1,IF(BA6+BA7+BA8+BB6+BB7+BB8+BC6+BC7+BC8+BD6+BD7+BD8<=15,(BA6+BA7+BA8+BC6+BC7+BC8)*Percapita/30*FO$4,IF(BA6+BA7+BA8+BB6+BB7+BB8+BC6+BC7+BC8+BD6+BD7+BD8>=16,Fixo/30*FO$4+(BA6+BA7+BA8+BB6+BB7+BB8+BC6+BC7+BC8+BD6+BD7-16)*Percapita/30*FO$4)))))) -> 0 | FP6: =IF(C6=4,SUM(BE6+BE7+BE8+BG6+BG7+BG8)*Percapita/30*FP$4+(BF6+BF7+BF8+BH6+BH7+BH8)*Cadeirante/30*FP$4,IF(C6=3,IF(BE9+BG9=10,Fixo/30*FP$4+(BE6+BE7+BE8+BG6+BG7+BG8)*Percapita/30*FP$4+(BF9+BH9)*Cadeirante/30*FP$4,IF(BE9+BG9<=9,(BE9+BG9)*Crechee/30*FP$4)+(BF9+BH9)*Cadeirante/30*FP$4+(BE6+BE7+BE8+BG6+BG7+BG8)*Percapita/30*FP$4)+IF(BE9+BG9>=11,Fixo/30*FP$4+(BE9+BG9-10)*Crechee/30*FP$4,0),IF(C6=2,IF(BF6+BF7+BF8+BF9+BH6+BH7+BH8+BH9=1,Cadeirante/30*FP$4,IF(BF6+BF7+BF8+BF9+BH6+BH7+BH8+BH9=2,Fixo/30*FP$4,IF(BF6+BF7+BF8+BF9+BH6+BH7+BH8+BH9>2,Fixo/30*FP$4+(BF6+BF7+BF8+BF9+BH6+BH7+BH8+BH9-2)*Cadeirante/30*FP$4)))+(BE6+BE7+BE8+BG6+BG7+BG8)*Percapita/30*FP$4+(BE9+BG9)*Crechee/30*FP$4,IF(C6=1,IF(BE6+BE7+BE8+BF6+BF7+BF8+BG6+BG7+BG8+BH6+BH7+BH8<=15,(BE6+BE7+BE8+BG6+BG7+BG8)*Percapita/30*FP$4,IF(BE6+BE7+BE8+BF6+BF7+BF8+BG6+BG7+BG8+BH6+BH7+BH8>=16,Fixo/30*FP$4+(BE6+BE7+BE8+BF6+BF7+BF8+BG6+BG7+BG8+BH6+BH7-16)*Percapita/30*FP$4)))))) -> 0 | FQ6: =IF(C6=4,SUM(BI6+BI7+BI8+BK6+BK7+BK8)*Percapita/30*FQ$4+(BJ6+BJ7+BJ8+BL6+BL7+BL8)*Cadeirante/30*FQ$4,IF(C6=3,IF(BI9+BK9=10,Fixo/30*FQ$4+(BI6+BI7+BI8+BK6+BK7+BK8)*Percapita/30*FQ$4+(BJ9+BL9)*Cadeirante/30*FQ$4,IF(BI9+BK9<=9,(BI9+BK9)*Crechee/30*FQ$4)+(BJ9+BL9)*Cadeirante/30*FQ$4+(BI6+BI7+BI8+BK6+BK7+BK8)*Percapita/30*FQ$4)+IF(BI9+BK9>=11,Fixo/30*FQ$4+(BI9+BK9-10)*Crechee/30*FQ$4,0),IF(C6=2,IF(BJ6+BJ7+BJ8+BJ9+BL6+BL7+BL8+BL9=1,Cadeirante/30*FQ$4,IF(BJ6+BJ7+BJ8+BJ9+BL6+BL7+BL8+BL9=2,Fixo/30*FQ$4,IF(BJ6+BJ7+BJ8+BJ9+BL6+BL7+BL8+BL9>2,Fixo/30*FQ$4+(BJ6+BJ7+BJ8+BJ9+BL6+BL7+BL8+BL9-2)*Cadeirante/30*FQ$4)))+(BI6+BI7+BI8+BK6+BK7+BK8)*Percapita/30*FQ$4+(BI9+BK9)*Crechee/30*FQ$4,IF(C6=1,IF(BI6+BI7+BI8+BJ6+BJ7+BJ8+BK6+BK7+BK8+BL6+BL7+BL8<=15,(BI6+BI7+BI8+BK6+BK7+BK8)*Percapita/30*FQ$4,IF(BI6+BI7+BI8+BJ6+BJ7+BJ8+BK6+BK7+BK8+BL6+BL7+BL8>=16,Fixo/30*FQ$4+(BI6+BI7+BI8+BJ6+BJ7+BJ8+BK6+BK7+BK8+BL6+BL7-16)*Percapita/30*FQ$4)))))) -> 0 | FR6: =IF(C6=4,SUM(BM6+BM7+BM8+BO6+BO7+BO8)*Percapita/30*FR$4+(BN6+BN7+BN8+BP6+BP7+BP8)*Cadeirante/30*FR$4,IF(C6=3,IF(BM9+BO9=10,Fixo/30*FR$4+(BM6+BM7+BM8+BO6+BO7+BO8)*Percapita/30*FR$4+(BN9+BP9)*Cadeirante/30*FR$4,IF(BM9+BO9<=9,(BM9+BO9)*Crechee/30*FR$4)+(BN9+BP9)*Cadeirante/30*FR$4+(BM6+BM7+BM8+BO6+BO7+BO8)*Percapita/30*FR$4)+IF(BM9+BO9>=11,Fixo/30*FR$4+(BM9+BO9-10)*Crechee/30*FR$4,0),IF(C6=2,IF(BN6+BN7+BN8+BN9+BP6+BP7+BP8+BP9=1,Cadeirante/30*FR$4,IF(BN6+BN7+BN8+BN9+BP6+BP7+BP8+BP9=2,Fixo/30*FR$4,IF(BN6+BN7+BN8+BN9+BP6+BP7+BP8+BP9>2,Fixo/30*FR$4+(BN6+BN7+BN8+BN9+BP6+BP7+BP8+BP9-2)*Cadeirante/30*FR$4)))+(BM6+BM7+BM8+BO6+BO7+BO8)*Percapita/30*FR$4+(BM9+BO9)*Crechee/30*FR$4,IF(C6=1,IF(BM6+BM7+BM8+BN6+BN7+BN8+BO6+BO7+BO8+BP6+BP7+BP8<=15,(BM6+BM7+BM8+BO6+BO7+BO8)*Percapita/30*FR$4,IF(BM6+BM7+BM8+BN6+BN7+BN8+BO6+BO7+BO8+BP6+BP7+BP8>=16,Fixo/30*FR$4+(BM6+BM7+BM8+BN6+BN7+BN8+BO6+BO7+BO8+BP6+BP7-16)*Percapita/30*FR$4)))))) -> 0 | FS6: =IF(C6=4,SUM(BQ6+BQ7+BQ8+BS6+BS7+BS8)*Percapita/30*FS$4+(BR6+BR7+BR8+BT6+BT7+BT8)*Cadeirante/30*FS$4,IF(C6=3,IF(BQ9+BS9=10,Fixo/30*FS$4+(BQ6+BQ7+BQ8+BS6+BS7+BS8)*Percapita/30*FS$4+(BR9+BT9)*Cadeirante/30*FS$4,IF(BQ9+BS9<=9,(BQ9+BS9)*Crechee/30*FS$4)+(BR9+BT9)*Cadeirante/30*FS$4+(BQ6+BQ7+BQ8+BS6+BS7+BS8)*Percapita/30*FS$4)+IF(BQ9+BS9>=11,Fixo/30*FS$4+(BQ9+BS9-10)*Crechee/30*FS$4,0),IF(C6=2,IF(BR6+BR7+BR8+BR9+BT6+BT7+BT8+BT9=1,Cadeirante/30*FS$4,IF(BR6+BR7+BR8+BR9+BT6+BT7+BT8+BT9=2,Fixo/30*FS$4,IF(BR6+BR7+BR8+BR9+BT6+BT7+BT8+BT9>2,Fixo/30*FS$4+(BR6+BR7+BR8+BR9+BT6+BT7+BT8+BT9-2)*Cadeirante/30*FS$4)))+(BQ6+BQ7+BQ8+BS6+BS7+BS8)*Percapita/30*FS$4+(BQ9+BS9)*Crechee/30*FS$4,IF(C6=1,IF(BQ6+BQ7+BQ8+BR6+BR7+BR8+BS6+BS7+BS8+BT6+BT7+BT8<=15,(BQ6+BQ7+BQ8+BS6+BS7+BS8)*Percapita/30*FS$4,IF(BQ6+BQ7+BQ8+BR6+BR7+BR8+BS6+BS7+BS8+BT6+BT7+BT8>=16,Fixo/30*FS$4+(BQ6+BQ7+BQ8+BR6+BR7+BR8+BS6+BS7+BS8+BT6+BT7-16)*Percapita/30*FS$4)))))) -> 0 | FT6: =IF(C6=4,SUM(BU6+BU7+BU8+BW6+BW7+BW8)*Percapita/30*FT$4+(BV6+BV7+BV8+BX6+BX7+BX8)*Cadeirante/30*FT$4,IF(C6=3,IF(BU9+BW9=10,Fixo/30*FT$4+(BU6+BU7+BU8+BW6+BW7+BW8)*Percapita/30*FT$4+(BV9+BX9)*Cadeirante/30*FT$4,IF(BU9+BW9<=9,(BU9+BW9)*Crechee/30*FT$4)+(BV9+BX9)*Cadeirante/30*FT$4+(BU6+BU7+BU8+BW6+BW7+BW8)*Percapita/30*FT$4)+IF(BU9+BW9>=11,Fixo/30*FT$4+(BU9+BW9-10)*Crechee/30*FT$4,0),IF(C6=2,IF(BV6+BV7+BV8+BV9+BX6+BX7+BX8+BX9=1,Cadeirante/30*FT$4,IF(BV6+BV7+BV8+BV9+BX6+BX7+BX8+BX9=2,Fixo/30*FT$4,IF(BV6+BV7+BV8+BV9+BX6+BX7+BX8+BX9>2,Fixo/30*FT$4+(BV6+BV7+BV8+BV9+BX6+BX7+BX8+BX9-2)*Cadeirante/30*FT$4)))+(BU6+BU7+BU8+BW6+BW7+BW8)*Percapita/30*FT$4+(BU9+BW9)*Crechee/30*FT$4,IF(C6=1,IF(BU6+BU7+BU8+BV6+BV7+BV8+BW6+BW7+BW8+BX6+BX7+BX8<=15,(BU6+BU7+BU8+BW6+BW7+BW8)*Percapita/30*FT$4,IF(BU6+BU7+BU8+BV6+BV7+BV8+BW6+BW7+BW8+BX6+BX7+BX8>=16,Fixo/30*FT$4+(BU6+BU7+BU8+BV6+BV7+BV8+BW6+BW7+BW8+BX6+BX7-16)*Percapita/30*FT$4)))))) -> 0 | FU6: =IF(C6=4,SUM(BY6+BY7+BY8+CA6+CA7+CA8)*Percapita/30*FU$4+(BZ6+BZ7+BZ8+CB6+CB7+CB8)*Cadeirante/30*FU$4,IF(C6=3,IF(BY9+CA9=10,Fixo/30*FU$4+(BY6+BY7+BY8+CA6+CA7+CA8)*Percapita/30*FU$4+(BZ9+CB9)*Cadeirante/30*FU$4,IF(BY9+CA9<=9,(BY9+CA9)*Crechee/30*FU$4)+(BZ9+CB9)*Cadeirante/30*FU$4+(BY6+BY7+BY8+CA6+CA7+CA8)*Percapita/30*FU$4)+IF(BY9+CA9>=11,Fixo/30*FU$4+(BY9+CA9-10)*Crechee/30*FU$4,0),IF(C6=2,IF(BZ6+BZ7+BZ8+BZ9+CB6+CB7+CB8+CB9=1,Cadeirante/30*FU$4,IF(BZ6+BZ7+BZ8+BZ9+CB6+CB7+CB8+CB9=2,Fixo/30*FU$4,IF(BZ6+BZ7+BZ8+BZ9+CB6+CB7+CB8+CB9>2,Fixo/30*FU$4+(BZ6+BZ7+BZ8+BZ9+CB6+CB7+CB8+CB9-2)*Cadeirante/30*FU$4)))+(BY6+BY7+BY8+CA6+CA7+CA8)*Percapita/30*FU$4+(BY9+CA9)*Crechee/30*FU$4,IF(C6=1,IF(BY6+BY7+BY8+BZ6+BZ7+BZ8+CA6+CA7+CA8+CB6+CB7+CB8<=15,(BY6+BY7+BY8+CA6+CA7+CA8)*Percapita/30*FU$4,IF(BY6+BY7+BY8+BZ6+BZ7+BZ8+CA6+CA7+CA8+CB6+CB7+CB8>=16,Fixo/30*FU$4+(BY6+BY7+BY8+BZ6+BZ7+BZ8+CA6+CA7+CA8+CB6+CB7-16)*Percapita/30*FU$4)))))) -> 0 | FV6: =IF(C6=4,SUM(CC6+CC7+CC8+CE6+CE7+CE8)*Percapita/30*FV$4+(CD6+CD7+CD8+CF6+CF7+CF8)*Cadeirante/30*FV$4,IF(C6=3,IF(CC9+CE9=10,Fixo/30*FV$4+(CC6+CC7+CC8+CE6+CE7+CE8)*Percapita/30*FV$4+(CD9+CF9)*Cadeirante/30*FV$4,IF(CC9+CE9<=9,(CC9+CE9)*Crechee/30*FV$4)+(CD9+CF9)*Cadeirante/30*FV$4+(CC6+CC7+CC8+CE6+CE7+CE8)*Percapita/30*FV$4)+IF(CC9+CE9>=11,Fixo/30*FV$4+(CC9+CE9-10)*Crechee/30*FV$4,0),IF(C6=2,IF(CD6+CD7+CD8+CD9+CF6+CF7+CF8+CF9=1,Cadeirante/30*FV$4,IF(CD6+CD7+CD8+CD9+CF6+CF7+CF8+CF9=2,Fixo/30*FV$4,IF(CD6+CD7+CD8+CD9+CF6+CF7+CF8+CF9>2,Fixo/30*FV$4+(CD6+CD7+CD8+CD9+CF6+CF7+CF8+CF9-2)*Cadeirante/30*FV$4)))+(CC6+CC7+CC8+CE6+CE7+CE8)*Percapita/30*FV$4+(CC9+CE9)*Crechee/30*FV$4,IF(C6=1,IF(CC6+CC7+CC8+CD6+CD7+CD8+CE6+CE7+CE8+CF6+CF7+CF8<=15,(CC6+CC7+CC8+CE6+CE7+CE8)*Percapita/30*FV$4,IF(CC6+CC7+CC8+CD6+CD7+CD8+CE6+CE7+CE8+CF6+CF7+CF8>=16,Fixo/30*FV$4+(CC6+CC7+CC8+CD6+CD7+CD8+CE6+CE7+CE8+CF6+CF7-16)*Percapita/30*FV$4)))))) -> 179.774 | FW6: =IF(C6=4,SUM(CG6+CG7+CG8+CI6+CI7+CI8)*Percapita/30*FW$4+(CH6+CH7+CH8+CJ6+CJ7+CJ8)*Cadeirante/30*FW$4,IF(C6=3,IF(CG9+CI9=10,Fixo/30*FW$4+(CG6+CG7+CG8+CI6+CI7+CI8)*Percapita/30*FW$4+(CH9+CJ9)*Cadeirante/30*FW$4,IF(CG9+CI9<=9,(CG9+CI9)*Crechee/30*FW$4)+(CH9+CJ9)*Cadeirante/30*FW$4+(CG6+CG7+CG8+CI6+CI7+CI8)*Percapita/30*FW$4)+IF(CG9+CI9>=11,Fixo/30*FW$4+(CG9+CI9-10)*Crechee/30*FW$4,0),IF(C6=2,IF(CH6+CH7+CH8+CH9+CJ6+CJ7+CJ8+CJ9=1,Cadeirante/30*FW$4,IF(CH6+CH7+CH8+CH9+CJ6+CJ7+CJ8+CJ9=2,Fixo/30*FW$4,IF(CH6+CH7+CH8+CH9+CJ6+CJ7+CJ8+CJ9>2,Fixo/30*FW$4+(CH6+CH7+CH8+CH9+CJ6+CJ7+CJ8+CJ9-2)*Cadeirante/30*FW$4)))+(CG6+CG7+CG8+CI6+CI7+CI8)*Percapita/30*FW$4+(CG9+CI9)*Crechee/30*FW$4,IF(C6=1,IF(CG6+CG7+CG8+CH6+CH7+CH8+CI6+CI7+CI8+CJ6+CJ7+CJ8<=15,(CG6+CG7+CG8+CI6+CI7+CI8)*Percapita/30*FW$4,IF(CG6+CG7+CG8+CH6+CH7+CH8+CI6+CI7+CI8+CJ6+CJ7+CJ8>=16,Fixo/30*FW$4+(CG6+CG7+CG8+CH6+CH7+CH8+CI6+CI7+CI8+CJ6+CJ7-16)*Percapita/30*FW$4)))))) -> 0 | FX6: =IF(C6=4,SUM(CK6+CK7+CK8+CM6+CM7+CM8)*Percapita/30*FX$4+(CL6+CL7+CL8+CN6+CN7+CN8)*Cadeirante/30*FX$4,IF(C6=3,IF(CK9+CM9=10,Fixo/30*FX$4+(CK6+CK7+CK8+CM6+CM7+CM8)*Percapita/30*FX$4+(CL9+CN9)*Cadeirante/30*FX$4,IF(CK9+CM9<=9,(CK9+CM9)*Crechee/30*FX$4)+(CL9+CN9)*Cadeirante/30*FX$4+(CK6+CK7+CK8+CM6+CM7+CM8)*Percapita/30*FX$4)+IF(CK9+CM9>=11,Fixo/30*FX$4+(CK9+CM9-10)*Crechee/30*FX$4,0),IF(C6=2,IF(CL6+CL7+CL8+CL9+CN6+CN7+CN8+CN9=1,Cadeirante/30*FX$4,IF(CL6+CL7+CL8+CL9+CN6+CN7+CN8+CN9=2,Fixo/30*FX$4,IF(CL6+CL7+CL8+CL9+CN6+CN7+CN8+CN9>2,Fixo/30*FX$4+(CL6+CL7+CL8+CL9+CN6+CN7+CN8+CN9-2)*Cadeirante/30*FX$4)))+(CK6+CK7+CK8+CM6+CM7+CM8)*Percapita/30*FX$4+(CK9+CM9)*Crechee/30*FX$4,IF(C6=1,IF(CK6+CK7+CK8+CL6+CL7+CL8+CM6+CM7+CM8+CN6+CN7+CN8<=15,(CK6+CK7+CK8+CM6+CM7+CM8)*Percapita/30*FX$4,IF(CK6+CK7+CK8+CL6+CL7+CL8+CM6+CM7+CM8+CN6+CN7+CN8>=16,Fixo/30*FX$4+(CK6+CK7+CK8+CL6+CL7+CL8+CM6+CM7+CM8+CN6+CN7-16)*Percapita/30*FX$4)))))) -> 0 | FY6: =IF(C6=4,SUM(CO6+CO7+CO8+CQ6+CQ7+CQ8)*Percapita/30*FY$4+(CP6+CP7+CP8+CR6+CR7+CR8)*Cadeirante/30*FY$4,IF(C6=3,IF(CO9+CQ9=10,Fixo/30*FY$4+(CO6+CO7+CO8+CQ6+CQ7+CQ8)*Percapita/30*FY$4+(CP9+CR9)*Cadeirante/30*FY$4,IF(CO9+CQ9<=9,(CO9+CQ9)*Crechee/30*FY$4)+(CP9+CR9)*Cadeirante/30*FY$4+(CO6+CO7+CO8+CQ6+CQ7+CQ8)*Percapita/30*FY$4)+IF(CO9+CQ9>=11,Fixo/30*FY$4+(CO9+CQ9-10)*Crechee/30*FY$4,0),IF(C6=2,IF(CP6+CP7+CP8+CP9+CR6+CR7+CR8+CR9=1,Cadeirante/30*FY$4,IF(CP6+CP7+CP8+CP9+CR6+CR7+CR8+CR9=2,Fixo/30*FY$4,IF(CP6+CP7+CP8+CP9+CR6+CR7+CR8+CR9>2,Fixo/30*FY$4+(CP6+CP7+CP8+CP9+CR6+CR7+CR8+CR9-2)*Cadeirante/30*FY$4)))+(CO6+CO7+CO8+CQ6+CQ7+CQ8)*Percapita/30*FY$4+(CO9+CQ9)*Crechee/30*FY$4,IF(C6=1,IF(CO6+CO7+CO8+CP6+CP7+CP8+CQ6+CQ7+CQ8+CR6+CR7+CR8<=15,(CO6+CO7+CO8+CQ6+CQ7+CQ8)*Percapita/30*FY$4,IF(CO6+CO7+CO8+CP6+CP7+CP8+CQ6+CQ7+CQ8+CR6+CR7+CR8>=16,Fixo/30*FY$4+(CO6+CO7+CO8+CP6+CP7+CP8+CQ6+CQ7+CQ8+CR6+CR7-16)*Percapita/30*FY$4)))))) -> 0 | FZ6: =IF(C6=4,SUM(CS6+CS7+CS8+CU6+CU7+CU8)*Percapita/30*FZ$4+(CT6+CT7+CT8+CV6+CV7+CV8)*Cadeirante/30*FZ$4,IF(C6=3,IF(CS9+CU9=10,Fixo/30*FZ$4+(CS6+CS7+CS8+CU6+CU7+CU8)*Percapita/30*FZ$4+(CT9+CV9)*Cadeirante/30*FZ$4,IF(CS9+CU9<=9,(CS9+CU9)*Crechee/30*FZ$4)+(CT9+CV9)*Cadeirante/30*FZ$4+(CS6+CS7+CS8+CU6+CU7+CU8)*Percapita/30*FZ$4)+IF(CS9+CU9>=11,Fixo/30*FZ$4+(CS9+CU9-10)*Crechee/30*FZ$4,0),IF(C6=2,IF(CT6+CT7+CT8+CT9+CV6+CV7+CV8+CV9=1,Cadeirante/30*FZ$4,IF(CT6+CT7+CT8+CT9+CV6+CV7+CV8+CV9=2,Fixo/30*FZ$4,IF(CT6+CT7+CT8+CT9+CV6+CV7+CV8+CV9>2,Fixo/30*FZ$4+(CT6+CT7+CT8+CT9+CV6+CV7+CV8+CV9-2)*Cadeirante/30*FZ$4)))+(CS6+CS7+CS8+CU6+CU7+CU8)*Percapita/30*FZ$4+(CS9+CU9)*Crechee/30*FZ$4,IF(C6=1,IF(CS6+CS7+CS8+CT6+CT7+CT8+CU6+CU7+CU8+CV6+CV7+CV8<=15,(CS6+CS7+CS8+CU6+CU7+CU8)*Percapita/30*FZ$4,IF(CS6+CS7+CS8+CT6+CT7+CT8+CU6+CU7+CU8+CV6+CV7+CV8>=16,Fixo/30*FZ$4+(CS6+CS7+CS8+CT6+CT7+CT8+CU6+CU7+CU8+CV6+CV7-16)*Percapita/30*FZ$4)))))) -> 0 | GA6: =IF(C6=4,SUM(CW6+CW7+CW8+CY6+CY7+CY8)*Percapita/30*GA$4+(CX6+CX7+CX8+CZ6+CZ7+CZ8)*Cadeirante/30*GA$4,IF(C6=3,IF(CW9+CY9=10,Fixo/30*GA$4+(CW6+CW7+CW8+CY6+CY7+CY8)*Percapita/30*GA$4+(CX9+CZ9)*Cadeirante/30*GA$4,IF(CW9+CY9<=9,(CW9+CY9)*Crechee/30*GA$4)+(CX9+CZ9)*Cadeirante/30*GA$4+(CW6+CW7+CW8+CY6+CY7+CY8)*Percapita/30*GA$4)+IF(CW9+CY9>=11,Fixo/30*GA$4+(CW9+CY9-10)*Crechee/30*GA$4,0),IF(C6=2,IF(CX6+CX7+CX8+CX9+CZ6+CZ7+CZ8+CZ9=1,Cadeirante/30*GA$4,IF(CX6+CX7+CX8+CX9+CZ6+CZ7+CZ8+CZ9=2,Fixo/30*GA$4,IF(CX6+CX7+CX8+CX9+CZ6+CZ7+CZ8+CZ9>2,Fixo/30*GA$4+(CX6+CX7+CX8+CX9+CZ6+CZ7+CZ8+CZ9-2)*Cadeirante/30*GA$4)))+(CW6+CW7+CW8+CY6+CY7+CY8)*Percapita/30*GA$4+(CW9+CY9)*Crechee/30*GA$4,IF(C6=1,IF(CW6+CW7+CW8+CX6+CX7+CX8+CY6+CY7+CY8+CZ6+CZ7+CZ8<=15,(CW6+CW7+CW8+CY6+CY7+CY8)*Percapita/30*GA$4,IF(CW6+CW7+CW8+CX6+CX7+CX8+CY6+CY7+CY8+CZ6+CZ7+CZ8>=16,Fixo/30*GA$4+(CW6+CW7+CW8+CX6+CX7+CX8+CY6+CY7+CY8+CZ6+CZ7-16)*Percapita/30*GA$4)))))) -> 115.569 | GB6: =IF(C6=4,SUM(DA6+DA7+DA8+DC6+DC7+DC8)*Percapita/30*GB$4+(DB6+DB7+DB8+DD6+DD7+DD8)*Cadeirante/30*GB$4,IF(C6=3,IF(DA9+DC9=10,Fixo/30*GB$4+(DA6+DA7+DA8+DC6+DC7+DC8)*Percapita/30*GB$4+(DB9+DD9)*Cadeirante/30*GB$4,IF(DA9+DC9<=9,(DA9+DC9)*Crechee/30*GB$4)+(DB9+DD9)*Cadeirante/30*GB$4+(DA6+DA7+DA8+DC6+DC7+DC8)*Percapita/30*GB$4)+IF(DA9+DC9>=11,Fixo/30*GB$4+(DA9+DC9-10)*Crechee/30*GB$4,0),IF(C6=2,IF(DB6+DB7+DB8+DB9+DD6+DD7+DD8+DD9=1,Cadeirante/30*GB$4,IF(DB6+DB7+DB8+DB9+DD6+DD7+DD8+DD9=2,Fixo/30*GB$4,IF(DB6+DB7+DB8+DB9+DD6+DD7+DD8+DD9>2,Fixo/30*GB$4+(DB6+DB7+DB8+DB9+DD6+DD7+DD8+DD9-2)*Cadeirante/30*GB$4)))+(DA6+DA7+DA8+DC6+DC7+DC8)*Percapita/30*GB$4+(DA9+DC9)*Crechee/30*GB$4,IF(C6=1,IF(DA6+DA7+DA8+DB6+DB7+DB8+DC6+DC7+DC8+DD6+DD7+DD8<=15,(DA6+DA7+DA8+DC6+DC7+DC8)*Percapita/30*GB$4,IF(DA6+DA7+DA8+DB6+DB7+DB8+DC6+DC7+DC8+DD6+DD7+DD8>=16,Fixo/30*GB$4+(DA6+DA7+DA8+DB6+DB7+DB8+DC6+DC7+DC8+DD6+DD7-16)*Percapita/30*GB$4)))))) -> 0 | GC6: =IF(C6=4,SUM(DE6+DE7+DE8+DG6+DG7+DG8)*Percapita/30*GC$4+(DF6+DF7+DF8+DH6+DH7+DH8)*Cadeirante/30*GC$4,IF(C6=3,IF(DE9+DG9=10,Fixo/30*GC$4+(DE6+DE7+DE8+DG6+DG7+DG8)*Percapita/30*GC$4+(DF9+DH9)*Cadeirante/30*GC$4,IF(DE9+DG9<=9,(DE9+DG9)*Crechee/30*GC$4)+(DF9+DH9)*Cadeirante/30*GC$4+(DE6+DE7+DE8+DG6+DG7+DG8)*Percapita/30*GC$4)+IF(DE9+DG9>=11,Fixo/30*GC$4+(DE9+DG9-10)*Crechee/30*GC$4,0),IF(C6=2,IF(DF6+DF7+DF8+DF9+DH6+DH7+DH8+DH9=1,Cadeirante/30*GC$4,IF(DF6+DF7+DF8+DF9+DH6+DH7+DH8+DH9=2,Fixo/30*GC$4,IF(DF6+DF7+DF8+DF9+DH6+DH7+DH8+DH9>2,Fixo/30*GC$4+(DF6+DF7+DF8+DF9+DH6+DH7+DH8+DH9-2)*Cadeirante/30*GC$4)))+(DE6+DE7+DE8+DG6+DG7+DG8)*Percapita/30*GC$4+(DE9+DG9)*Crechee/30*GC$4,IF(C6=1,IF(DE6+DE7+DE8+DF6+DF7+DF8+DG6+DG7+DG8+DH6+DH7+DH8<=15,(DE6+DE7+DE8+DG6+DG7+DG8)*Percapita/30*GC$4,IF(DE6+DE7+DE8+DF6+DF7+DF8+DG6+DG7+DG8+DH6+DH7+DH8>=16,Fixo/30*GC$4+(DE6+DE7+DE8+DF6+DF7+DF8+DG6+DG7+DG8+DH6+DH7-16)*Percapita/30*GC$4)))))) -> 0 | GD6: =IF(C6=4,SUM(DI6+DI7+DI8+DK6+DK7+DK8)*Percapita/30*GD$4+(DJ6+DJ7+DJ8+DL6+DL7+DL8)*Cadeirante/30*GD$4,IF(C6=3,IF(DI9+DK9=10,Fixo/30*GD$4+(DI6+DI7+DI8+DK6+DK7+DK8)*Percapita/30*GD$4+(DJ9+DL9)*Cadeirante/30*GD$4,IF(DI9+DK9<=9,(DI9+DK9)*Crechee/30*GD$4)+(DJ9+DL9)*Cadeirante/30*GD$4+(DI6+DI7+DI8+DK6+DK7+DK8)*Percapita/30*GD$4)+IF(DI9+DK9>=11,Fixo/30*GD$4+(DI9+DK9-10)*Crechee/30*GD$4,0),IF(C6=2,IF(DJ6+DJ7+DJ8+DJ9+DL6+DL7+DL8+DL9=1,Cadeirante/30*GD$4,IF(DJ6+DJ7+DJ8+DJ9+DL6+DL7+DL8+DL9=2,Fixo/30*GD$4,IF(DJ6+DJ7+DJ8+DJ9+DL6+DL7+DL8+DL9>2,Fixo/30*GD$4+(DJ6+DJ7+DJ8+DJ9+DL6+DL7+DL8+DL9-2)*Cadeirante/30*GD$4)))+(DI6+DI7+DI8+DK6+DK7+DK8)*Percapita/30*GD$4+(DI9+DK9)*Crechee/30*GD$4,IF(C6=1,IF(DI6+DI7+DI8+DJ6+DJ7+DJ8+DK6+DK7+DK8+DL6+DL7+DL8<=15,(DI6+DI7+DI8+DK6+DK7+DK8)*Percapita/30*GD$4,IF(DI6+DI7+DI8+DJ6+DJ7+DJ8+DK6+DK7+DK8+DL6+DL7+DL8>=16,Fixo/30*GD$4+(DI6+DI7+DI8+DJ6+DJ7+DJ8+DK6+DK7+DK8+DL6+DL7-16)*Percapita/30*GD$4)))))) -> 0 | GE6: =IF(C6=4,SUM(DM6+DM7+DM8+DO6+DO7+DO8)*Percapita/30*GE$4+(DN6+DN7+DN8+DP6+DP7+DP8)*Cadeirante/30*GE$4,IF(C6=3,IF(DM9+DO9=10,Fixo/30*GE$4+(DM6+DM7+DM8+DO6+DO7+DO8)*Percapita/30*GE$4+(DN9+DP9)*Cadeirante/30*GE$4,IF(DM9+DO9<=9,(DM9+DO9)*Crechee/30*GE$4)+(DN9+DP9)*Cadeirante/30*GE$4+(DM6+DM7+DM8+DO6+DO7+DO8)*Percapita/30*GE$4)+IF(DM9+DO9>=11,Fixo/30*GE$4+(DM9+DO9-10)*Crechee/30*GE$4,0),IF(C6=2,IF(DN6+DN7+DN8+DN9+DP6+DP7+DP8+DP9=1,Cadeirante/30*GE$4,IF(DN6+DN7+DN8+DN9+DP6+DP7+DP8+DP9=2,Fixo/30*GE$4,IF(DN6+DN7+DN8+DN9+DP6+DP7+DP8+DP9>2,Fixo/30*GE$4+(DN6+DN7+DN8+DN9+DP6+DP7+DP8+DP9-2)*Cadeirante/30*GE$4)))+(DM6+DM7+DM8+DO6+DO7+DO8)*Percapita/30*GE$4+(DM9+DO9)*Crechee/30*GE$4,IF(C6=1,IF(DM6+DM7+DM8+DN6+DN7+DN8+DO6+DO7+DO8+DP6+DP7+DP8<=15,(DM6+DM7+DM8+DO6+DO7+DO8)*Percapita/30*GE$4,IF(DM6+DM7+DM8+DN6+DN7+DN8+DO6+DO7+DO8+DP6+DP7+DP8>=16,Fixo/30*GE$4+(DM6+DM7+DM8+DN6+DN7+DN8+DO6+DO7+DO8+DP6+DP7-16)*Percapita/30*GE$4)))))) -> 0 | GF6: =IF(C6=4,SUM(DQ6+DQ7+DQ8+DS6+DS7+DS8)*Percapita/30*GF$4+(DR6+DR7+DR8+DT6+DT7+DT8)*Cadeirante/30*GF$4,IF(C6=3,IF(DQ9+DS9=10,Fixo/30*GF$4+(DQ6+DQ7+DQ8+DS6+DS7+DS8)*Percapita/30*GF$4+(DR9+DT9)*Cadeirante/30*GF$4,IF(DQ9+DS9<=9,(DQ9+DS9)*Crechee/30*GF$4)+(DR9+DT9)*Cadeirante/30*GF$4+(DQ6+DQ7+DQ8+DS6+DS7+DS8)*Percapita/30*GF$4)+IF(DQ9+DS9>=11,Fixo/30*GF$4+(DQ9+DS9-10)*Crechee/30*GF$4,0),IF(C6=2,IF(DR6+DR7+DR8+DR9+DT6+DT7+DT8+DT9=1,Cadeirante/30*GF$4,IF(DR6+DR7+DR8+DR9+DT6+DT7+DT8+DT9=2,Fixo/30*GF$4,IF(DR6+DR7+DR8+DR9+DT6+DT7+DT8+DT9>2,Fixo/30*GF$4+(DR6+DR7+DR8+DR9+DT6+DT7+DT8+DT9-2)*Cadeirante/30*GF$4)))+(DQ6+DQ7+DQ8+DS6+DS7+DS8)*Percapita/30*GF$4+(DQ9+DS9)*Crechee/30*GF$4,IF(C6=1,IF(DQ6+DQ7+DQ8+DR6+DR7+DR8+DS6+DS7+DS8+DT6+DT7+DT8<=15,(DQ6+DQ7+DQ8+DS6+DS7+DS8)*Percapita/30*GF$4,IF(DQ6+DQ7+DQ8+DR6+DR7+DR8+DS6+DS7+DS8+DT6+DT7+DT8>=16,Fixo/30*GF$4+(DQ6+DQ7+DQ8+DR6+DR7+DR8+DS6+DS7+DS8+DT6+DT7-16)*Percapita/30*GF$4)))))) -> 0 | GG6: =IF(C6=4,SUM(DU6+DU7+DU8+DW6+DW7+DW8)*Percapita/30*GG$4+(DV6+DV7+DV8+DX6+DX7+DX8)*Cadeirante/30*GG$4,IF(C6=3,IF(DU9+DW9=10,Fixo/30*GG$4+(DU6+DU7+DU8+DW6+DW7+DW8)*Percapita/30*GG$4+(DV9+DX9)*Cadeirante/30*GG$4,IF(DU9+DW9<=9,(DU9+DW9)*Crechee/30*GG$4)+(DV9+DX9)*Cadeirante/30*GG$4+(DU6+DU7+DU8+DW6+DW7+DW8)*Percapita/30*GG$4)+IF(DU9+DW9>=11,Fixo/30*GG$4+(DU9+DW9-10)*Crechee/30*GG$4,0),IF(C6=2,IF(DV6+DV7+DV8+DV9+DX6+DX7+DX8+DX9=1,Cadeirante/30*GG$4,IF(DV6+DV7+DV8+DV9+DX6+DX7+DX8+DX9=2,Fixo/30*GG$4,IF(DV6+DV7+DV8+DV9+DX6+DX7+DX8+DX9>2,Fixo/30*GG$4+(DV6+DV7+DV8+DV9+DX6+DX7+DX8+DX9-2)*Cadeirante/30*GG$4)))+(DU6+DU7+DU8+DW6+DW7+DW8)*Percapita/30*GG$4+(DU9+DW9)*Crechee/30*GG$4,IF(C6=1,IF(DU6+DU7+DU8+DV6+DV7+DV8+DW6+DW7+DW8+DX6+DX7+DX8<=15,(DU6+DU7+DU8+DW6+DW7+DW8)*Percapita/30*GG$4,IF(DU6+DU7+DU8+DV6+DV7+DV8+DW6+DW7+DW8+DX6+DX7+DX8>=16,Fixo/30*GG$4+(DU6+DU7+DU8+DV6+DV7+DV8+DW6+DW7+DW8+DX6+DX7-16)*Percapita/30*GG$4)))))) -> 0 | GH6: =IF(C6=4,SUM(DY6+DY7+DY8+EA6+EA7+EA8)*Percapita/30*GH$4+(DZ6+DZ7+DZ8+EB6+EB7+EB8)*Cadeirante/30*GH$4,IF(C6=3,IF(DY9+EA9=10,Fixo/30*GH$4+(DY6+DY7+DY8+EA6+EA7+EA8)*Percapita/30*GH$4+(DZ9+EB9)*Cadeirante/30*GH$4,IF(DY9+EA9<=9,(DY9+EA9)*Crechee/30*GH$4)+(DZ9+EB9)*Cadeirante/30*GH$4+(DY6+DY7+DY8+EA6+EA7+EA8)*Percapita/30*GH$4)+IF(DY9+EA9>=11,Fixo/30*GH$4+(DY9+EA9-10)*Crechee/30*GH$4,0),IF(C6=2,IF(DZ6+DZ7+DZ8+DZ9+EB6+EB7+EB8+EB9=1,Cadeirante/30*GH$4,IF(DZ6+DZ7+DZ8+DZ9+EB6+EB7+EB8+EB9=2,Fixo/30*GH$4,IF(DZ6+DZ7+DZ8+DZ9+EB6+EB7+EB8+EB9>2,Fixo/30*GH$4+(DZ6+DZ7+DZ8+DZ9+EB6+EB7+EB8+EB9-2)*Cadeirante/30*GH$4)))+(DY6+DY7+DY8+EA6+EA7+EA8)*Percapita/30*GH$4+(DY9+EA9)*Crechee/30*GH$4,IF(C6=1,IF(DY6+DY7+DY8+DZ6+DZ7+DZ8+EA6+EA7+EA8+EB6+EB7+EB8<=15,(DY6+DY7+DY8+EA6+EA7+EA8)*Percapita/30*GH$4,IF(DY6+DY7+DY8+DZ6+DZ7+DZ8+EA6+EA7+EA8+EB6+EB7+EB8>=16,Fixo/30*GH$4+(DY6+DY7+DY8+DZ6+DZ7+DZ8+EA6+EA7+EA8+EB6+EB7-16)*Percapita/30*GH$4)))))) -> 0 | GI6: =IF(C6=4,SUM(EC6+EC7+EC8+EE6+EE7+EE8)*Percapita/30*GI$4+(ED6+ED7+ED8+EF6+EF7+EF8)*Cadeirante/30*GI$4,IF(C6=3,IF(EC9+EE9=10,Fixo/30*GI$4+(EC6+EC7+EC8+EE6+EE7+EE8)*Percapita/30*GI$4+(ED9+EF9)*Cadeirante/30*GI$4,IF(EC9+EE9<=9,(EC9+EE9)*Crechee/30*GI$4)+(ED9+EF9)*Cadeirante/30*GI$4+(EC6+EC7+EC8+EE6+EE7+EE8)*Percapita/30*GI$4)+IF(EC9+EE9>=11,Fixo/30*GI$4+(EC9+EE9-10)*Crechee/30*GI$4,0),IF(C6=2,IF(ED6+ED7+ED8+ED9+EF6+EF7+EF8+EF9=1,Cadeirante/30*GI$4,IF(ED6+ED7+ED8+ED9+EF6+EF7+EF8+EF9=2,Fixo/30*GI$4,IF(ED6+ED7+ED8+ED9+EF6+EF7+EF8+EF9>2,Fixo/30*GI$4+(ED6+ED7+ED8+ED9+EF6+EF7+EF8+EF9-2)*Cadeirante/30*GI$4)))+(EC6+EC7+EC8+EE6+EE7+EE8)*Percapita/30*GI$4+(EC9+EE9)*Crechee/30*GI$4,IF(C6=1,IF(EC6+EC7+EC8+ED6+ED7+ED8+EE6+EE7+EE8+EF6+EF7+EF8<=15,(EC6+EC7+EC8+EE6+EE7+EE8)*Percapita/30*GI$4,IF(EC6+EC7+EC8+ED6+ED7+ED8+EE6+EE7+EE8+EF6+EF7+EF8>=16,Fixo/30*GI$4+(EC6+EC7+EC8+ED6+ED7+ED8+EE6+EE7+EE8+EF6+EF7-16)*Percapita/30*GI$4)))))) -> 0 | GJ6: =IF(C6=4,SUM(EG6+EG7+EG8+EI6+EI7+EI8)*Percapita/30*GJ$4+(EH6+EH7+EH8+EJ6+EJ7+EJ8)*Cadeirante/30*GJ$4,IF(C6=3,IF(EG9+EI9=10,Fixo/30*GJ$4+(EG6+EG7+EG8+EI6+EI7+EI8)*Percapita/30*GJ$4+(EH9+EJ9)*Cadeirante/30*GJ$4,IF(EG9+EI9<=9,(EG9+EI9)*Crechee/30*GJ$4)+(EH9+EJ9)*Cadeirante/30*GJ$4+(EG6+EG7+EG8+EI6+EI7+EI8)*Percapita/30*GJ$4)+IF(EG9+EI9>=11,Fixo/30*GJ$4+(EG9+EI9-10)*Crechee/30*GJ$4,0),IF(C6=2,IF(EH6+EH7+EH8+EH9+EJ6+EJ7+EJ8+EJ9=1,Cadeirante/30*GJ$4,IF(EH6+EH7+EH8+EH9+EJ6+EJ7+EJ8+EJ9=2,Fixo/30*GJ$4,IF(EH6+EH7+EH8+EH9+EJ6+EJ7+EJ8+EJ9>2,Fixo/30*GJ$4+(EH6+EH7+EH8+EH9+EJ6+EJ7+EJ8+EJ9-2)*Cadeirante/30*GJ$4)))+(EG6+EG7+EG8+EI6+EI7+EI8)*Percapita/30*GJ$4+(EG9+EI9)*Crechee/30*GJ$4,IF(C6=1,IF(EG6+EG7+EG8+EH6+EH7+EH8+EI6+EI7+EI8+EJ6+EJ7+EJ8<=15,(EG6+EG7+EG8+EI6+EI7+EI8)*Percapita/30*GJ$4,IF(EG6+EG7+EG8+EH6+EH7+EH8+EI6+EI7+EI8+EJ6+EJ7+EJ8>=16,Fixo/30*GJ$4+(EG6+EG7+EG8+EH6+EH7+EH8+EI6+EI7+EI8+EJ6+EJ7-16)*Percapita/30*GJ$4)))))) -> 0 | GL6: =IF(J6="ADAPTADO",T6*Cadeirante/30*GM6+S6*Percapita/30*GM6,IF(J6="NORMAL",(S6+T6)*Percapita/30*GM6,IF(J6="CRECHE",0)))*-1 -> 0 | GN6: =SUMIF(V6:V9,"<0")*Cadeirante/30*GN$4+SUMIF(X6:X9,"<0")*Cadeirante/30*GN$4 -> 0 | GO6: =SUMIF(Z6:Z9,"<0")*Cadeirante/30*GO$4+SUMIF(AB6:AB9,"<0")*Cadeirante/30*GO$4 -> 0 | GP6: =SUMIF(AD6:AD9,"<0")*Cadeirante/30*GP$4+SUMIF(AF6:AF9,"<0")*Cadeirante/30*GP$4 -> 0 | GQ6: =SUMIF(AH6:AH9,"<0")*Cadeirante/30*GQ$4+SUMIF(AJ6:AJ9,"<0")*Cadeirante/30*GQ$4 -> 0 | GR6: =SUMIF(AL6:AL9,"<0")*Cadeirante/30*GR$4+SUMIF(AN6:AN9,"<0")*Cadeirante/30*GR$4 -> 0 | GS6: =SUMIF(AP6:AP9,"<0")*Cadeirante/30*GS$4+SUMIF(AR6:AR9,"<0")*Cadeirante/30*GS$4 -> 0 | GT6: =SUMIF(AT6:AT9,"<0")*Cadeirante/30*GT$4+SUMIF(AV6:AV9,"<0")*Cadeirante/30*GT$4 -> 0 | GU6: =SUMIF(AX6:AX9,"<0")*Cadeirante/30*GU$4+SUMIF(AZ6:AZ9,"<0")*Cadeirante/30*GU$4 -> 0 | GV6: =SUMIF(BB6:BB9,"<0")*Cadeirante/30*GV$4+SUMIF(BD6:BD9,"<0")*Cadeirante/30*GV$4 -> 0 | GW6: =SUMIF(BF6:BF9,"<0")*Cadeirante/30*GW$4+SUMIF(BH6:BH9,"<0")*Cadeirante/30*GW$4 -> 0 | GX6: =SUMIF(BJ6:BJ9,"<0")*Cadeirante/30*GX$4+SUMIF(BL6:BL9,"<0")*Cadeirante/30*GX$4 -> 0 | GY6: =SUMIF(BN6:BN9,"<0")*Cadeirante/30*GY$4+SUMIF(BP6:BP9,"<0")*Cadeirante/30*GY$4 -> 0 | GZ6: =SUMIF(BR6:BR9,"<0")*Cadeirante/30*GZ$4+SUMIF(BT6:BT9,"<0")*Cadeirante/30*GZ$4 -> 0 | HA6: =SUMIF(BV6:BV9,"<0")*Cadeirante/30*HA$4+SUMIF(BX6:BX9,"<0")*Cadeirante/30*HA$4 -> 0 | HB6: =SUMIF(BZ6:BZ9,"<0")*Cadeirante/30*HB$4+SUMIF(CB6:CB9,"<0")*Cadeirante/30*HB$4 -> 0 | HC6: =SUMIF(CD6:CD9,"<0")*Cadeirante/30*HC$4+SUMIF(CF6:CF9,"<0")*Cadeirante/30*HC$4 -> 0 | HD6: =SUMIF(CH6:CH9,"<0")*Cadeirante/30*HD$4+SUMIF(CJ6:CJ9,"<0")*Cadeirante/30*HD$4 -> 0 | HE6: =SUMIF(CL6:CL9,"<0")*Cadeirante/30*HE$4+SUMIF(CN6:CN9,"<0")*Cadeirante/30*HE$4 -> 0 | HF6: =SUMIF(CP6:CP9,"<0")*Cadeirante/30*HF$4+SUMIF(CR6:CR9,"<0")*Cadeirante/30*HF$4 -> 0 | HG6: =SUMIF(CT6:CT9,"<0")*Cadeirante/30*HG$4+SUMIF(CV6:CV9,"<0")*Cadeirante/30*HG$4 -> 0 | HH6: =SUMIF(CX6:CX9,"<0")*Cadeirante/30*HH$4+SUMIF(CZ6:CZ9,"<0")*Cadeirante/30*HH$4 -> 0 | HI6: =SUMIF(DB6:DB9,"<0")*Cadeirante/30*HI$4+SUMIF(DD6:DD9,"<0")*Cadeirante/30*HI$4 -> 0 | HJ6: =SUMIF(DF6:DF9,"<0")*Cadeirante/30*HJ$4+SUMIF(DH6:DH9,"<0")*Cadeirante/30*HJ$4 -> 0 | HK6: =SUMIF(DJ6:DJ9,"<0")*Cadeirante/30*HK$4+SUMIF(DL6:DL9,"<0")*Cadeirante/30*HK$4 -> 0 | HL6: =SUMIF(DN6:DN9,"<0")*Cadeirante/30*HL$4+SUMIF(DP6:DP9,"<0")*Cadeirante/30*HL$4 -> 0 | HM6: =SUMIF(DR6:DR9,"<0")*Cadeirante/30*HM$4+SUMIF(DT6:DT9,"<0")*Cadeirante/30*HM$4 -> 0 | HN6: =SUMIF(DV6:DV9,"<0")*Cadeirante/30*HN$4+SUMIF(DX6:DX9,"<0")*Cadeirante/30*HN$4 -> 0 | HO6: =SUMIF(DZ6:DZ9,"<0")*Cadeirante/30*HO$4+SUMIF(EB6:EB9,"<0")*Cadeirante/30*HO$4 -> 0 | HP6: =SUMIF(ED6:ED9,"<0")*Cadeirante/30*HP$4+SUMIF(EF6:EF9,"<0")*Cadeirante/30*HP$4 -> 0 | HW6: 17629.31 | HY6: =IF(ISTEXT(EM6), VALUE(EM6), EM6) -> 0 | HZ6: =IF(ISTEXT(EN6), VALUE(EN6), EN6) -> 0 | IA6: =IF(ISTEXT(EO6), VALUE(EO6), EO6) -> 0 | IB6: =HW6=FE6 -> FALSE
A7: 028.293-00 | B7: 2024/0058910-001 | C7: BT | D7: 2024/0058910 | E7: EFV2108 | F7: 01/04/2026 | G7: 30/04/2026 | H7: A.C.G. TRANSPORTE ESCOLAR LTDA | I7: ANDREIA PEREIRA DA SILVA | J7: NORMAL | K7: EMEF | L7: =CONTINUA!BV7 -> 46 | M7: =CONTINUA!BW7 -> 0 | O7: 6020.2024/0058910-3 | P7: O | Q7: 49 | CE7: 1 | CY7: 1 | EP7: =Q7 -> 49 | EQ7: =U7+Y7+AC7+AG7+AK7+AO7+AS7+AW7+BA7+BE7+BI7+BM7+BQ7+BU7+BY7+CC7+CG7+CK7+CO7+CS7+CW7+DA7+DE7+DI7+DM7+DQ7+DU7+DY7+EC7+EG7 -> 0 | ER7: =S7+W7+AA7+AE7+AI7+AM7+AQ7+AU7+AY7+BC7+BG7+BK7+BO7+BS7+BW7+CA7+CE7+CI7+CM7+CQ7+CU7+CY7+DC7+DG7+DK7+DO7+DS7+DW7+EA7+EE7+EI7 -> 2 | ES7: =R7 -> 0 | ET7: =V7+Z7+AD7+AH7+AL7+AP7+AT7+AX7+BB7+BF7+BJ7+BN7+BR7+BV7+BZ7+CD7+CH7+CL7+CP7+CT7+CX7+DB7+DF7+DJ7+DN7+DR7+DV7+DZ7+ED7+EH7 -> 0 | EU7: =T7+X7+AB7+AF7+AJ7+AN7+AR7+AV7+AZ7+BD7+BH7+BL7+BP7+BT7+BX7+CB7+CF7+CJ7+CN7+CR7+CV7+CZ7+DD7+DH7+DL7+DP7+DT7+DX7+EB7+EF7+EJ7 -> 0 | EV7: =EP7+EQ7+ES7+ET7+ER7+EU7 -> 51 | EX7: =FF7 -> 0 | EY7: =(L7*regular)+(M7*Cadeirantee) -> 443.44 | EZ7: =SUMIF(FG7:GJ7,">0") -> 0 | FA7: =SUMIF(FG7:GJ7,"<0")+SUMIF(GN7:HP7,"<0") -> 0 | FB7: 0 | FC7: =N7*km*'VALORES TABELA'!$B$13 -> 0 | FD7: =GL7 -> 0 | GL7: =IF(J7="ADAPTADO",T7*Cadeirante/30*GM7+S7*Percapita/30*GM7,IF(J7="NORMAL",(S7+T7)*Percapita/30*GM7,IF(J7="CRECHE",0)))*-1 -> 0 | HY7: =IF(ISTEXT(EM7), VALUE(EM7), EM7) -> 0 | HZ7: =IF(ISTEXT(EN7), VALUE(EN7), EN7) -> 0 | IA7: =IF(ISTEXT(EO7), VALUE(EO7), EO7) -> 0
A8: 028.293-00 | B8: 2024/0058910-001 | C8: BT | D8: 2024/0058910 | E8: EFV2108 | F8: 01/04/2026 | G8: 30/04/2026 | H8: A.C.G. TRANSPORTE ESCOLAR LTDA | I8: ANDREIA PEREIRA DA SILVA | J8: NORMAL | K8: EMEE | L8: =CONTINUA!BV8 -> 0 | M8: =CONTINUA!BW8 -> 0 | O8: 6020.2024/0058910-3 | P8: O | EP8: =Q8 -> 0 | EQ8: =U8+Y8+AC8+AG8+AK8+AO8+AS8+AW8+BA8+BE8+BI8+BM8+BQ8+BU8+BY8+CC8+CG8+CK8+CO8+CS8+CW8+DA8+DE8+DI8+DM8+DQ8+DU8+DY8+EC8+EG8 -> 0 | ER8: =S8+W8+AA8+AE8+AI8+AM8+AQ8+AU8+AY8+BC8+BG8+BK8+BO8+BS8+BW8+CA8+CE8+CI8+CM8+CQ8+CU8+CY8+DC8+DG8+DK8+DO8+DS8+DW8+EA8+EE8+EI8 -> 0 | ES8: =R8 -> 0 | ET8: =V8+Z8+AD8+AH8+AL8+AP8+AT8+AX8+BB8+BF8+BJ8+BN8+BR8+BV8+BZ8+CD8+CH8+CL8+CP8+CT8+CX8+DB8+DF8+DJ8+DN8+DR8+DV8+DZ8+ED8+EH8 -> 0 | EU8: =T8+X8+AB8+AF8+AJ8+AN8+AR8+AV8+AZ8+BD8+BH8+BL8+BP8+BT8+BX8+CB8+CF8+CJ8+CN8+CR8+CV8+CZ8+DD8+DH8+DL8+DP8+DT8+DX8+EB8+EF8+EJ8 -> 0 | EV8: =EP8+EQ8+ES8+ET8+ER8+EU8 -> 0 | EX8: =FF8 -> 0 | EY8: =(L8*regular)+(M8*Cadeirantee) -> 0 | EZ8: =SUMIF(FG8:GJ8,">0") -> 0 | FA8: =SUMIF(FG8:GJ8,"<0")+SUMIF(GN8:HP8,"<0") -> 0 | FB8: 0 | FC8: =N8*km*'VALORES TABELA'!$B$13 -> 0 | FD8: =GL8 -> 0 | GL8: =IF(J8="ADAPTADO",T8*Cadeirante/30*GM8+S8*Percapita/30*GM8,IF(J8="NORMAL",(S8+T8)*Percapita/30*GM8,IF(J8="CRECHE",0)))*-1 -> 0 | HY8: =IF(ISTEXT(EM8), VALUE(EM8), EM8) -> 0 | HZ8: =IF(ISTEXT(EN8), VALUE(EN8), EN8) -> 0 | IA8: =IF(ISTEXT(EO8), VALUE(EO8), EO8) -> 0
A9: 028.293-00 | B9: 2024/0058910-001 | C9: BT | D9: 2024/0058910 | E9: EFV2108 | F9: 01/04/2026 | G9: 30/04/2026 | H9: A.C.G. TRANSPORTE ESCOLAR LTDA | I9: ANDREIA PEREIRA DA SILVA | J9: NORMAL | K9: CEI | L9: =CONTINUA!BV9 -> 0 | M9: =CONTINUA!BW9 -> 0 | O9: 6020.2024/0058910-3 | P9: O | EP9: =Q9 -> 0 | EQ9: =U9+Y9+AC9+AG9+AK9+AO9+AS9+AW9+BA9+BE9+BI9+BM9+BQ9+BU9+BY9+CC9+CG9+CK9+CO9+CS9+CW9+DA9+DE9+DI9+DM9+DQ9+DU9+DY9+EC9+EG9 -> 0 | ER9: =S9+W9+AA9+AE9+AI9+AM9+AQ9+AU9+AY9+BC9+BG9+BK9+BO9+BS9+BW9+CA9+CE9+CI9+CM9+CQ9+CU9+CY9+DC9+DG9+DK9+DO9+DS9+DW9+EA9+EE9+EI9 -> 0 | ES9: =R9 -> 0 | ET9: =V9+Z9+AD9+AH9+AL9+AP9+AT9+AX9+BB9+BF9+BJ9+BN9+BR9+BV9+BZ9+CD9+CH9+CL9+CP9+CT9+CX9+DB9+DF9+DJ9+DN9+DR9+DV9+DZ9+ED9+EH9 -> 0 | EU9: =T9+X9+AB9+AF9+AJ9+AN9+AR9+AV9+AZ9+BD9+BH9+BL9+BP9+BT9+BX9+CB9+CF9+CJ9+CN9+CR9+CV9+CZ9+DD9+DH9+DL9+DP9+DT9+DX9+EB9+EF9+EJ9 -> 0 | EV9: =EP9+EQ9+ES9+ET9+ER9+EU9 -> 0 | EX9: =FF9 -> 0 | EY9: =(L9*regular)+(M9*Cadeirantee) -> 0 | EZ9: =SUMIF(FG9:GJ9,">0") -> 0 | FA9: =SUMIF(FG9:GJ9,"<0")+SUMIF(GN9:HP9,"<0") -> 0 | FB9: 0 | FC9: =N9*km*'VALORES TABELA'!$B$13 -> 0 | FD9: =GL9 -> 0 | GL9: =IF(J9="ADAPTADO",T9*Cadeirante/30*GM9+S9*Percapita/30*GM9,IF(J9="NORMAL",(S9+T9)*Percapita/30*GM9,IF(J9="CRECHE",0)))*-1 -> 0 | HY9: =IF(ISTEXT(EM9), VALUE(EM9), EM9) -> 0 | HZ9: =IF(ISTEXT(EN9), VALUE(EN9), EN9) -> 0 | IA9: =IF(ISTEXT(EO9), VALUE(EO9), EO9) -> 0
A10: 028.293-00 | B10: 2024/0058910-001 | C10: BT | D10: 2024/0058910 | E10: EFV2108 | F10: 01/04/2026 | G10: 30/04/2026 | H10: A.C.G. TRANSPORTE ESCOLAR LTDA | I10: ANDREIA PEREIRA DA SILVA | J10: NORMAL | K10: CCA | L10: =CONTINUA!BV10 -> 0 | M10: =CONTINUA!BW10 -> 0 | O10: 6020.2024/0058910-3 | P10: O | EP10: =Q10 -> 0 | EQ10: =U10+Y10+AC10+AG10+AK10+AO10+AS10+AW10+BA10+BE10+BI10+BM10+BQ10+BU10+BY10+CC10+CG10+CK10+CO10+CS10+CW10+DA10+DE10+DI10+DM10+DQ10+DU10+DY10+EC10+EG10 -> 0 | ER10: =S10+W10+AA10+AE10+AI10+AM10+AQ10+AU10+AY10+BC10+BG10+BK10+BO10+BS10+BW10+CA10+CE10+CI10+CM10+CQ10+CU10+CY10+DC10+DG10+DK10+DO10+DS10+DW10+EA10+EE10+EI10 -> 0 | ES10: =R10 -> 0 | ET10: =V10+Z10+AD10+AH10+AL10+AP10+AT10+AX10+BB10+BF10+BJ10+BN10+BR10+BV10+BZ10+CD10+CH10+CL10+CP10+CT10+CX10+DB10+DF10+DJ10+DN10+DR10+DV10+DZ10+ED10+EH10 -> 0 | EU10: =T10+X10+AB10+AF10+AJ10+AN10+AR10+AV10+AZ10+BD10+BH10+BL10+BP10+BT10+BX10+CB10+CF10+CJ10+CN10+CR10+CV10+CZ10+DD10+DH10+DL10+DP10+DT10+DX10+EB10+EF10+EJ10 -> 0 | EV10: =EP10+EQ10+ES10+ET10+ER10+EU10 -> 0 | EX10: 0 | EY10: 0 | EZ10: 0 | FA10: 0 | FB10: =SUM(FF10:GI10)/2 -> 0 | FC10: =N10*km*'VALORES TABELA'!$B$13 -> 0 | FD10: =GL10 -> 0 | FF10: =((Q10+S10)*Percapita)+((R10+T10)*Cadeirante) -> 0 | FG10: =((U10+W10)*Percapita/30*FG$4)+((V10+X10)*Cadeirante/30*FG$4) -> 0 | FH10: =((Y10+AA10)*Percapita/30*FH$4)+((Z10+AB10)*Cadeirante/30*FH$4) -> 0 | FI10: =((AC10+AE10)*Percapita/30*FI$4)+((AD10+AF10)*Cadeirante/30*FI$4) -> 0 | FJ10: =((AG10+AI10)*Percapita/30*FJ$4)+((AH10+AJ10)*Cadeirante/30*FJ$4) -> 0 | FK10: =((AK10+AM10)*Percapita/30*FK$4)+((AL10+AN10)*Cadeirante/30*FK$4) -> 0 | FL10: =((AO10+AQ10)*Percapita/30*FL$4)+((AP10+AR10)*Cadeirante/30*FL$4) -> 0 | FM10: =((AS10+AU10)*Percapita/30*FM$4)+((AT10+AV10)*Cadeirante/30*FM$4) -> 0 | FN10: =((AW10+AY10)*Percapita/30*FN$4)+((AX10+AZ10)*Cadeirante/30*FN$4) -> 0 | FO10: =((BA10+BC10)*Percapita/30*FO$4)+((BB10+BD10)*Cadeirante/30*FO$4) -> 0 | FP10: =((BE10+BG10)*Percapita/30*FP$4)+((BF10+BH10)*Cadeirante/30*FP$4) -> 0 | FQ10: =((BI10+BK10)*Percapita/30*FQ$4)+((BJ10+BL10)*Cadeirante/30*FQ$4) -> 0 | FR10: =((BM10+BO10)*Percapita/30*FR$4)+((BN10+BP10)*Cadeirante/30*FR$4) -> 0 | FS10: =((BQ10+BS10)*Percapita/30*FS$4)+((BR10+BT10)*Cadeirante/30*FS$4) -> 0 | FT10: =((BU10+BW10)*Percapita/30*FT$4)+((BV10+BX10)*Cadeirante/30*FT$4) -> 0 | FU10: =((BY10+CA10)*Percapita/30*FU$4)+((BZ10+CB10)*Cadeirante/30*FU$4) -> 0 | FV10: =((CC10+CE10)*Percapita/30*FV$4)+((CD10+CF10)*Cadeirante/30*FV$4) -> 0 | FW10: =((CG10+CI10)*Percapita/30*FW$4)+((CI10+CK10)*Cadeirante/30*FW$4) -> 0 | FX10: =((CK10+CM10)*Percapita/30*FX$4)+((CL10+CN10)*Cadeirante/30*FX$4) -> 0 | FY10: =((CO10+CQ10)*Percapita/30*FY$4)+((CP10+CR10)*Cadeirante/30*FY$4) -> 0 | FZ10: =((CS10+CU10)*Percapita/30*FZ$4)+((CT10+CV10)*Cadeirante/30*FZ$4) -> 0 | GA10: =((CW10+CY10)*Percapita/30*GA$4)+((CX10+CZ10)*Cadeirante/30*GA$4) -> 0 | GB10: =((DA10+DC10)*Percapita/30*GB$4)+((DB10+DD10)*Cadeirante/30*GB$4) -> 0 | GC10: =((DE10+DG10)*Percapita/30*GC$4)+((DF10+DH10)*Cadeirante/30*GC$4) -> 0 | GD10: =((DI10+DK10)*Percapita/30*GD$4)+((DJ10+DL10)*Cadeirante/30*GD$4) -> 0 | GE10: =((DM10+DO10)*Percapita/30*GE$4)+((DN10+DP10)*Cadeirante/30*GE$4) -> 0 | GF10: =((DQ10+DS10)*Percapita/30*GF$4)+((DR10+DT10)*Cadeirante/30*GF$4) -> 0 | GG10: =((DU10+DW10)*Percapita/30*GG$4)+((DV10+DX10)*Cadeirante/30*GG$4) -> 0 | GH10: =((DY10+EA10)*Percapita/30*GH$4)+((DZ10+EB10)*Cadeirante/30*GH$4) -> 0 | GI10: =((EC10+EE10)*Percapita/30*GI$4)+((ED10+EF10)*Cadeirante/30*GI$4) -> 0 | GJ10: =((EG10+EI10)*Percapita)+((EH10+EJ10)*Cadeirante) -> 0 | GL10: =IF(J10="ADAPTADO",T10*Cadeirante/30*GM10+S10*Percapita/30*GM10,IF(J10="NORMAL",(S10+T10)*Percapita/30*GM10,IF(J10="CRECHE",0)))*-1 -> 0 | HY10: =IF(ISTEXT(EM10), VALUE(EM10), EM10) -> 0 | HZ10: =IF(ISTEXT(EN10), VALUE(EN10), EN10) -> 0 | IA10: =IF(ISTEXT(EO10), VALUE(EO10), EO10) -> 0
